Workbook

Sheet Assumptions
A1: Reliance Industries Limited - consolidated 5-year model (Rs crore). Base case on every statement tab; Scenarios tab carries Bull / Bear (rating stress) / Tail.
A2: Generated by build_model.py from compute_ratios.py (208 tie-outs). FY2023-FY2026 audited; yellow = projection. Segment history FY2024-FY2026 (FY2023 segment split not extracted).
A4: Driver | B4: FY2027E | C4: FY2028E | D4: FY2029E | E4: FY2030E | F4: FY2031E | G4: Source / basis
A5: BASE
A6: Revenue growth - O2C (%) | B6: 5 | C6: 3 | D6: 3 | E6: 3 | F6: 3 | G6: ANALYST JUDGMENT anchored on FY2024-26 segment history (audited segment information): O2C 5,64,749 -> 6,62,401 (+8.3% CAGR, crude-price driven); Oil & Gas 24,439 -> 23,861 with KG D6 output 260.3 -> 248.8 BCFe (natural decline); Retail 3,06,848 -> 3,71,085 (+10.0% CAGR); Digital 1,32,938 -> 1,76,164 (+15.1% CAGR); Others 80,516 -> 80,522.
A7: Revenue growth - Oil and Gas (%) | B7: -5 | C7: -5 | D7: -5 | E7: -5 | F7: -5
A8: Revenue growth - Retail (%) | B8: 12 | C8: 12 | D8: 11 | E8: 11 | F8: 10
A9: Revenue growth - Digital Services (%) | B9: 13 | C9: 12 | D9: 12 | E9: 11 | F9: 10
A10: Revenue growth - Others (%) | B10: 10 | C10: 10 | D10: 10 | E10: 10 | F10: 10
A11: EBITDA margin - O2C (%) | B11: 9 | C11: 9 | D11: 9 | E11: 9 | F11: 9 | G11: ANALYST JUDGMENT anchored on FY2024-26 margins (engine): O2C 11.0 / 8.8 / 9.1; Oil & Gas 82.6 / 84.0 / 79.8; Retail 7.5 / 7.6 / 7.3; Digital 42.6 / 42.2 / 43.5; Others 10.5 / 15.3 / 13.5. Q1 FY2027 (release 17-Jul-2026): O2C EBITDA +17.2% YoY, JPL margin 53.3% on operating revenue.
A12: EBITDA margin - Oil and Gas (%) | B12: 76 | C12: 75 | D12: 74 | E12: 73 | F12: 72
A13: EBITDA margin - Retail (%) | B13: 7.3 | C13: 7.4 | D13: 7.5 | E13: 7.5 | F13: 7.5
A14: EBITDA margin - Digital Services (%) | B14: 44 | C14: 44.5 | D14: 45 | E14: 45 | F14: 45
A15: EBITDA margin - Others (%) | B15: 13.5 | C15: 13.5 | D15: 13.5 | E15: 13.5 | F15: 13.5
A16: Capex - cash (Rs crore) | B16: 150000 | C16: 145000 | D16: 135000 | E16: 130000 | F16: 125000 | G16: ANALYST JUDGMENT: company capex excl. spectrum 1,31,769 / 1,31,107 / 1,44,271 (FY2024-26 releases); Q1 FY2027 38,682 (annualised ~1.55 lakh crore); capital commitments rose to 66,517 from 31,629 (note 34). Bear adds a 15% overrun on new-energy / O2C projects (CRISIL project risk: projects large relative to operations).
A17: Share of gross interest capitalised (%) | B17: 40 | C17: 35 | D17: 30 | E17: 25 | F17: 20 | G17: FY2026 16,091 of 38,358 gross = 42%; FY2025 18,283 of 38,987 = 47%. Falls as 5G / new-energy assets commission (Q1 FY2027 release: finance cost +18.5% 'due to ... capitalisation of 5G assets').
A18: Working-capital shock (Rs crore) | B18: 0 | C18: 0 | D18: 0 | E18: 0 | F18: 0
A19: BULL
A20: Revenue growth - O2C (%) | B20: 5 | C20: 3 | D20: 3 | E20: 3 | F20: 3
A21: Revenue growth - Oil and Gas (%) | B21: -5 | C21: -5 | D21: -5 | E21: -5 | F21: -5
A22: Revenue growth - Retail (%) | B22: 14 | C22: 14 | D22: 14 | E22: 14 | F22: 14
A23: Revenue growth - Digital Services (%) | B23: 15 | C23: 14 | D23: 13 | E23: 12 | F23: 12
A24: Revenue growth - Others (%) | B24: 10 | C24: 10 | D24: 10 | E24: 10 | F24: 10
A25: EBITDA margin - O2C (%) | B25: 10.5 | C25: 10.5 | D25: 10.5 | E25: 10.5 | F25: 10.5
A26: EBITDA margin - Oil and Gas (%) | B26: 76 | C26: 75 | D26: 74 | E26: 73 | F26: 72
A27: EBITDA margin - Retail (%) | B27: 7.3 | C27: 7.4 | D27: 7.5 | E27: 7.5 | F27: 7.5
A28: EBITDA margin - Digital Services (%) | B28: 45 | C28: 46 | D28: 47 | E28: 47 | F28: 47
A29: EBITDA margin - Others (%) | B29: 13.5 | C29: 13.5 | D29: 13.5 | E29: 13.5 | F29: 13.5
A30: Capex - cash (Rs crore) | B30: 150000 | C30: 145000 | D30: 135000 | E30: 130000 | F30: 125000
A31: Share of gross interest capitalised (%) | B31: 40 | C31: 35 | D31: 30 | E31: 25 | F31: 20
A32: Working-capital shock (Rs crore) | B32: 0 | C32: 0 | D32: 0 | E32: 0 | F32: 0 | G32: STRESS VARIABLE (CRISIL cash-flow adequacy): FY2026 contract liabilities rose 1,09,196 to 1,72,201 (note 23) and trade/other payables added 86,609 to CFO; supplier finance is 76,377 (note 44). Bear unwinds 1,00,000 in FY2027; Tail 1,50,000 + 30,000.
A33: BEAR / RATING STRESS
A34: Revenue growth - O2C (%) | B34: -10 | C34: -5 | D34: 3 | E34: 3 | F34: 3
A35: Revenue growth - Oil and Gas (%) | B35: -10 | C35: -10 | D35: -10 | E35: -10 | F35: -10
A36: Revenue growth - Retail (%) | B36: 6 | C36: 6 | D36: 8 | E36: 9 | F36: 9
A37: Revenue growth - Digital Services (%) | B37: 8 | C37: 8 | D37: 9 | E37: 9 | F37: 9
A38: Revenue growth - Others (%) | B38: 5 | C38: 5 | D38: 5 | E38: 5 | F38: 5
A39: EBITDA margin - O2C (%) | B39: 6.5 | C39: 6.5 | D39: 7.5 | E39: 8 | F39: 8.5
A40: EBITDA margin - Oil and Gas (%) | B40: 70 | C40: 68 | D40: 66 | E40: 65 | F40: 65
A41: EBITDA margin - Retail (%) | B41: 6.5 | C41: 6.5 | D41: 7 | E41: 7 | F41: 7
...

Sheet Revenue Model
A1: Rs crore | B1: FY2023 | C1: FY2024 | D1: FY2025 | E1: FY2026 | F1: FY2027E | G1: FY2028E | H1: FY2029E | I1: FY2030E | J1: FY2031E | K1: Source / note
A2: SEGMENT REVENUE (gross value of sales and services, audited segment information)
A3: O2C | C3: 564749 | D3: 626921 | E3: 662401 | F3: 695521.05 | G3: 716386.68 | H3: 737878.28 | I3: 760014.63 | J3: 782815.07 | K3: segment information (Q4 FY2025 / Q4 FY2026 releases)
A4: Oil and Gas | C4: 24439 | D4: 25211 | E4: 23861 | F4: 22667.95 | G4: 21534.553 | H4: 20457.825 | I4: 19434.934 | J4: 18463.187 | K4: segment information (Q4 FY2025 / Q4 FY2026 releases)
A5: Retail | C5: 306848 | D5: 330943 | E5: 371085 | F5: 415615.2 | G5: 465489.02 | H5: 516692.82 | I5: 573529.03 | J5: 630881.93 | K5: segment information (Q4 FY2025 / Q4 FY2026 releases)
A6: Digital Services | C6: 132938 | D6: 154119 | E6: 176164 | F6: 199065.32 | G6: 222953.16 | H6: 249707.54 | I6: 277175.37 | J6: 304892.9 | K6: segment information (Q4 FY2025 / Q4 FY2026 releases)
A7: Others | C7: 80516 | D7: 55859 | E7: 80522 | F7: 88574.2 | G7: 97431.62 | H7: 107174.78 | I7: 117892.26 | J7: 129681.49 | K7: segment information (Q4 FY2025 / Q4 FY2026 releases)
A8: Less: inter-segment transfers | C8: 109368 | D8: 121879 | E8: 138114 | F8: 149403.61 | G8: 160161.45 | H8: 171525.21 | I8: 183731.81 | J8: 196206.78 | K8: segment information
A9: VALUE OF SALES AND SERVICES | B9: 974864 | C9: 1000122 | D9: 1071174 | E9: 1175919 | F9: 1272040.1 | G9: 1363633.6 | H9: 1460386 | I9: 1564314.4 | J9: 1670527.8 | K9: P&L
A10: Less: GST recovered | B10: 83553 | C10: 85650 | D10: 91038 | E10: 100244 | F10: 108438.07 | G10: 116246.17 | H10: 124494.07 | I10: 133353.69 | J10: 142408.1 | K10: P&L
A11: REVENUE FROM OPERATIONS | B11: 891311 | C11: 914472 | D11: 980136 | E11: 1075675 | F11: 1163602 | G11: 1247387.4 | H11: 1335892 | I11: 1430960.7 | J11: 1528119.7 | K11: P&L (engine tie-outs)
A12: SEGMENT EBITDA
A13: O2C | C13: 62389 | D13: 54988 | E13: 60546 | F13: 62596.895 | G13: 64474.801 | H13: 66409.045 | I13: 68401.317 | J13: 70453.356 | K13: segment results (EBITDA)
A14: Oil and Gas | C14: 20191 | D14: 21188 | E14: 19050 | F14: 17227.642 | G14: 16150.914 | H14: 15138.79 | I14: 14187.502 | J14: 13293.495 | K14: segment results (EBITDA)
A15: Retail | C15: 23108 | D15: 25094 | E15: 27034 | F15: 30339.91 | G15: 34446.188 | H15: 38751.961 | I15: 43014.677 | J15: 47316.145 | K15: segment results (EBITDA)
A16: Digital Services | C16: 56675 | D16: 65001 | E16: 76560 | F16: 87588.741 | G16: 99214.155 | H16: 112368.39 | I16: 124728.91 | J16: 137201.81 | K16: segment results (EBITDA)
A17: Others | C17: 8466 | D17: 8526 | E17: 10857 | F17: 11957.517 | G17: 13153.269 | H17: 14468.596 | I17: 15915.455 | J17: 17507.001 | K17: segment results (EBITDA)
A18: OPERATING METRICS (history; drive the narrative, not the model)
A19: Jio subscribers (mn) | C19: 481.8 | D19: 488.2 | E19: 524.4 | K19: Q4 releases
A20: Jio ARPU Q4 (Rs/month) | C20: 181.7 | D20: 206.2 | E20: 214 | K20: Q4 releases
A21: O2C throughput (MMT) | C21: 78.2 | D21: 80.5 | E21: 80 | K21: Q4 releases
A22: KG D6 production (BCFe) | C22: 260.3 | D22: 270.9 | E22: 248.8 | K22: Q4 releases
A23: Retail stores (nos.) | D23: 19340 | E23: 20160 | K23: Q4 releases

Sheet Income Statement
A1: Rs crore | B1: FY2023 | C1: FY2024 | D1: FY2025 | E1: FY2026 | F1: FY2027E | G1: FY2028E | H1: FY2029E | I1: FY2030E | J1: FY2031E | K1: Source / note
A2: Revenue from operations (net of GST) | B2: 891311 | C2: 914472 | D2: 980136 | E2: 1075675 | F2: 1163602 | G2: 1247387.4 | H2: 1335892 | I2: 1430960.7 | J2: 1528119.7 | K2: P&L
A3: PBDIT (CRISIL: incl. recurring other income, excl. one-time) | B3: 153896 | C3: 178290 | D3: 183422 | E3: 198987 | F3: 216177.25 | G3: 233572.4 | H3: 253845.21 | I3: 274720.04 | J3: 296983.98 | K3: history = engine; projection = segment EBITDA + treasury yield + unallocable
A4: One-time income (profit on sale of listed investments) | B4: 0 | C4: 0 | D4: 0 | E4: 8924 | F4: 0 | G4: 0 | H4: 0 | I4: 0 | J4: 0 | K4: Q4 FY2026 release note 5
A5: Depreciation, amortisation and depletion | B5: 40303 | C5: 50832 | D5: 53136 | E5: 57688 | F5: 62293.435 | G5: 67000.511 | H5: 71170.07 | I5: 74599.585 | J5: 77553.152 | K5: P&L; projected on opening block
A6: Finance costs (P&L, net of capitalised interest) | B6: 19571 | C6: 23118 | D6: 24269 | E6: 27061 | F6: 24875.792 | G6: 26514.796 | H6: 28093.488 | I6: 29605.88 | J6: 31045.872 | K6: P&L / note 29
A7: Memo: interest capitalised | B7: 8830 | C7: 15222 | D7: 18283 | E7: 16091 | F7: 15246.528 | G7: 13197.044 | H7: 11180.352 | I7: 9199.96 | J7: 7259.968 | K7: note 29 footnote
A8: Profit before tax (before associates) | B8: 94022 | C8: 104340 | D8: 106017 | E8: 123162 | F8: 129008.02 | G8: 140057.09 | H8: 154581.65 | I8: 170514.57 | J8: 188384.96 | K8: P&L (tied)
A9: Tax expense (current + deferred) | B9: 20376 | C9: 25707 | D9: 25230 | E9: 27552 | F9: 29671.845 | G9: 32213.131 | H9: 35553.779 | I9: 39218.352 | J9: 43328.54 | K9: P&L
A10: Share of associates / JVs (+ FY2023 discontinued) | B10: 442 | C10: 387 | D10: 522 | E10: 144 | F10: 0 | G10: 0 | H10: 0 | I10: 0 | J10: 0 | K10: P&L; not projected
A11: PROFIT FOR THE YEAR | B11: 74088 | C11: 79020 | D11: 81309 | E11: 95754 | F11: 99336.176 | G11: 107843.96 | H11: 119027.87 | I11: 131296.22 | J11: 145056.42 | K11: P&L printed (tied)
A12: of which non-controlling interest | B12: 7386 | C12: 9399 | D12: 11661 | E12: 14979 | F12: 15496.443 | G12: 16823.658 | H12: 18568.348 | I12: 20482.21 | J12: 22628.801 | K12: P&L attribution
A13: of which owners of the company | B13: 66702 | C13: 69621 | D13: 69648 | E13: 80775 | F13: 83839.733 | G13: 91020.304 | H13: 100459.52 | I13: 110814.01 | J13: 122427.61 | K13: P&L attribution

Sheet Cash Flow
A1: Rs crore | B1: FY2023 | C1: FY2024 | D1: FY2025 | E1: FY2026 | F1: FY2027E | G1: FY2028E | H1: FY2029E | I1: FY2030E | J1: FY2031E | K1: Source / note
A2: Net cash from operating activities | B2: 115032 | C2: 158788 | D2: 178703 | E2: 192113 | F2: 171022.38 | G2: 185764.28 | H2: 202495.93 | I2: 219619.72 | J2: 238259.18 | K2: historical: cash-flow statement; projected: PAT + D&A + deferred tax - change in inventory and receivables + change in payables and other current liabilities (incl. the stress shock)
A3: Capex - PPE, spectrum, intangibles | B3: 140988 | C3: 152883 | D3: 139967 | E3: 122916 | F3: 150000 | G3: 145000 | H3: 135000 | I3: 130000 | J3: 125000 | K3: cash-flow statement
A4: Interest capitalised (paid in cash, added to block) | B4: 8830 | C4: 15222 | D4: 18283 | E4: 16091 | F4: 15246.528 | G4: 13197.044 | H4: 11180.352 | I4: 9199.96 | J4: 7259.968 | K4: inside 'interest paid' historically
A5: Payment of DoT deferred payment liabilities | B5: 0 | C5: 4423 | D5: 4574 | E5: 4736 | F5: 4962 | G5: 5300 | H5: 5650 | I5: 6050 | J5: 6450 | K5: cash-flow statement
A6: Dividends paid (owners + NCI) | B6: 5083 | C6: 6089 | D6: 7180 | E6: 7879 | F6: 8569 | G6: 8887.0117 | H6: 9648.1522 | I6: 10648.709 | J6: 11746.285 | K6: cash-flow statement
A7: New borrowing (DERIVED: funding gap below the cash floor) | F7: 0 | G7: 0 | H7: 0 | I7: 0 | J7: 0 | K7: zero unless cash + current investments < floor
A8: Closing cash and current investments | B8: 187137 | C8: 203395 | D8: 225211 | E8: 243408 | F8: 235652.85 | G8: 249033.08 | H8: 290050.5 | I8: 353771.55 | J8: 441574.48 | K8: balance sheet

Sheet Balance Sheet
A1: Rs crore | B1: FY2023 | C1: FY2024 | D1: FY2025 | E1: FY2026 | F1: FY2027E | G1: FY2028E | H1: FY2029E | I1: FY2030E | J1: FY2031E | K1: Source / note
A2: Capital block (PPE, spectrum, intangibles, goodwill, CWIP, under development) | B2: 1018557 | C2: 1118840 | D2: 1261751 | E2: 1362481 | F2: 1465434.1 | G2: 1556630.6 | H2: 1631640.9 | I2: 1696241.3 | J2: 1750948.1
A3: Investments and other non-current assets | B3: 163578 | C3: 167046 | D3: 189100 | E3: 221410 | F3: 221410 | G3: 221410 | H3: 221410 | I3: 221410 | J3: 221410
A4: Inventories | B4: 140008 | C4: 152770 | D4: 146062 | E4: 166941 | F4: 180586.97 | G4: 193590.17 | H4: 207325.76 | I4: 222080.1 | J4: 237158.84
A5: Trade receivables | B5: 28448 | C5: 31628 | D5: 42121 | E5: 58491 | F5: 63272.128 | G5: 67828.05 | H5: 72640.581 | I5: 77810.048 | J5: 83093.174
A6: Cash and current investments | B6: 187137 | C6: 203395 | D6: 225211 | E6: 243408 | F6: 235652.85 | G6: 249033.08 | H6: 290050.5 | I6: 353771.55 | J6: 441574.48
A7: Other current assets | B7: 69703 | C7: 82307 | D7: 85876 | E7: 125409 | F7: 125409 | G7: 125409 | H7: 125409 | I7: 125409 | J7: 125409
A8: TOTAL ASSETS | B8: 1607431 | C8: 1755986 | D8: 1950121 | E8: 2178140 | F8: 2291765 | G8: 2413900.9 | H8: 2548476.8 | I8: 2696722 | J8: 2859593.6 | K8: consolidated balance sheet (grouped; totals tie to the AR)
A9: Equity attributable to owners | B9: 715872 | C9: 793481 | D9: 843200 | E9: 904030 | F9: 979750.73 | G9: 1062772.7 | H9: 1154548.9 | I9: 1255779.1 | J9: 1367635
A10: Non-controlling interest | B10: 113009 | C10: 132307 | D10: 166426 | E10: 181836 | F10: 196882.44 | G10: 212817.4 | H10: 230420.93 | I10: 249838.27 | J10: 271292.44
A11: Borrowings (non-current + current) | B11: 313966 | C11: 324622 | D11: 347530 | E11: 374421 | F11: 374421 | G11: 374421 | H11: 374421 | I11: 374421 | J11: 374421
A12: Lease liabilities | B12: 20426 | C12: 21520 | D12: 22045 | E12: 23579 | F12: 23579 | G12: 23579 | H12: 23579 | I12: 23579 | J12: 23579
A13: DoT deferred payment liabilities (non-current + current) | B13: 117272 | C13: 112849 | D13: 109148 | E13: 104514 | F13: 99552 | G13: 94252 | H13: 88602 | I13: 82552 | J13: 76102
A14: Deferred tax liabilities | B14: 60324 | C14: 72241 | D14: 83453 | E14: 97961 | F14: 112796.92 | G14: 128903.49 | H14: 146680.38 | I14: 166289.55 | J14: 187953.82
A15: Other non-current liabilities and provisions | B15: 10230 | C15: 12191 | D15: 44854 | E15: 66558 | F15: 66558 | G15: 66558 | H15: 66558 | I15: 66558 | J15: 66558
A16: Trade payables (incl. supplier finance) | B16: 147172 | C16: 178377 | D16: 186789 | E16: 158842 | F16: 171825.95 | G16: 184198.3 | H16: 197267.53 | I16: 211306.08 | J16: 225653.28
A17: Other current liabilities (incl. contract liabilities; excl. current DPL) | B17: 109160 | C17: 108398 | D17: 146676 | E17: 266399 | F17: 266399 | G17: 266399 | H17: 266399 | I17: 266399 | J17: 266399
A18: TOTAL EQUITY AND LIABILITIES | B18: 1607431 | C18: 1755986 | D18: 1950121 | E18: 2178140 | F18: 2291765 | G18: 2413900.9 | H18: 2548476.8 | I18: 2696722 | J18: 2859593.6 | K18: consolidated balance sheet (grouped; totals tie to the AR)
A19: Check: assets - (equity + liabilities) | B19: 0 | C19: 0 | D19: 0 | E19: 0 | F19: 0 | G19: 0 | H19: 0 | I19: 0 | J19: 0 | K19: must be zero in every column

Sheet Credit Ratios
A1: CRISIL convention (formulas) | B1: FY2023 | C1: FY2024 | D1: FY2025 | E1: FY2026 | F1: FY2027E | G1: FY2028E | H1: FY2029E | I1: FY2030E | J1: FY2031E | K1: Source / note
A2: PBDIT margin (%) | B2: =100*'Income Statement'!B3/'Income Statement'!B2 -> 17.266252 | C2: =100*'Income Statement'!C3/'Income Statement'!C2 -> 19.496496 | D2: =100*'Income Statement'!D3/'Income Statement'!D2 -> 18.713934 | E2: =100*'Income Statement'!E3/'Income Statement'!E2 -> 18.498803 | F2: =100*'Income Statement'!F3/'Income Statement'!F2 -> 18.57828 | G2: =100*'Income Statement'!G3/'Income Statement'!G2 -> 18.724928 | H2: =100*'Income Statement'!H3/'Income Statement'!H2 -> 19.001926 | I2: =100*'Income Statement'!I3/'Income Statement'!I2 -> 19.198293 | J2: =100*'Income Statement'!J3/'Income Statement'!J2 -> 19.434602
A3: PAT margin (%) | B3: =100*'Income Statement'!B11/'Income Statement'!B2 -> 8.3122502 | C3: =100*'Income Statement'!C11/'Income Statement'!C2 -> 8.6410519 | D3: =100*'Income Statement'!D11/'Income Statement'!D2 -> 8.2956855 | E3: =100*'Income Statement'!E11/'Income Statement'!E2 -> 8.9017594 | F3: =100*'Income Statement'!F11/'Income Statement'!F2 -> 8.5369545 | G3: =100*'Income Statement'!G11/'Income Statement'!G2 -> 8.6455868 | H3: =100*'Income Statement'!H11/'Income Statement'!H2 -> 8.9099922 | I3: =100*'Income Statement'!I11/'Income Statement'!I2 -> 9.1753895 | J3: =100*'Income Statement'!J11/'Income Statement'!J2 -> 9.4924773
A4: Adjusted total debt (borrowings + leases + DoT liabilities) | B4: ='Balance Sheet'!B11+'Balance Sheet'!B12+'Balance Sheet'!B13 -> 451664 | C4: ='Balance Sheet'!C11+'Balance Sheet'!C12+'Balance Sheet'!C13 -> 458991 | D4: ='Balance Sheet'!D11+'Balance Sheet'!D12+'Balance Sheet'!D13 -> 478723 | E4: ='Balance Sheet'!E11+'Balance Sheet'!E12+'Balance Sheet'!E13 -> 502514 | F4: ='Balance Sheet'!F11+'Balance Sheet'!F12+'Balance Sheet'!F13 -> 497552 | G4: ='Balance Sheet'!G11+'Balance Sheet'!G12+'Balance Sheet'!G13 -> 492252 | H4: ='Balance Sheet'!H11+'Balance Sheet'!H12+'Balance Sheet'!H13 -> 486602 | I4: ='Balance Sheet'!I11+'Balance Sheet'!I12+'Balance Sheet'!I13 -> 480552 | J4: ='Balance Sheet'!J11+'Balance Sheet'!J12+'Balance Sheet'!J13 -> 474102
A5: Adjusted networth (owners + NCI) | B5: ='Balance Sheet'!B9+'Balance Sheet'!B10 -> 828881 | C5: ='Balance Sheet'!C9+'Balance Sheet'!C10 -> 925788 | D5: ='Balance Sheet'!D9+'Balance Sheet'!D10 -> 1009626 | E5: ='Balance Sheet'!E9+'Balance Sheet'!E10 -> 1085866 | F5: ='Balance Sheet'!F9+'Balance Sheet'!F10 -> 1176633.2 | G5: ='Balance Sheet'!G9+'Balance Sheet'!G10 -> 1275590.1 | H5: ='Balance Sheet'!H9+'Balance Sheet'!H10 -> 1384969.8 | I5: ='Balance Sheet'!I9+'Balance Sheet'!I10 -> 1505617.4 | J5: ='Balance Sheet'!J9+'Balance Sheet'!J10 -> 1638927.5
A6: Gearing - adjusted debt / adjusted networth (x) | B6: =B4/B5 -> 0.54490814 | C6: =C4/C5 -> 0.49578413 | D6: =D4/D5 -> 0.47415875 | E6: =E4/E5 -> 0.46277718 | F6: =F4/F5 -> 0.42286076 | G6: =G4/G5 -> 0.38590139 | H6: =H4/H5 -> 0.35134483 | I6: =I4/I5 -> 0.31917273 | J6: =J4/J5 -> 0.28927576
A7: TOL / adjusted networth (x) | B7: =('Balance Sheet'!B8-B5)/B5 -> 0.93927838 | C7: =('Balance Sheet'!C8-C5)/C5 -> 0.89674742 | D7: =('Balance Sheet'!D8-D5)/D5 -> 0.93152811 | E7: =('Balance Sheet'!E8-E5)/E5 -> 1.0059013 | F7: =('Balance Sheet'!F8-F5)/F5 -> 0.94773111 | G7: =('Balance Sheet'!G8-G5)/G5 -> 0.89237975 | H7: =('Balance Sheet'!H8-H5)/H5 -> 0.84009548 | I7: =('Balance Sheet'!I8-I5)/I5 -> 0.79110713 | J7: =('Balance Sheet'!J8-J5)/J5 -> 0.74479567
A8: Adjusted debt / PBDIT (x) | B8: =B4/'Income Statement'!B3 -> 2.9348651 | C8: =C4/'Income Statement'!C3 -> 2.5744069 | D8: =D4/'Income Statement'!D3 -> 2.6099541 | E8: =E4/'Income Statement'!E3 -> 2.525361 | F8: =F4/'Income Statement'!F3 -> 2.3015928 | G8: =G4/'Income Statement'!G3 -> 2.1074921 | H8: =H4/'Income Statement'!H3 -> 1.9169241 | I8: =I4/'Income Statement'!I3 -> 1.7492426 | J8: =J4/'Income Statement'!J3 -> 1.5963891
A9: Interest incl. capitalised | B9: ='Income Statement'!B6+'Income Statement'!B7 -> 28401 | C9: ='Income Statement'!C6+'Income Statement'!C7 -> 38340 | D9: ='Income Statement'!D6+'Income Statement'!D7 -> 42552 | E9: ='Income Statement'!E6+'Income Statement'!E7 -> 43152 | F9: ='Income Statement'!F6+'Income Statement'!F7 -> 40122.32 | G9: ='Income Statement'!G6+'Income Statement'!G7 -> 39711.84 | H9: ='Income Statement'!H6+'Income Statement'!H7 -> 39273.84 | I9: ='Income Statement'!I6+'Income Statement'!I7 -> 38805.84 | J9: ='Income Statement'!J6+'Income Statement'!J7 -> 38305.84
A10: Interest coverage - PBDIT / interest incl. capitalised (x) | B10: ='Income Statement'!B3/B9 -> 5.4186824 | C10: ='Income Statement'!C3/C9 -> 4.6502347 | D10: ='Income Statement'!D3/D9 -> 4.3105377 | E10: ='Income Statement'!E3/E9 -> 4.6113042 | F10: ='Income Statement'!F3/F9 -> 5.3879548 | G10: ='Income Statement'!G3/G9 -> 5.8816816 | H10: ='Income Statement'!H3/H9 -> 6.463468 | I10: ='Income Statement'!I3/I9 -> 7.0793478 | J10: ='Income Statement'!J3/J9 -> 7.7529687
A11: NCATD - (PAT - dividend + D&A) / adjusted debt (x) | B11: =('Income Statement'!B11-'Cash Flow'!B6+'Income Statement'!B5)/B4 -> 0.24201176 | C11: =('Income Statement'!C11-'Cash Flow'!C6+'Income Statement'!C5)/C4 -> 0.26964145 | D11: =('Income Statement'!D11-'Cash Flow'!D6+'Income Statement'!D5)/D4 -> 0.26584267 | E11: =('Income Statement'!E11-'Cash Flow'!E6+'Income Statement'!E5)/E4 -> 0.28966954 | F11: =('Income Statement'!F11-'Cash Flow'!F6+'Income Statement'!F5)/F4 -> 0.30762737 | G11: =('Income Statement'!G11-'Cash Flow'!G6+'Income Statement'!G5)/G4 -> 0.33713923 | H11: =('Income Statement'!H11-'Cash Flow'!H6+'Income Statement'!H5)/H4 -> 0.37104202 | I11: =('Income Statement'!I11-'Cash Flow'!I6+'Income Statement'!I5)/I4 -> 0.40629754 | J11: =('Income Statement'!J11-'Cash Flow'!J6+'Income Statement'!J5)/J4 -> 0.44476354
A12: RoCE - PBIT / avg (adj. debt + adj. networth + DTL) (%) | C12: =100*('Income Statement'!C3-'Income Statement'!C5)/((C4+C5+'Balance Sheet'!C14+B4+B5+'Balance Sheet'!B14)/2) -> 9.1110119 | D12: =100*('Income Statement'!D3-'Income Statement'!D5)/((D4+D5+'Balance Sheet'!D14+C4+C5+'Balance Sheet'!C14)/2) -> 8.6030807 | E12: =100*('Income Statement'!E3-'Income Statement'!E5)/((E4+E5+'Balance Sheet'!E14+D4+D5+'Balance Sheet'!D14)/2) -> 8.6735911 | F12: =100*('Income Statement'!F3-'Income Statement'!F5)/((F4+F5+'Balance Sheet'!F14+E4+E5+'Balance Sheet'!E14)/2) -> 8.8608983 | G12: =100*('Income Statement'!G3-'Income Statement'!G5)/((G4+G5+'Balance Sheet'!G14+F4+F5+'Balance Sheet'!F14)/2) -> 9.0436592 | H12: =100*('Income Statement'!H3-'Income Statement'!H5)/((H4+H5+'Balance Sheet'!H14+G4+G5+'Balance Sheet'!G14)/2) -> 9.3320683 | I12: =100*('Income Statement'!I3-'Income Statement'!I5)/((I4+I5+'Balance Sheet'!I14+H4+H5+'Balance Sheet'!H14)/2) -> 9.5964667 | J12: =100*('Income Statement'!J3-'Income Statement'!J5)/((J4+J5+'Balance Sheet'!J14+I4+I5+'Balance Sheet'!I14)/2) -> 9.8544369
A13: Net adjusted debt (adj. debt - cash and current investments) | B13: =B4-'Balance Sheet'!B6 -> 264527 | C13: =C4-'Balance Sheet'!C6 -> 255596 | D13: =D4-'Balance Sheet'!D6 -> 253512 | E13: =E4-'Balance Sheet'!E6 -> 259106 | F13: =F4-'Balance Sheet'!F6 -> 261899.15 | G13: =G4-'Balance Sheet'!G6 -> 243218.92 | H13: =H4-'Balance Sheet'!H6 -> 196551.5 | I13: =I4-'Balance Sheet'!I6 -> 126780.45 | J13: =J4-'Balance Sheet'!J6 -> 32527.522
A14: Net adjusted debt / PBDIT (x) | B14: =B13/'Income Statement'!B3 -> 1.7188686 | C14: =C13/'Income Statement'!C3 -> 1.4335969 | D14: =D13/'Income Statement'!D3 -> 1.3821243 | E14: =E13/'Income Statement'!E3 -> 1.3021253 | F14: =F13/'Income Statement'!F3 -> 1.2115019 | G14: =G13/'Income Statement'!G3 -> 1.0412999 | H14: =H13/'Income Statement'!H3 -> 0.77429668 | I14: =I13/'Income Statement'!I3 -> 0.46148964 | J14: =J13/'Income Statement'!J3 -> 0.10952618
A16: Supplier finance (note 44) is NOT in adjusted debt here; adding it (76,377 FY2026) takes gearing to 0.53x and adjusted debt/PBDIT to 2.91x (engine 'incl. SF' rows). Net-debt rows use cash + current investments only; the AR's own 'cash and marketable securities' also adds 6,296 of other marketable securities (FY2026).

Sheet Scenarios
A1: Scenario / metric | B1: FY2027E | C1: FY2028E | D1: FY2029E | E1: FY2030E | F1: FY2031E | G1: Note
A2: BASE
A3: Revenue from operations | B3: 1163602 | C3: 1247387.4 | D3: 1335892 | E3: 1430960.7 | F3: 1528119.7
A4: PBDIT | B4: 216177.25 | C4: 233572.4 | D4: 253845.21 | E4: 274720.04 | F4: 296983.98
A5: PBDIT margin (%) | B5: 18.58 | C5: 18.72 | D5: 19 | E5: 19.2 | F5: 19.43
A6: PAT | B6: 99336.18 | C6: 107843.96 | D6: 119027.87 | E6: 131296.22 | F6: 145056.42
A7: Cash and current investments | B7: 235652.85 | C7: 249033.08 | D7: 290050.5 | E7: 353771.55 | F7: 441574.48
A8: New borrowing drawn (funding gap) | B8: 0 | C8: 0 | D8: 0 | E8: 0 | F8: 0
A9: Adjusted total debt | B9: 497552 | C9: 492252 | D9: 486602 | E9: 480552 | F9: 474102
A10: Gearing (x) | B10: 0.42 | C10: 0.39 | D10: 0.35 | E10: 0.32 | F10: 0.29
A11: Adjusted debt / PBDIT (x) | B11: 2.3 | C11: 2.11 | D11: 1.92 | E11: 1.75 | F11: 1.6
A12: Net adjusted debt / PBDIT (x) | B12: 1.21 | C12: 1.04 | D12: 0.77 | E12: 0.46 | F12: 0.11
A13: Interest coverage incl. capitalised (x) | B13: 5.39 | C13: 5.88 | D13: 6.46 | E13: 7.08 | F13: 7.75
A14: NCATD (x) | B14: 0.31 | C14: 0.34 | D14: 0.37 | E14: 0.41 | F14: 0.44
A15: RoCE (%) | B15: 8.86 | C15: 9.04 | D15: 9.33 | E15: 9.6 | F15: 9.85
A16: BULL
A17: Revenue from operations | B17: 1172561.7 | C17: 1267665 | D17: 1372199.6 | E17: 1486900.1 | F17: 1614960.9
A18: PBDIT | B18: 230727.98 | C18: 253112.59 | D18: 278884.76 | E18: 304812.37 | F18: 334728.8
A19: PBDIT margin (%) | B19: 19.68 | C19: 19.97 | D19: 20.32 | E19: 20.5 | F19: 20.73
A20: PAT | B20: 110540.24 | C20: 122889.91 | D20: 138308.33 | E20: 154467.32 | F20: 174119.93
A21: Cash and current investments | B21: 247975.6 | C21: 276945.89 | D21: 337784.9 | E21: 425197.46 | F21: 542418.59
A22: New borrowing drawn (funding gap) | B22: 0 | C22: 0 | D22: 0 | E22: 0 | F22: 0
A23: Adjusted total debt | B23: 497552 | C23: 492252 | D23: 486602 | E23: 480552 | F23: 474102
A24: Gearing (x) | B24: 0.42 | C24: 0.38 | D24: 0.34 | E24: 0.31 | F24: 0.27
A25: Adjusted debt / PBDIT (x) | B25: 2.16 | C25: 1.94 | D25: 1.74 | E25: 1.58 | F25: 1.42
A26: Net adjusted debt / PBDIT (x) | B26: 1.08 | C26: 0.85 | D26: 0.53 | E26: 0.18 | F26: -0.2
A27: Interest coverage incl. capitalised (x) | B27: 5.75 | C27: 6.37 | D27: 7.1 | E27: 7.85 | F27: 8.74
A28: NCATD (x) | B28: 0.33 | C28: 0.37 | D28: 0.41 | E28: 0.45 | F28: 0.5
A29: RoCE (%) | B29: 9.66 | C29: 9.99 | D29: 10.4 | E29: 10.72 | F29: 11.1
A30: BEAR / RATING STRESS
A31: Revenue from operations | B31: 1052556 | C31: 1061637.2 | D31: 1120041.2 | E31: 1186435.5 | F31: 1258063.7
A32: PBDIT | B32: 175025.47 | C32: 177723.33 | D32: 197913.71 | E32: 212943.13 | F32: 229540.24
A33: PBDIT margin (%) | B33: 16.63 | C33: 16.74 | D33: 17.67 | E33: 17.95 | F33: 18.25
A34: PAT | B34: 65415.18 | C34: 57913.69 | D34: 65576.32 | E34: 70830.31 | F34: 78886.24
A35: Cash and current investments | B35: 199999.99 | C35: 200000 | D35: 200000 | E35: 200000 | F35: 213878.28
A36: New borrowing drawn (funding gap) | B36: 120894.22 | C36: 61222.89 | D36: 36895.91 | E36: 10405.41 | F36: 0
A37: Adjusted total debt | B37: 618446.22 | C37: 674369.11 | D37: 705615.03 | E37: 709970.43 | F37: 703520.43
A38: Gearing (x) | B38: 0.54 | C38: 0.56 | D38: 0.56 | E38: 0.54 | F38: 0.51
A39: Adjusted debt / PBDIT (x) | B39: 3.53 | C39: 3.79 | D39: 3.57 | E39: 3.33 | F39: 3.06
A40: Net adjusted debt / PBDIT (x) | B40: 2.39 | C40: 2.67 | D40: 2.55 | E40: 2.39 | F40: 2.13
...

Sheet DCF Inputs
A1: Rs crore | B1: FY2023 | C1: FY2024 | D1: FY2025 | E1: FY2026 | F1: FY2027E | G1: FY2028E | H1: FY2029E | I1: FY2030E | J1: FY2031E | K1: Source / note
A2: PBDIT | B2: 153896 | C2: 178290 | D2: 183422 | E2: 198987 | F2: 216177.25 | G2: 233572.4 | H2: 253845.21 | I2: 274720.04 | J2: 296983.98 | K2: Income Statement
A3: Less: treasury income (valued separately as cash) | F3: 10466.544 | G3: 10133.073 | H3: 10708.422 | I3: 12472.172 | J3: 15212.177
A4: Less: capex | B4: 140988 | C4: 152883 | D4: 139967 | E4: 122916 | F4: 150000 | G4: 145000 | H4: 135000 | I4: 130000 | J4: 125000
A5: UNLEVERED FREE CASH FLOW (after cash tax on EBIT, capex and working capital) | F5: 33774.567 | G5: 55262.103 | H5: 82881.71 | I5: 104783.05 | J5: 127272

Sheet Valuation
A1: Valuation (Rs crore) - informs financial flexibility only (Step 12(f)); it does not move the grade.
A2: ANALYST ASSUMPTIONS: WACC 11.0% (cost of equity ~12%, post-tax cost of debt ~6%, ~20% debt weight); terminal growth 5.0% nominal. Minority interests deducted at book (no market value disclosed).
A3: Enterprise value (WACC 11.0%, g 5.0%) | B3: 1602205.9
A4: Less: net adjusted debt 31-Mar-2026 (incl. DoT, leases; cash and marketable securities netted) | B4: 252810 | C4: engine
A5: Less: non-controlling interest at book 31-Mar-2026 | B5: 181836 | C5: balance sheet
A6: Implied equity value | B6: 1167559.9
A7: Implied value per share (Rs) | B7: 862.78 | C7: 1,353.25 crore shares
A8: Market price (Rs, screener.in 10-Oct-2026; not exchange-verified) | B8: 1170 | C8: 52-week range Rs 1,160-1,612
A9: Market capitalisation (Rs crore, screener.in) | B9: 1583713
A10: Market capitalisation / adjusted total debt 31-Mar-2026 (x) | B10: 3.15 | C10: the financial-flexibility reading: equity cushion over debt
A11: Market capitalisation / adjusted debt incl. supplier finance (x) | B11: 2.74
A13: Sensitivity: equity value (Rs crore) | B13: g 4.0% | C13: g 4.5% | D13: g 5.0% | E13: g 5.5% | F13: g 6.0%
A14: WACC 10.0% | B14: 1224376 | C14: 1356086 | D14: 1514138 | E14: 1707312 | F14: 1948780
A15: WACC 10.5% | B15: 1086208 | C15: 1195651 | D15: 1324993 | E15: 1480204 | F15: 1669906
A16: WACC 11.0% | B16: 967946 | C16: 1060075 | D16: 1167560 | E16: 1294587 | F16: 1447020
A17: WACC 11.5% | B17: 865604 | C17: 944027 | D17: 1034515 | E17: 1140085 | F17: 1264849
A18: WACC 12.0% | B18: 776195 | C18: 843598 | D18: 920630 | E18: 1009514 | F18: 1113211

Sheet Debt Breakup
A1: (i) STATUTORY BORROWINGS - consolidated (Rs crore) | B1: FY2023 | C1: FY2024 | D1: FY2025 | E1: FY2026 | F1: Source
A2: Non-current borrowings | B2: 183176 | C2: 222712 | D2: 236899 | E2: 270751 | F2: balance sheet (note 16)
A3: Current borrowings (incl. current maturities) | B3: 130790 | C3: 101910 | D3: 110631 | E3: 103670 | F3: balance sheet (note 20)
A4: of which current maturities of non-current borrowings | B4: 48532 | C4: 45268 | D4: 29323 | E4: 25965 | F4: note 20
A5: of which commercial paper | B5: 20506 | C5: 19595 | D5: 29162 | E5: 13186 | F5: note 20
A6: GROSS DEBT (company definition) | B6: 313966 | C6: 324622 | D6: 347530 | E6: 374421 | F6: equals note 35 gross debt; screener.in tie in spreads
A7: Lease liabilities (non-current + current) | B7: 20426 | C7: 21520 | D7: 22045 | E7: 23579 | F7: balance sheet
A8: DoT deferred payment liabilities (note 17 + current maturity in note 22) | B8: 117272 | C8: 112849 | D8: 109148 | E8: 104514 | F8: notes 17, 22
A9: ADJUSTED TOTAL DEBT (CRISIL) | B9: 451664 | C9: 458991 | D9: 478723 | E9: 502514 | F9: engine
A10: Supplier-finance arrangements (in trade payables / other financial liabilities) | D10: 103716 | E10: 76377 | F10: note 44; first disclosed for FY2025
A11: ADJUSTED DEBT incl. supplier finance | D11: 582439 | E11: 578891 | F11: wide measure
A13: (ii) INSTRUMENT VIEW (note 16 / 20, FY2025-26 AR) | D13: FY2025 | E13: FY2026
A14: NC: Secured NCDs | D14: 20415 | E14: 20545 | F14: note 16
A15: NC: Secured term loans from banks | D15: 1089 | E15: 640 | F15: note 16
A16: NC: Unsecured NCDs | D16: 7367 | E16: 7369 | F16: note 16
A17: NC: Bonds (foreign currency) | D17: 52048 | E17: 57274 | F17: note 16
A18: NC: Unsecured term loans from banks | D18: 154683 | E18: 183436 | F18: note 16
A19: NC: Unsecured term loans from others | D19: 1297 | E19: 1487 | F19: note 16
A20: Current: Secured WC loans from banks | D20: 15594 | E20: 17146 | F20: note 20
A21: Current: Secured WC loans from others | D21: 0 | E21: 7 | F21: note 20
A22: Current: Unsecured WC loans from others | D22: 0 | E22: 32 | F22: note 20
A23: Current: Unsecured loans from banks | D23: 33124 | E23: 47334 | F23: note 20
A24: Current: Unsecured loans from others | D24: 3366 | E24: 0 | F24: note 20
A25: Current: Commercial paper (note 20) | D25: 29162 | E25: 13186 | F25: note 20
... A27: Current: Current maturities (note 20) | D27: 29323 | E27: 25965 | F27: note 20
A28: Secured NCDs: 7.79% Rs 20,000 crore (15,000 due 2033-34; 5,000 due 2032-33) | E28: 20000 | F28: note 16.3 (face); unsecured NCDs 7,389 at 8.65-9.05% due 2028-29
A29: DoT liabilities by auction: Mar-2021 7.30% / Aug-2022 7.20% / Jul-2024 8.65% | E29: 30,213 / 73,425 / 876 | F29: note 17 footnote
A30: Currency mix | F30: foreign-currency bonds 57,274 (NC) + 510 (current); FC term loans and ECBs inside term loans - split not disclosed in the notes read
A32: (iii) THE AR'S OWN NET-DEBT BRIDGE (note 35) | B32: FY2023 | C32: FY2024 | D32: FY2025 | E32: FY2026
A33: Gross debt | B33: 313966 | C33: 324622 | D33: 347530 | E33: 374421 | F33: note 35 capital management
A34: Cash and marketable securities | B34: 188200 | C34: 208341 | D34: 230447 | E34: 249704 | F34: note 35 capital management
A35: Net debt | B35: 125766 | C35: 116281 | D35: 117083 | E35: 124717 | F35: note 35 capital management
A36: Equity attributable to owners | B36: 715872 | C36: 793481 | D36: 843200 | E36: 904030 | F36: note 35 capital management
A37: Arithmetic: gross debt - cash & MS | B37: 125766 | C37: 116281 | D37: 117083 | E37: 124717 | F37: equals printed net debt every year
A38: Company net gearing (x) | B38: 0.18 | C38: 0.15 | D38: 0.14 | E38: 0.14 | F38: printed 0.18 / 0.15 / 0.14 / 0.14
A39: Analyst net adjusted debt (adds leases + DoT liabilities) | B39: 263505 | C39: 250616 | D39: 248276 | E39: 252810 | F39: basis difference: company net debt excludes leases (23,579) and DoT liabilities (1,04,514) in FY2026
A41: (iv) RATED LIMITS vs DRAWN DEBT | E41: Rs crore
A42: CRISIL bank facilities - CRA-PUBLISHED 30-Mar-2026 (Credit Bulletin), NOT issuer-confirmed | E42: see rationale Annexure | F42: ECB 23,424 + fund-based 22,740 + non-fund-based 50,510 + proposed 326 + term loan 3,000
A43: Drawn borrowings 31-Mar-2026 (consolidated, all entities) | E43: 374421 | F43: limits (RIL facilities) and consolidated drawn debt are different measures and are not expected to reconcile
