Workbook

Sheet README
B2: Credit Rating Scorecard - CRISIL
B4: How to use
B5: 1. On the Inputs sheet, fill every YELLOW cell: issuer, agency, sector, three years of financials, projection assumptions and the qualitative scores.
B6: 2. The Projections sheet builds FY+1/FY+2 earnings (future earning potential) from your assumptions.
B7: 3. The Ratios sheet computes the ratio set for all five years, labelled in the selected agency's conventions (OPBDIT / EBITDA / PBILDT etc.).
B8: 4. The Scorecard sheet scores financial risk automatically from threshold bands (Ref_Bands), takes your qualitative scores for industry/business/management, and weights them by the SECTOR you picked (Ref_Weights).
B9: 5. The Rating sheet converts the weighted score to a grade on the selected AGENCY's scale, applies support notches and hard caps, maps the short-term rating, and prints the rating line in that agency's house style.
B11: Legend
B12: YELLOW fill + blue text = cells you edit. Black = formulas (do not edit). Green = links to another sheet. An example issuer ('Example Manufacturing Ltd') is pre-filled to show the expected format - overwrite it with your issuer.
B14: Scoring convention
B15: All scores run 1 (strongest) to 6 (weakest), consistent with the credit-rating-tool scorecard. The composite maps onto the 17-notch AAA..C scale; D is assigned only on actual default, never by the scorecard.
B17: Assumptions and sources
... B26: This is an analytical exercise tool; the output is an ANCHOR grade, not an agency rating. Qualitative judgment, peer comparison and the full methodology always override.

Sheet Inputs
B2: Inputs - fill every yellow cell
B4: Issuer name | C4: JSW Steel Limited | F4: Example values pre-filled throughout - replace with your issuer's audited figures.
B5: Rating agency | C5: CRISIL
B6: Sector | C6: Iron & Steel / Metals / Mining
B7: Rating date | C7: 13-Jul-2026
B10: Historical financials (Rs crore, audited)
B11: Line item | C11: FY2024 | D11: FY2025 | E11: FY2026
B12: Total operating income | C12: 175006 | D12: 168824 | E12: 185470
B13: EBITDA (OPBDIT / PBILDT) | C13: 28236 | D13: 22904 | E13: 29821
B14: Depreciation & amortisation | C14: 8172 | D14: 9309 | E14: 9601
B15: Interest expense | C15: 8105 | D15: 8412 | E15: 9102
B16: Profit after tax (PAT) | C16: 8973 | D16: 3504 | E16: 8698
B17: Total debt (incl. lease liabilities) | C17: 87984 | D17: 98752 | E17: 99310
B18: Cash & liquid investments | C18: 12351 | D18: 19104 | E18: 41507
B19: Tangible net worth | C19: 79776 | D19: 81666 | E19: 105475
B20: Total outside liabilities | C20: 148422 | D20: 159076 | E20: 164201
B21: Current assets | C21: 64534 | D21: 70736 | E21: 103435
B22: Current liabilities | C22: 66065 | D22: 60626 | E22: 69377
B23: Capital expenditure | C23: 0 | D23: 0 | E23: 15595
B24: Dividends paid | C24: 0 | D24: 0 | E24: 1462
B27: Projection assumptions (future earning potential)
B28: Assumption | C28: FY+1 | D28: FY+2
B29: Revenue growth (%) | C29: -0.04 | D29: 0.09
B30: EBITDA margin (%) | C30: 0.165 | D30: 0.168
B31: Capital expenditure (Rs crore) | C31: 23000 | D31: 25000
B32: Net new debt + / (repayment) (Rs crore) | C32: 2000 | D32: 6000
B33: Average interest rate on debt (%) | C33: 0.0875 | D33: 0.0875
B34: Tax rate (%) | C34: 0.25 | D34: 0.25
B35: Dividend payout (% of PAT) | C35: 0.24 | D35: 0.24
B38: Qualitative assessment (1 = strongest ... 6 = weakest)
B39: Industry risk override (blank = use sector base from Ref_Weights) | F39: Leave blank to accept the sector's base score; enter 1-6 to override.
B40: Business risk / market position score | C40: 2 | F40: Market share, brand/distribution, diversification, pricing power vs peers.
B41: Management & governance score | C41: 3 | F41: Track record, financial policy/risk appetite, governance, group linkages.
B42: Parent/group support notches (+ = uplift, - = drag) | C42: 0 | F42: Per the agency's parent/group notching criteria; usually 0 to +/-3.
B43: Liquidity descriptor | C43: Strong | F43: Superior/Strong lifts ST mapping in overlap bands and improves the composite (Ref_Scales).
B44: Outlook | C44: Stable
B47: Financial-sector inputs - fill ONLY if Sector is Bank / NBFC / HFC | F47: For a financial issuer, leave the corporate financials/projections above at their example values (they are ignored) and fill these instead.
B48: Metric | C48: Latest | D48: Expected FY+1
B49: Capital adequacy - CRAR (%) | C49: 0.16 | D49: 0.158
B50: Gross NPA (%) | C50: 0.025 | D50: 0.022
...

Sheet Projections
B2: Projections - future earning potential (all formulas; edit assumptions on Inputs)
B4: Rs crore | C4: FY+1 | D4: FY+2
B5: Revenue | C5: =Inputs!E12*(1+Inputs!C29) | D5: =C5*(1+Inputs!D29)
B6: EBITDA | C6: =C5*Inputs!C30 | D6: =D5*Inputs!D30
B7: Depreciation | C7: =Inputs!E14 | D7: =C7
B8: EBIT | C8: =C6-C7 | D8: =D6-D7
B9: Total debt (closing) | C9: =Inputs!E17+Inputs!C32 | D9: =C9+Inputs!D32
B10: Interest expense | C10: =AVERAGE(Inputs!E17,C9)*Inputs!C33 | D10: =AVERAGE(C9,D9)*Inputs!D33
B11: Profit before tax | C11: =C8-C10 | D11: =D8-D10
B12: Tax | C12: =MAX(C11,0)*Inputs!C34 | D12: =MAX(D11,0)*Inputs!D34
B13: PAT | C13: =C11-C12 | D13: =D11-D12
B14: Gross cash accruals (PAT + Dep) | C14: =C13+C7 | D14: =D13+D7
B15: Dividends | C15: =C13*Inputs!C35 | D15: =D13*Inputs!D35
B16: Tangible net worth (closing) | C16: =Inputs!E19+C13-C15 | D16: =C16+D13-D15
B17: Cash & liquid investments (closing) | C17: =Inputs!E18+C14-Inputs!C31-C15+Inputs!C32 | D17: =C17+D14-Inputs!D31-D15+Inputs!D32
B18: Free cash flow (GCA - capex - dividends) | C18: =C14-Inputs!C31-C15 | D18: =D14-Inputs!D31-D15
B20: Interest on average of opening/closing debt. Depreciation held at FY0 level (conservative for flat capex). No equity raising assumed - an unraised issue is not a committed source of funds.

Sheet Ratios
B2: Ratios - five years, in the selected agency's conventions
B3: ="Agency: "&Inputs!C5&" | EBITDA is labelled "&INDEX(Ref_Scales!I5:I7,MATCH(Inputs!C5,Ref_Scales!H5:H7,0))&" by this agency"
B5: Ratio | C5: =Inputs!C11 | D5: =Inputs!D11 | E5: =Inputs!E11 | F5: FY+1 (P) | G5: FY+2 (P)
B6: Revenue growth (%) | C6: n.a. | D6: =Inputs!D12/Inputs!C12-1 | E6: =Inputs!E12/Inputs!D12-1 | F6: =Projections!C5/Inputs!E12-1 | G6: =Projections!D5/Projections!C5-1
B7: =INDEX(Ref_Scales!I5:I7,MATCH(Inputs!C5,Ref_Scales!H5:H7,0))&" margin (%)" | C7: =Inputs!C13/Inputs!C12 | D7: =Inputs!D13/Inputs!D12 | E7: =Inputs!E13/Inputs!E12 | F7: =Projections!C6/Projections!C5 | G7: =Projections!D6/Projections!D5
B8: PAT margin (%) | C8: =Inputs!C16/Inputs!C12 | D8: =Inputs!D16/Inputs!D12 | E8: =Inputs!E16/Inputs!E12 | F8: =Projections!C13/Projections!C5 | G8: =Projections!D13/Projections!D5
B9: ROCE (EBIT / (TD + TNW)) (%) | C9: =(Inputs!C13-Inputs!C14)/(Inputs!C17+Inputs!C19) | D9: =(Inputs!D13-Inputs!D14)/(Inputs!D17+Inputs!D19) | E9: =(Inputs!E13-Inputs!E14)/(Inputs!E17+Inputs!E19) | F9: =Projections!C8/(Projections!C9+Projections!C16) | G9: =Projections!D8/(Projections!D9+Projections!D16)
B10: ="Gearing / overall gearing - Total debt/TNW (x)" | C10: =Inputs!C17/Inputs!C19 | D10: =Inputs!D17/Inputs!D19 | E10: =Inputs!E17/Inputs!E19 | F10: =Projections!C9/Projections!C16 | G10: =Projections!D9/Projections!D16
B11: TOL/TNW (x) | C11: =Inputs!C20/Inputs!C19 | D11: =Inputs!D20/Inputs!D19 | E11: =Inputs!E20/Inputs!E19 | F11: n.a. | G11: n.a.
B12: ="Total debt/"&INDEX(Ref_Scales!I5:I7,MATCH(Inputs!C5,Ref_Scales!H5:H7,0))&" (x)" | C12: =Inputs!C17/Inputs!C13 | D12: =Inputs!D17/Inputs!D13 | E12: =Inputs!E17/Inputs!E13 | F12: =Projections!C9/Projections!C6 | G12: =Projections!D9/Projections!D6
B13: Total debt/GCA (x) | C13: =Inputs!C17/(Inputs!C16+Inputs!C14) | D13: =Inputs!D17/(Inputs!D16+Inputs!D14) | E13: =Inputs!E17/(Inputs!E16+Inputs!E14) | F13: =Projections!C9/Projections!C14 | G13: =Projections!D9/Projections!D14
B14: Interest coverage (x) | C14: =Inputs!C13/Inputs!C15 | D14: =Inputs!D13/Inputs!D15 | E14: =Inputs!E13/Inputs!E15 | F14: =Projections!C6/Projections!C10 | G14: =Projections!D6/Projections!D10
B15: GCA/Total debt (x) | C15: =(Inputs!C16+Inputs!C14)/Inputs!C17 | D15: =(Inputs!D16+Inputs!D14)/Inputs!D17 | E15: =(Inputs!E16+Inputs!E14)/Inputs!E17 | F15: =Projections!C14/Projections!C9 | G15: =Projections!D14/Projections!D9
B16: Current ratio (x) | C16: =Inputs!C21/Inputs!C22 | D16: =Inputs!D21/Inputs!D22 | E16: =Inputs!E21/Inputs!E22 | F16: n.a. | G16: n.a.
B17: Net debt (TD - cash & liquid) (Rs crore) | C17: =Inputs!C17-Inputs!C18 | D17: =Inputs!D17-Inputs!D18 | E17: =Inputs!E17-Inputs!E18 | F17: =Projections!C9-Projections!C17 | G17: =Projections!D9-Projections!D17
B19: Guarded denominators: enter non-zero TNW/EBITDA/interest; zero inputs will show Excel errors by design (fix the input, not the formula).

Sheet Scorecard
B2: Scorecard - financial risk auto-scored; qualitative from Inputs; weights by sector
B4: 1 - Financial risk (assessed on average of FY0 actual and FY+1 projected)
B5: Metric | C5: FY0 | D5: FY+1 (P) | E5: Assessed | F5: Score (1-6) | G5: Weight | H5: Wtd
B6: Interest coverage (x) | C6: =Ratios!E14 | D6: =Ratios!F14 | E6: =AVERAGE(C6:D6) | F6: =IF(Ref_Bands!$B$5="higher",6-COUNTIF(Ref_Bands!$C$5:$G$5,"<="&E6),1+COUNTIF(Ref_Bands!$C$5:$G$5,"<"&E6)) | G6: =Ref_Bands!$H$5 | H6: =F6*G6 | I6: Scores 1 (strongest) - 6 (weakest) from Ref_Bands thresholds; current ratio assessed on FY0 only (no projected balance-sheet split).
B7: Gearing - TD/TNW (x) | C7: =Ratios!E10 | D7: =Ratios!F10 | E7: =AVERAGE(C7:D7) | F7: =IF(Ref_Bands!$B$6="higher",6-COUNTIF(Ref_Bands!$C$6:$G$6,"<="&E7),1+COUNTIF(Ref_Bands!$C$6:$G$6,"<"&E7)) | G7: =Ref_Bands!$H$6 | H7: =F7*G7
B8: Total debt/EBITDA (x) | C8: =Ratios!E12 | D8: =Ratios!F12 | E8: =AVERAGE(C8:D8) | F8: =IF(Ref_Bands!$B$7="higher",6-COUNTIF(Ref_Bands!$C$7:$G$7,"<="&E8),1+COUNTIF(Ref_Bands!$C$7:$G$7,"<"&E8)) | G8: =Ref_Bands!$H$7 | H8: =F8*G8
B9: EBITDA margin (fraction) | C9: =Ratios!E7 | D9: =Ratios!F7 | E9: =AVERAGE(C9:D9) | F9: =IF(Ref_Bands!$B$8="higher",6-COUNTIF(Ref_Bands!$C$8:$G$8,"<="&E9),1+COUNTIF(Ref_Bands!$C$8:$G$8,"<"&E9)) | G9: =Ref_Bands!$H$8 | H9: =F9*G9
B10: GCA/Total debt (x) | C10: =Ratios!E15 | D10: =Ratios!F15 | E10: =AVERAGE(C10:D10) | F10: =IF(Ref_Bands!$B$9="higher",6-COUNTIF(Ref_Bands!$C$9:$G$9,"<="&E10),1+COUNTIF(Ref_Bands!$C$9:$G$9,"<"&E10)) | G10: =Ref_Bands!$H$9 | H10: =F10*G10
B11: Current ratio (x) | C11: =Ratios!E16 | D11: =Ratios!E16 | E11: =AVERAGE(C11:D11) | F11: =IF(Ref_Bands!$B$10="higher",6-COUNTIF(Ref_Bands!$C$10:$G$10,"<="&E11),1+COUNTIF(Ref_Bands!$C$10:$G$10,"<"&E11)) | G11: =Ref_Bands!$H$10 | H11: =F11*G11
B12: Financial risk score | F12: =SUM(H6:H11)/SUM(G6:G11)
B15: 2 - Risk blocks and sector weights
B16: Block | C16: Score (1-6) | D16: Sector weight | E16: Weighted
B17: Industry / operating-environment risk | C17: =IF(Inputs!C39<>"",Inputs!C39,INDEX(Ref_Weights!$B$5:$B$26,MATCH(Inputs!$C$6,Ref_Weights!$A$5:$A$26,0))) | D17: =INDEX(Ref_Weights!$C$5:$C$26,MATCH(Inputs!$C$6,Ref_Weights!$A$5:$A$26,0)) | E17: =C17*D17
B18: Business risk / market position / franchise | C18: =Inputs!C40 | D18: =INDEX(Ref_Weights!$D$5:$D$26,MATCH(Inputs!$C$6,Ref_Weights!$A$5:$A$26,0)) | E18: =C18*D18
B19: Financial risk (auto: corporate OR financial-sector) | C19: =IF(INDEX(Ref_Weights!$H$5:$H$26,MATCH(Inputs!$C$6,Ref_Weights!$A$5:$A$26,0))="Corporate",F12,F35) | D19: =INDEX(Ref_Weights!$E$5:$E$26,MATCH(Inputs!$C$6,Ref_Weights!$A$5:$A$26,0)) | E19: =C19*D19
B20: Management & governance | C20: =Inputs!C41 | D20: =INDEX(Ref_Weights!$F$5:$F$26,MATCH(Inputs!$C$6,Ref_Weights!$A$5:$A$26,0)) | E20: =C20*D20
B22: Composite score (weighted) | E22: =SUM(E17:E20)/SUM(D17:D20)
B23: Liquidity adjustment | E23: =INDEX(Ref_Scales!$F$5:$F$9,MATCH(Inputs!$C$43,Ref_Scales!$E$5:$E$9,0))
B24: Adjusted composite (1 = best, 6 = worst) | E24: =MIN(6,MAX(1,E22+E23))
B27: 1b - Financial-sector risk (banks / NBFCs / HFCs) - used only when Sector Type is not Corporate
B28: Metric | C28: Latest | D28: Expected | E28: Assessed | F28: Score (1-6) | G28: Weight | H28: Wtd
B29: Capital adequacy - CRAR (%) | C29: =Inputs!C49 | D29: =Inputs!D49 | E29: =AVERAGE(C29:D29) | F29: =IF(Ref_Bands_Fin!$B$5="higher",6-COUNTIF(Ref_Bands_Fin!$C$5:$G$5,"<="&E29),1+COUNTIF(Ref_Bands_Fin!$C$5:$G$5,"<"&E29)) | G29: =Ref_Bands_Fin!$H$5 | H29: =F29*G29
B30: Gross NPA (%) | C30: =Inputs!C50 | D30: =Inputs!D50 | E30: =AVERAGE(C30:D30) | F30: =IF(Ref_Bands_Fin!$B$6="higher",6-COUNTIF(Ref_Bands_Fin!$C$6:$G$6,"<="&E30),1+COUNTIF(Ref_Bands_Fin!$C$6:$G$6,"<"&E30)) | G30: =Ref_Bands_Fin!$H$6 | H30: =F30*G30
B31: Net NPA (%) | C31: =Inputs!C51 | D31: =Inputs!D51 | E31: =AVERAGE(C31:D31) | F31: =IF(Ref_Bands_Fin!$B$7="higher",6-COUNTIF(Ref_Bands_Fin!$C$7:$G$7,"<="&E31),1+COUNTIF(Ref_Bands_Fin!$C$7:$G$7,"<"&E31)) | G31: =Ref_Bands_Fin!$H$7 | H31: =F31*G31
B32: Return on assets - RoA (%) | C32: =Inputs!C52 | D32: =Inputs!D52 | E32: =AVERAGE(C32:D32) | F32: =IF(Ref_Bands_Fin!$B$8="higher",6-COUNTIF(Ref_Bands_Fin!$C$8:$G$8,"<="&E32),1+COUNTIF(Ref_Bands_Fin!$C$8:$G$8,"<"&E32)) | G32: =Ref_Bands_Fin!$H$8 | H32: =F32*G32
B33: Net interest margin - NIM (%) | C33: =Inputs!C53 | D33: =Inputs!D53 | E33: =AVERAGE(C33:D33) | F33: =IF(Ref_Bands_Fin!$B$9="higher",6-COUNTIF(Ref_Bands_Fin!$C$9:$G$9,"<="&E33),1+COUNTIF(Ref_Bands_Fin!$C$9:$G$9,"<"&E33)) | G33: =Ref_Bands_Fin!$H$9 | H33: =F33*G33
B34: Cost-to-income (%) | C34: =Inputs!C54 | D34: =Inputs!D54 | E34: =AVERAGE(C34:D34) | F34: =IF(Ref_Bands_Fin!$B$10="higher",6-COUNTIF(Ref_Bands_Fin!$C$10:$G$10,"<="&E34),1+COUNTIF(Ref_Bands_Fin!$C$10:$G$10,"<"&E34)) | G34: =Ref_Bands_Fin!$H$10 | H34: =F34*G34
B35: Financial-sector risk score | F35: =SUM(H29:H34)/SUM(G29:G34)
B37: 3 - BUSINESS-RISK GATE (failure mode 53)
B38: Neither ICRA nor CareEdge publishes a business-risk-to-notch formula. Their Financial Risk factors carry numeric bands; their Business Risk factors are descriptive only. So business risk sets a CEILING here - it is not scored into the Stage 1 composite above.
B39: Business risk score (1-6) | C39: =C18
B40: Financial risk score (1-6) | C40: =C19
B41: Business weaker than financial by | C41: =C39-C40
B42: GATE | C42: =IF(C41>=2,"YES - set a ceiling in Inputs!C69 or state in Inputs!D69 why none applies","No - business and financial risk agree within one band")
B43: Ceiling grade entered (Inputs!C69) | C43: =Inputs!C69 | D43: =Inputs!D69
B44: Ceiling index (0 = none/AAA ... 16 = C) | C44: =IF(Inputs!C69="",0,IFERROR(MATCH(Inputs!C69,Ref_Scales!$A$5:$A$21,0)-1,0))

Sheet Rating
B2: ASSIGNED RATING - this is the rating the rationale must state
B3: Long-term | C3: =C36
B4: Short-term | C4: =C37
B5: Combined | C5: =C38
B6: ="Issuer: "&Inputs!C4&" | Agency: "&Inputs!C5&" | Sector: "&Inputs!C6 | E6: Sector type | F6: =INDEX(Ref_Weights!$H$5:$H$26,MATCH(Inputs!$C$6,Ref_Weights!$A$5:$A$26,0))
B7: Derived below: STAGE 1 financial anchor -> STAGE 2 committee overlay -> STAGE 3 assigned rating. Every step is computed on this sheet.
B9: STAGE 1 - FINANCIAL ANCHOR (screening view, computed from audited financials alone)
B10: Adjusted composite score | C10: =Scorecard!E24
B11: Scale index before notches (0 = AAA ... 19 = D) | C11: =MIN(19,MAX(0,ROUND(16*((C10-1)/5)^1.4,0))) | D11: back-tested map (18-Jul-2026): power p=1.4, zero bias, reliable to about +/-2 notches as a SCREEN
B12: Support notches entered at Step 12b (+ improves) | C12: =Inputs!C42
B13: Index after support notches | C13: =MIN(19,MAX(0,C11-C12))
B14: Hard cap tested | C14: =IF(Inputs!C67="N","DISAPPLIED for this issuer - reason in Inputs!D67",IF(F6="Corporate",IF(Inputs!E19<0,"Negative net worth: capped at B-",IF(Ratios!E14<1,"Coverage <1x: capped at B+","None")),IF(Inputs!C49<0.09,"CRAR below 9%: capped at BB+","None"))) | D14: =IF(Inputs!C67="N",Inputs!D67,"(cap applies - not disapplied)")
B15: ANCHOR INDEX (after caps) | C15: =MAX(IF(Inputs!C67="N",C13,IF(F6="Corporate",IF(Inputs!E19<0,MAX(C13,15),IF(Ratios!E14<1,MAX(C13,13),C13)),IF(Inputs!C49<0.09,MAX(C13,10),C13))),Scorecard!C44)
B16: Anchor long-term grade | C16: =INDEX(Ref_Scales!$A$5:$A$24,C15+1)
B17: Anchor short-term grade | C17: =IF(OR(Inputs!$C$43="Superior",Inputs!$C$43="Strong"),INDEX(Ref_Scales!$C$5:$C$24,C15+1),INDEX(Ref_Scales!$B$5:$B$24,C15+1))
B18: Anchor line (a SCREEN, not the rating) | C18: =C16&" / "&C17
B19: Stage 1 is bounded above by the business-risk ceiling (Scorecard!B37) - a ceiling on the grade is a floor on the index, so it is applied to C15 as a MAX. With no ceiling set it has no effect.
B20: STAGE 2 - COMMITTEE OVERLAY (Step 17c: what the anchor cannot see) | C20: Notches | D20: Justification
B21: Sector-metric applicability | C21: =Inputs!C60 | D21: =Inputs!D60
B22: Business / franchise strength beyond the financial composite | C22: =Inputs!C61 | D22: =Inputs!D61
B23: Parent / group support beyond the Step 12b notch | C23: =Inputs!C62 | D23: =Inputs!D62
B24: Peer benchmarking / calibration | C24: =Inputs!C63 | D24: =Inputs!D63
B25: Other (name it in the justification) | C25: =Inputs!C64 | D25: =Inputs!D64
B26: Total overlay notches (+ improves) | C26: =SUM(C21:C25)
B27: Index after overlay | C27: =MIN(19,MAX(0,C15-C26))
B29: STAGE 3 - ASSIGNED RATING (the Committee's decision - what the rationale states)
B30: Committee direct override index (blank = anchor + overlay) | C30: =IF(Inputs!C66="","(none)",Inputs!C66) | D30: =Inputs!D66
B31: ASSIGNED INDEX | C31: =IF(Inputs!C66="",C27,Inputs!C66)
B32: Assigned long-term grade | C32: =INDEX(Ref_Scales!$A$5:$A$24,C31+1)
B33: Assigned short-term grade | C33: =IF(OR(Inputs!$C$43="Superior",Inputs!$C$43="Strong"),INDEX(Ref_Scales!$C$5:$C$24,C31+1),INDEX(Ref_Scales!$B$5:$B$24,C31+1))
B34: Divergence, anchor -> assigned (notches) | C34: =C15-C31 | D34: =IF(C34=0,"None - the anchor and the assigned rating agree.","COMPUTED, not typed. Stage 2 must carry a justification for every notch of this. The rationale quotes THIS number.")
B36: Assigned long-term line (agency house style) | C36: =IF(Inputs!C5="ICRA","[ICRA]"&C32&IF(AND(Inputs!C44<>"Not applicable",LEFT(C32,1)<>"C",LEFT(C32,1)<>"D")," ("&Inputs!C44&")",""),IF(Inputs!C5="CRISIL","Crisil "&C32&IF(AND(Inputs!C44<>"Not applicable",LEFT(C32,1)<>"C",LEFT(C32,1)<>"D"),"/"&Inputs!C44,""),"CARE "&C32&IF(AND(Inputs!C44<>"Not applicable",LEFT(C32,1)<>"C",LEFT(C32,1)<>"D"),"; "&Inputs!C44,"")))
B37: Assigned short-term line | C37: =IF(Inputs!C5="ICRA","[ICRA]"&C33,IF(Inputs!C5="CRISIL","Crisil "&C33,"CARE "&C33))
B38: Assigned combined | C38: =C36&" / "&C37
B40: Future earning potential (from Projections)
B41: Rs crore / x | C41: FY+1 | D41: FY+2
B42: Revenue | C42: =Projections!C5 | D42: =Projections!D5
B43: EBITDA | C43: =Projections!C6 | D43: =Projections!D6
B44: PAT | C44: =Projections!C13 | D44: =Projections!D13
B45: Gross cash accruals | C45: =Projections!C14 | D45: =Projections!D14
...

Sheet Ref_Scales
A1: Reference: scales, mappings, agency conventions
A3: 17-notch long-term scale (1=AAA) | E3: Liquidity adjustment | H3: Agency conventions
A4: Grade | B4: ST (normal) | C4: ST (Superior/Strong liq) | E4: Descriptor | F4: Score adj | H4: Agency | I4: EBITDA term | J4: Rating line style
A5: AAA | B5: A1+ | C5: A1+ | E5: Superior | F5: -0.25
A6: AA+ | B6: A1+ | C6: A1+ | E6: Strong | F6: -0.1 | H6: CRISIL | I6: EBITDA | J6: Crisil AA+/Stable / Crisil A1+
A7: AA | B7: A1+ | C7: A1+ | E7: Adequate | F7: 0
A8: AA- | B8: A1+ | C8: A1+ | E8: Stretched | F8: 0.75
A9: A+ | B9: A1 | C9: A1+ | E9: Poor | F9: 1.5
A10: A | B10: A2+ | C10: A1
A11: A- | B11: A2+ | C11: A2+ | E11: Outlook options
A12: BBB+ | B12: A2 | C12: A2 | E12: Stable
A13: BBB | B13: A3+ | C13: A3+ | E13: Positive
A14: BBB- | B14: A3 | C14: A3 | E14: Negative
A15: BB+ | B15: A4+ | C15: A4+ | E15: Not applicable
A16: BB | B16: A4 | C16: A4
A17: BB- | B17: A4 | C17: A4
A18: B+ | B18: A4 | C18: A4
A19: B | B19: A4 | C19: A4
A20: B- | B20: A4 | C20: A4
A21: C+ | B21: A4 | C21: A4
A22: C | B22: A4 | C22: A4
A23: Derived from an empirical corpus of published rationales and back-tested 18-Jul-2026 against 396 rated issuers. This is THIS PROJECT'S calibration and is NOT published by CRISIL. | B23: A4 | C23: A4
A24: D | B24: D | C24: D

Sheet Ref_Weights
A1: Reference: sector weights and base scores (EDITABLE assumptions)
A2: Weights (C:F) must sum to 1 per row. Base score 1 (best) .. 6 (worst) anchors the sector's operating-environment risk. Type = Corporate uses the EBITDA/gearing framework; Bank/NBFC/HFC use the financial-sector framework (capital, asset quality, earnings). Yellow = edit freely.
A4: Sector | B4: Env/Industry base | C4: w Industry/Env | D4: w Business/Franchise | E4: w Financial | F4: w Management | G4: Sum | H4: Type
A5: FMCG / Consumer staples | B5: 2 | C5: 0.15 | D5: 0.25 | E5: 0.45 | F5: 0.15 | G5: =SUM(C5:F5) | H5: Corporate
A6: Pharmaceuticals / Healthcare | B6: 2.5 | C6: 0.15 | D6: 0.25 | E6: 0.45 | F6: 0.15 | G6: =SUM(C6:F6) | H6: Corporate
A7: IT / Software & services | B7: 2.5 | C7: 0.15 | D7: 0.25 | E7: 0.4 | F7: 0.2 | G7: =SUM(C7:F7) | H7: Corporate
A8: Auto OEM | B8: 3 | C8: 0.2 | D8: 0.25 | E8: 0.4 | F8: 0.15 | G8: =SUM(C8:F8) | H8: Corporate
A9: Auto components | B9: 3.5 | C9: 0.2 | D9: 0.2 | E9: 0.45 | F9: 0.15 | G9: =SUM(C9:F9) | H9: Corporate
A10: Cement | B10: 3 | C10: 0.2 | D10: 0.2 | E10: 0.45 | F10: 0.15 | G10: =SUM(C10:F10) | H10: Corporate
A11: Iron & Steel / Metals / Mining | B11: 4 | C11: 0.25 | D11: 0.15 | E11: 0.45 | F11: 0.15 | G11: =SUM(C11:F11) | H11: Corporate
A12: Chemicals / Agrochemicals | B12: 3 | C12: 0.2 | D12: 0.2 | E12: 0.45 | F12: 0.15 | G12: =SUM(C12:F12) | H12: Corporate
A13: Oil & Gas / Refining | B13: 3 | C13: 0.2 | D13: 0.2 | E13: 0.45 | F13: 0.15 | G13: =SUM(C13:F13) | H13: Corporate
A14: Textiles | B14: 4 | C14: 0.2 | D14: 0.2 | E14: 0.45 | F14: 0.15 | G14: =SUM(C14:F14) | H14: Corporate
A15: Paper & Packaging | B15: 3.5 | C15: 0.2 | D15: 0.2 | E15: 0.45 | F15: 0.15 | G15: =SUM(C15:F15) | H15: Corporate
A16: Sugar / Agro-processing | B16: 4 | C16: 0.25 | D16: 0.15 | E16: 0.45 | F16: 0.15 | G16: =SUM(C16:F16) | H16: Corporate
... A26: Housing Finance Co (HFC) | B26: 2.5 | C26: 0.15 | D26: 0.25 | E26: 0.45 | F26: 0.15 | G26: =SUM(C26:F26) | H26: HFC

Sheet Ref_Bands
A1: Reference: financial-risk threshold bands (score 1 strongest .. 6 weakest)
A2: This project's OWN calibration - illustrative benchmark ranges, NOT published by CRISIL. See Scorecard_Backtest_Report_18Jul2026.md.
A4: Metric | B4: Direction | C4: t1 | D4: t2 | E4: t3 | F4: t4 | G4: t5 | H4: Weight
A5: Interest coverage (x) | B5: higher | C5: 1.5 | D5: 2.5 | E5: 3.5 | F5: 5 | G5: 8 | H5: 0.25
A6: Gearing - Total debt/TNW (x) | B6: lower | C6: 0.5 | D6: 1 | E6: 1.5 | F6: 2 | G6: 3 | H6: 0.2
A7: Total debt/EBITDA (x) | B7: lower | C7: 1.5 | D7: 2.5 | E7: 3.5 | F7: 4.5 | G7: 6 | H7: 0.2
A8: EBITDA margin (%) | B8: higher | C8: 0.04 | D8: 0.08 | E8: 0.12 | F8: 0.18 | G8: 0.25 | H8: 0.15
A9: Gross cash accruals/Total debt (x) | B9: higher | C9: 0.06 | D9: 0.12 | E9: 0.18 | F9: 0.25 | G9: 0.35 | H9: 0.12
A10: Current ratio (x) | B10: higher | C10: 0.9 | D10: 1.05 | E10: 1.2 | F10: 1.33 | G10: 1.5 | H10: 0.08
A12: EBITDA margin thresholds stored as fractions (0.25 = 25%) to match the Ratios sheet.

Sheet Ref_Bands_Fin
A1: Reference: FINANCIAL-sector threshold bands (banks / NBFCs / HFCs) - score 1 strongest .. 6 weakest
A2: This project's OWN calibration - illustrative benchmark ranges, NOT published by CRISIL. See Scorecard_Backtest_Report_18Jul2026.md.
A4: Metric | B4: Direction | C4: t1 | D4: t2 | E4: t3 | F4: t4 | G4: t5 | H4: Weight
A5: Capital adequacy - CRAR (%) | B5: higher | C5: 0.11 | D5: 0.13 | E5: 0.15 | F5: 0.17 | G5: 0.19 | H5: 0.22
A6: Gross NPA (%) | B6: lower | C6: 0.01 | D6: 0.02 | E6: 0.03 | F6: 0.05 | G6: 0.08 | H6: 0.18
A7: Net NPA (%) | B7: lower | C7: 0.003 | D7: 0.007 | E7: 0.012 | F7: 0.02 | G7: 0.03 | H7: 0.15
A8: Return on assets - RoA (%) | B8: higher | C8: 0.005 | D8: 0.009 | E8: 0.013 | F8: 0.017 | G8: 0.021 | H8: 0.2
A9: Net interest margin - NIM (%) | B9: higher | C9: 0.02 | D9: 0.027 | E9: 0.033 | F9: 0.04 | G9: 0.05 | H9: 0.13
A10: Cost-to-income (%) | B10: lower | C10: 0.4 | D10: 0.45 | E10: 0.5 | F10: 0.58 | G10: 0.68 | H10: 0.12
A12: For NBFCs/HFCs, CRAR captures leverage (higher CRAR = lower gearing). NIM for NBFCs = net interest spread. Cost-to-income applies to all.
