Workbook

Sheet Inputs
B2: Balkrishna Industries Limited - extracted line items (Consolidated, Rs crore)
B3: Yellow cells are EXTRACTED INPUTS traced to the source in the final column - nothing here is computed. Every downstream ratio references this sheet, so correcting a value here reflows the entire workbook.
B5: Line item | C5: FY2023 | D5: FY2024 | E5: FY2025 | F5: FY2026 | G5: Source
B6: --- PROFIT AND LOSS ---
B7: Revenue from operations | C7: 9759.53 | D7: 9368.87 | E7: 10446.95 | F7: 10823.08 | G7: FY2023-24 AR, consolidated (reported in lakhs, converted /100; cross-validated against the FY2024-25 AR's FY2024 comparative - see TieOut) / FY2024-25 AR, consolidated (Rs crore; FY2024 comparative used for the reclassified lines) / FY2025-26 AR, consolidated, audited (Rs crore)
B8: Other income | C8: 346.53 | D8: 449.22 | E8: 538.79 | F8: 251.83 | G8: FY2023-24 AR, consolidated (reported in lakhs, converted /100; cross-validated against the FY2024-25 AR's FY2024 comparative - see TieOut) / FY2024-25 AR, consolidated (Rs crore; FY2024 comparative used for the reclassified lines) / FY2025-26 AR, consolidated, audited (Rs crore)
B9: Total income | C9: 10106.06 | D9: 9818.09 | E9: 10985.74 | F9: 11074.91 | G9: FY2023-24 AR, consolidated (reported in lakhs, converted /100; cross-validated against the FY2024-25 AR's FY2024 comparative - see TieOut) / FY2024-25 AR, consolidated (Rs crore; FY2024 comparative used for the reclassified lines) / FY2025-26 AR, consolidated, audited (Rs crore)
B10: Cost of materials consumed | C10: 4804.19 | D10: 4404.45 | E10: 4985.43 | F10: 5140.88 | G10: FY2023-24 AR, consolidated (reported in lakhs, converted /100; cross-validated against the FY2024-25 AR's FY2024 comparative - see TieOut) / FY2024-25 AR, consolidated (Rs crore; FY2024 comparative used for the reclassified lines) / FY2025-26 AR, consolidated, audited (Rs crore)
B11: Purchases of stock-in-trade | C11: 106.25 | D11: 119.85 | E11: 135.63 | F11: 165.86 | G11: FY2023-24 AR, consolidated (reported in lakhs, converted /100; cross-validated against the FY2024-25 AR's FY2024 comparative - see TieOut) / FY2024-25 AR, consolidated (Rs crore; FY2024 comparative used for the reclassified lines) / FY2025-26 AR, consolidated, audited (Rs crore)
B12: Change in inventories (+ build, - draw) | C12: 4.87 | D12: -32.88 | E12: -60.6 | F12: -79.59 | G12: FY2023-24 AR, consolidated (reported in lakhs, converted /100; cross-validated against the FY2024-25 AR's FY2024 comparative - see TieOut) / FY2024-25 AR, consolidated (Rs crore; FY2024 comparative used for the reclassified lines) / FY2025-26 AR, consolidated, audited (Rs crore)
B13: Employee benefits expense | C13: 459.43 | D13: 499.51 | E13: 554.36 | F13: 596.19 | G13: FY2023-24 AR, consolidated (reported in lakhs, converted /100; cross-validated against the FY2024-25 AR's FY2024 comparative - see TieOut) / FY2024-25 AR, consolidated (Rs crore; FY2024 comparative used for the reclassified lines) / FY2025-26 AR, consolidated, audited (Rs crore)
B14: Finance costs | C14: 48.04 | D14: 112.87 | E14: 128.34 | F14: 133.62 | G14: FY2023-24 AR, consolidated (reported in lakhs, converted /100; cross-validated against the FY2024-25 AR's FY2024 comparative - see TieOut) / FY2024-25 AR, consolidated (Rs crore; FY2024 comparative used for the reclassified lines) / FY2025-26 AR, consolidated, audited (Rs crore)
B15: Depreciation and amortisation | C15: 570.81 | D15: 650.72 | E15: 680.66 | F15: 774.96 | G15: FY2023-24 AR, consolidated (reported in lakhs, converted /100; cross-validated against the FY2024-25 AR's FY2024 comparative - see TieOut) / FY2024-25 AR, consolidated (Rs crore; FY2024 comparative used for the reclassified lines) / FY2025-26 AR, consolidated, audited (Rs crore)
B16: Other expenses | C16: 2677.68 | D16: 2122.57 | E16: 2374.53 | F16: 2699.31 | G16: FY2023-24 AR, consolidated (reported in lakhs, converted /100; cross-validated against the FY2024-25 AR's FY2024 comparative - see TieOut) / FY2024-25 AR, consolidated (Rs crore; FY2024 comparative used for the reclassified lines) / FY2025-26 AR, consolidated, audited (Rs crore)
B17: of which NON-OPERATING, added back to OPBDITA | C17: 0 | D17: 0 | E17: 0 | F17: 290.01 | G17: FY2025-26 AR consolidated Other Expenses note: 'Net Loss on foreign currency transaction and translation' Rs 290.01 cr (FY2026; nil FY2025). Surfaced by preflight probe [0c]. In FY2024/FY2025 the SAME item was a net GAIN and sat in OTHER INCOME instead (FY2025 Rs 267.36 cr) - already stripped by the '- other income' term, so no add-back arises. That migration between notes with the item's sign is failure mode 36.
B18: Total expenses | C18: 8671.27 | D18: 7877.09 | E18: 8798.35 | F18: 9431.23 | G18: FY2023-24 AR, consolidated (reported in lakhs, converted /100; cross-validated against the FY2024-25 AR's FY2024 comparative - see TieOut) / FY2024-25 AR, consolidated (Rs crore; FY2024 comparative used for the reclassified lines) / FY2025-26 AR, consolidated, audited (Rs crore)
... B22: Earnings per share (Rs) | C22: 54.7 | D22: 76.12 | E22: 85.61 | F22: 64.3 | G22: FY2023-24 AR, consolidated (reported in lakhs, converted /100; cross-validated against the FY2024-25 AR's FY2024 comparative - see TieOut) / FY2024-25 AR, consolidated (Rs crore; FY2024 comparative used for the reclassified lines) / FY2025-26 AR, consolidated, audited (Rs crore)
B23: --- BALANCE SHEET ---
B24: Total assets | C24: 12347.66 | D24: 13684.54 | E24: 15634.66 | F24: 17766.34 | G24: FY2023-24 AR, consolidated (reported in lakhs, converted /100; cross-validated against the FY2024-25 AR's FY2024 comparative - see TieOut) / FY2024-25 AR, consolidated (Rs crore; FY2024 comparative used for the reclassified lines) / FY2025-26 AR, consolidated, audited (Rs crore)
B25: Total equity | C25: 7556.93 | D25: 8853.82 | E25: 10387.6 | F25: 10955.29 | G25: FY2023-24 AR, consolidated (reported in lakhs, converted /100; cross-validated against the FY2024-25 AR's FY2024 comparative - see TieOut) / FY2024-25 AR, consolidated (Rs crore; FY2024 comparative used for the reclassified lines) / FY2025-26 AR, consolidated, audited (Rs crore)
B26: NC borrowings | C26: 1038.09 | D26: 691.44 | E26: 387.3 | F26: 888 | G26: FY2023-24 AR, consolidated (reported in lakhs, converted /100; cross-validated against the FY2024-25 AR's FY2024 comparative - see TieOut) / FY2024-25 AR, consolidated (Rs crore; FY2024 comparative used for the reclassified lines) / FY2025-26 AR, consolidated, audited (Rs crore)
B27: NC lease liabilities | C27: 4.74 | D27: 4.01 | E27: 4.55 | F27: 4.07 | G27: FY2023-24 AR, consolidated (reported in lakhs, converted /100; cross-validated against the FY2024-25 AR's FY2024 comparative - see TieOut) / FY2024-25 AR, consolidated (Rs crore; FY2024 comparative used for the reclassified lines) / FY2025-26 AR, consolidated, audited (Rs crore)
B28: Deferred tax liabilities | C28: 241.85 | D28: 349 | E28: 456.3 | F28: 316.84 | G28: FY2023-24 AR, consolidated (reported in lakhs, converted /100; cross-validated against the FY2024-25 AR's FY2024 comparative - see TieOut) / FY2024-25 AR, consolidated (Rs crore; FY2024 comparative used for the reclassified lines) / FY2025-26 AR, consolidated, audited (Rs crore)
B29: Total non-current liabilities | C29: 1441.46 | D29: 1170.28 | E29: 1020.41 | F29: 1722.05 | G29: FY2023-24 AR, consolidated (reported in lakhs, converted /100; cross-validated against the FY2024-25 AR's FY2024 comparative - see TieOut) / FY2024-25 AR, consolidated (Rs crore; FY2024 comparative used for the reclassified lines) / FY2025-26 AR, consolidated, audited (Rs crore)
B30: C borrowings | C30: 2303.66 | D30: 2403.99 | E30: 2875.25 | F30: 3217.56 | G30: FY2023-24 AR, consolidated (reported in lakhs, converted /100; cross-validated against the FY2024-25 AR's FY2024 comparative - see TieOut) / FY2024-25 AR, consolidated (Rs crore; FY2024 comparative used for the reclassified lines) / FY2025-26 AR, consolidated, audited (Rs crore)
B31: C lease liabilities | C31: 0.04 | D31: 0 | E31: 0.35 | F31: 1.19 | G31: FY2023-24 AR, consolidated (reported in lakhs, converted /100; cross-validated against the FY2024-25 AR's FY2024 comparative - see TieOut) / FY2024-25 AR, consolidated (Rs crore; FY2024 comparative used for the reclassified lines) / FY2025-26 AR, consolidated, audited (Rs crore)
B32: Trade payables | C32: 492.14 | D32: 808.19 | E32: 753.93 | F32: 912.26 | G32: FY2023-24 AR, consolidated (reported in lakhs, converted /100; cross-validated against the FY2024-25 AR's FY2024 comparative - see TieOut) (original) / FY2024-25 AR, consolidated (Rs crore; FY2024 comparative used for the reclassified lines) (restated, used here - Rs 102.04 cr reclassified vs Other financial liabilities for FY2024, both totals unaffected) / FY2025-26 AR, consolidated, audited (Rs crore)
B33: Total current liabilities | C33: 3349.27 | D33: 3660.44 | E33: 4226.65 | F33: 5089 | G33: FY2023-24 AR, consolidated (reported in lakhs, converted /100; cross-validated against the FY2024-25 AR's FY2024 comparative - see TieOut) / FY2024-25 AR, consolidated (Rs crore; FY2024 comparative used for the reclassified lines) / FY2025-26 AR, consolidated, audited (Rs crore)
B34: Total current assets | C34: 3927.95 | D34: 4644.06 | E34: 5571.4 | F34: 5154.47 | G34: FY2023-24 AR, consolidated (reported in lakhs, converted /100; cross-validated against the FY2024-25 AR's FY2024 comparative - see TieOut) / FY2024-25 AR, consolidated (Rs crore; FY2024 comparative used for the reclassified lines) / FY2025-26 AR, consolidated, audited (Rs crore)
B35: Inventories | C35: 1667.37 | D35: 1331.53 | E35: 1781.93 | F35: 1808.47 | G35: FY2023-24 AR, consolidated (reported in lakhs, converted /100; cross-validated against the FY2024-25 AR's FY2024 comparative - see TieOut) / FY2024-25 AR, consolidated (Rs crore; FY2024 comparative used for the reclassified lines) / FY2025-26 AR, consolidated, audited (Rs crore)
... B39: Current investments | C39: 774.6 | D39: 1348.99 | E39: 1702.78 | F39: 1327.48 | G39: FY2023-24 AR, consolidated (reported in lakhs, converted /100; cross-validated against the FY2024-25 AR's FY2024 comparative - see TieOut) / FY2024-25 AR, consolidated (Rs crore; FY2024 comparative used for the reclassified lines) / FY2025-26 AR, consolidated, audited (Rs crore)
B40: --- DISCLOSED / REGULATORY (not computed here) ---
B41: Total debt/total assets (company's own ratio) | F41: 0.23 | G41: Q1 FY2026-27 filing, 30-Jun-2026, consolidated column, Reg 52(4)
B42: Debt-Equity ratio (company's own ratio) | F42: 0.37 | G42: Q1 FY2026-27 filing, 30-Jun-2026, consolidated column, Reg 52(4)
B43: DSCR (company's own ratio, times) | F43: 4.31 | G43: Q1 FY2026-27 filing, 30-Jun-2026, consolidated column, Reg 52(4)
B44: ISCR (company's own ratio, times) | F44: 70.76 | G44: Q1 FY2026-27 filing, 30-Jun-2026, consolidated column, Reg 52(4)
B45: Current ratio (company's own ratio) | F45: 1.01 | G45: Q1 FY2026-27 filing, 30-Jun-2026, consolidated column, Reg 52(4)
B46: Operating margin % (EBIT basis, company's own) | F46: 14.09 | G46: Q1 FY2026-27 filing, 30-Jun-2026, consolidated column, Reg 52(4)
B47: Net profit margin % (on total income, company's own) | F47: 11.22 | G47: Q1 FY2026-27 filing, 30-Jun-2026, consolidated column, Reg 52(4)
B48: Contingent liabilities (Rs cr, standalone Note 46) | F48: 946.09 | G48: FY2025-26 AR, standalone Note 46
...

Sheet RatioSuite
B2: Balkrishna Industries Limited - ratio suite (Consolidated, Rs crore; agency conventions applied)
B3: Every value is a LIVE FORMULA referencing the Inputs sheet - click any cell to see the arithmetic. 'Calculation' states the same formula in words; 'Convention' records the definitional choice (lease treatment, normalisation, netting) so the basis is auditable.
B5: Ratio | C5: FY2023 | D5: FY2024 | E5: FY2025 | F5: FY2026 | G5: Calculation | H5: Convention / note
B6: OPBDITA (Rs cr) | C6: =(Inputs!C19+Inputs!C14+Inputs!C15-Inputs!C8+Inputs!C17) -> 1707.11 | D6: =(Inputs!D19+Inputs!D14+Inputs!D15-Inputs!D8+Inputs!D17) -> 2255.37 | E6: =(Inputs!E19+Inputs!E14+Inputs!E15-Inputs!E8+Inputs!E17) -> 2457.6 | F6: =(Inputs!F19+Inputs!F14+Inputs!F15-Inputs!F8+Inputs!F17) -> 2590.44 | G6: PBT + finance cost + depreciation - other income (ICRA convention, excludes other income)
B7: OPBDITA margin % | C7: =100*(Inputs!C19+Inputs!C14+Inputs!C15-Inputs!C8+Inputs!C17)/Inputs!C7 -> 17.491723 | D7: =100*(Inputs!D19+Inputs!D14+Inputs!D15-Inputs!D8+Inputs!D17)/Inputs!D7 -> 24.073021 | E7: =100*(Inputs!E19+Inputs!E14+Inputs!E15-Inputs!E8+Inputs!E17)/Inputs!E7 -> 23.524569 | F7: =100*(Inputs!F19+Inputs!F14+Inputs!F15-Inputs!F8+Inputs!F17)/Inputs!F7 -> 23.934407 | G7: OPBDITA over revenue from operations
B8: PAT margin % | C8: =100*Inputs!C21/Inputs!C7 -> 10.834538 | D8: =100*Inputs!D21/Inputs!D7 -> 15.706163 | E8: =100*Inputs!E21/Inputs!E7 -> 15.841561 | F8: =100*Inputs!F21/Inputs!F7 -> 11.48564 | G8: PAT over revenue from operations
B9: Total debt (Rs cr) | C9: =(Inputs!C26+Inputs!C27+Inputs!C30+Inputs!C31) -> 3346.53 | D9: =(Inputs!D26+Inputs!D27+Inputs!D30+Inputs!D31) -> 3099.44 | E9: =(Inputs!E26+Inputs!E27+Inputs!E30+Inputs!E31) -> 3267.45 | F9: =(Inputs!F26+Inputs!F27+Inputs!F30+Inputs!F31) -> 4110.82 | G9: NC + C borrowings, including lease liabilities
B10: Net debt (Rs cr) | C10: =((Inputs!C26+Inputs!C27+Inputs!C30+Inputs!C31)-(Inputs!C37+Inputs!C38+Inputs!C39)) -> 2495.6 | D10: =((Inputs!D26+Inputs!D27+Inputs!D30+Inputs!D31)-(Inputs!D37+Inputs!D38+Inputs!D39)) -> 1670.45 | E10: =((Inputs!E26+Inputs!E27+Inputs!E30+Inputs!E31)-(Inputs!E37+Inputs!E38+Inputs!E39)) -> 1478.42 | F10: =((Inputs!F26+Inputs!F27+Inputs!F30+Inputs!F31)-(Inputs!F37+Inputs!F38+Inputs!F39)) -> 2718.83 | G10: total debt less cash, other bank balances and CURRENT investments (non-current strategic investments excluded)
B11: Gearing (times) | C11: =(Inputs!C26+Inputs!C27+Inputs!C30+Inputs!C31)/Inputs!C25 -> 0.44284253 | D11: =(Inputs!D26+Inputs!D27+Inputs!D30+Inputs!D31)/Inputs!D25 -> 0.35006811 | E11: =(Inputs!E26+Inputs!E27+Inputs!E30+Inputs!E31)/Inputs!E25 -> 0.31455293 | F11: =(Inputs!F26+Inputs!F27+Inputs!F30+Inputs!F31)/Inputs!F25 -> 0.37523607 | G11: total debt over net worth
B12: Net gearing (times) | C12: =((Inputs!C26+Inputs!C27+Inputs!C30+Inputs!C31)-(Inputs!C37+Inputs!C38+Inputs!C39))/Inputs!C25 -> 0.33023993 | D12: =((Inputs!D26+Inputs!D27+Inputs!D30+Inputs!D31)-(Inputs!D37+Inputs!D38+Inputs!D39))/Inputs!D25 -> 0.18866998 | E12: =((Inputs!E26+Inputs!E27+Inputs!E30+Inputs!E31)-(Inputs!E37+Inputs!E38+Inputs!E39))/Inputs!E25 -> 0.14232546 | F12: =((Inputs!F26+Inputs!F27+Inputs!F30+Inputs!F31)-(Inputs!F37+Inputs!F38+Inputs!F39))/Inputs!F25 -> 0.24817508 | G12: net debt over net worth
B13: TOL/TNW (times) | C13: =(Inputs!C24-Inputs!C25)/Inputs!C25 -> 0.63395188 | D13: =(Inputs!D24-Inputs!D25)/Inputs!D25 -> 0.54560856 | E13: =(Inputs!E24-Inputs!E25)/Inputs!E25 -> 0.50512727 | F13: =(Inputs!F24-Inputs!F25)/Inputs!F25 -> 0.62171335 | G13: total outside liabilities over net worth
B14: Total debt/OPBDITA (times) | C14: =(Inputs!C26+Inputs!C27+Inputs!C30+Inputs!C31)/((Inputs!C19+Inputs!C14+Inputs!C15-Inputs!C8+Inputs!C17)) -> 1.9603482 | D14: =(Inputs!D26+Inputs!D27+Inputs!D30+Inputs!D31)/((Inputs!D19+Inputs!D14+Inputs!D15-Inputs!D8+Inputs!D17)) -> 1.374249 | E14: =(Inputs!E26+Inputs!E27+Inputs!E30+Inputs!E31)/((Inputs!E19+Inputs!E14+Inputs!E15-Inputs!E8+Inputs!E17)) -> 1.3295288 | F14: =(Inputs!F26+Inputs!F27+Inputs!F30+Inputs!F31)/((Inputs!F19+Inputs!F14+Inputs!F15-Inputs!F8+Inputs!F17)) -> 1.5869196
B15: Net debt/OPBDITA (times) | C15: =((Inputs!C26+Inputs!C27+Inputs!C30+Inputs!C31)-(Inputs!C37+Inputs!C38+Inputs!C39))/((Inputs!C19+Inputs!C14+Inputs!C15-Inputs!C8+Inputs!C17)) -> 1.4618859 | D15: =((Inputs!D26+Inputs!D27+Inputs!D30+Inputs!D31)-(Inputs!D37+Inputs!D38+Inputs!D39))/((Inputs!D19+Inputs!D14+Inputs!D15-Inputs!D8+Inputs!D17)) -> 0.74065453 | E15: =((Inputs!E26+Inputs!E27+Inputs!E30+Inputs!E31)-(Inputs!E37+Inputs!E38+Inputs!E39))/((Inputs!E19+Inputs!E14+Inputs!E15-Inputs!E8+Inputs!E17)) -> 0.60157064 | F15: =((Inputs!F26+Inputs!F27+Inputs!F30+Inputs!F31)-(Inputs!F37+Inputs!F38+Inputs!F39))/((Inputs!F19+Inputs!F14+Inputs!F15-Inputs!F8+Inputs!F17)) -> 1.049563
B16: Interest coverage (times) | C16: =((Inputs!C19+Inputs!C14+Inputs!C15-Inputs!C8+Inputs!C17))/Inputs!C14 -> 35.535179 | D16: =((Inputs!D19+Inputs!D14+Inputs!D15-Inputs!D8+Inputs!D17))/Inputs!D14 -> 19.982015 | E16: =((Inputs!E19+Inputs!E14+Inputs!E15-Inputs!E8+Inputs!E17))/Inputs!E14 -> 19.149135 | F16: =((Inputs!F19+Inputs!F14+Inputs!F15-Inputs!F8+Inputs!F17))/Inputs!F14 -> 19.386619 | G16: OPBDITA over finance costs
B17: RoCE % | C17: =100*(((Inputs!C19+Inputs!C14+Inputs!C15-Inputs!C8+Inputs!C17))-Inputs!C15)/(((Inputs!C26+Inputs!C27+Inputs!C30+Inputs!C31)+Inputs!C25+Inputs!C28)) -> 10.19532 | D17: =100*(((Inputs!D19+Inputs!D14+Inputs!D15-Inputs!D8+Inputs!D17))-Inputs!D15)/(((Inputs!D26+Inputs!D27+Inputs!D30+Inputs!D31)+Inputs!D25+Inputs!D28)) -> 13.043538 | E17: =100*(((Inputs!E19+Inputs!E14+Inputs!E15-Inputs!E8+Inputs!E17))-Inputs!E15)/(((Inputs!E26+Inputs!E27+Inputs!E30+Inputs!E31)+Inputs!E25+Inputs!E28)) -> 12.592275 | F17: =100*(((Inputs!F19+Inputs!F14+Inputs!F15-Inputs!F8+Inputs!F17))-Inputs!F15)/(((Inputs!F26+Inputs!F27+Inputs!F30+Inputs!F31)+Inputs!F25+Inputs!F28)) -> 11.801898 | G17: (OPBDITA - depreciation) over capital employed (debt + net worth + deferred tax liability), period-end basis
B18: Current ratio (times) | C18: =Inputs!C34/Inputs!C33 -> 1.1727779 | D18: =Inputs!D34/Inputs!D33 -> 1.2687163 | E18: =Inputs!E34/Inputs!E33 -> 1.3181598 | F18: =Inputs!F34/Inputs!F33 -> 1.012865
B19: Debtor days | C19: =365*Inputs!C36/Inputs!C7 -> 41.710364 | D19: =365*Inputs!D36/Inputs!D7 -> 56.312229 | E19: =365*Inputs!E36/Inputs!E7 -> 52.216877 | F19: =365*Inputs!F36/Inputs!F7 -> 48.784454 | G19: closing balance (point-in-time), used in every year for a consistent convention across the series - FY2023 has no prior-year balance sheet in the document set to average with
B20: Inventory days | C20: =365*Inputs!C35/((Inputs!C10+Inputs!C11+Inputs!C12)) -> 123.81519 | D20: =365*Inputs!D35/((Inputs!D10+Inputs!D11+Inputs!D12)) -> 108.20819 | E20: =365*Inputs!E35/((Inputs!E10+Inputs!E11+Inputs!E12)) -> 128.52674 | F20: =365*Inputs!F35/((Inputs!F10+Inputs!F11+Inputs!F12)) -> 126.28135 | G20: closing inventory over COGS
B21: Payable days | C21: =365*Inputs!C32/((Inputs!C10+Inputs!C11+Inputs!C12)) -> 36.545223 | D21: =365*Inputs!D32/((Inputs!D10+Inputs!D11+Inputs!D12)) -> 65.678416 | E21: =365*Inputs!E32/((Inputs!E10+Inputs!E11+Inputs!E12)) -> 54.379335 | F21: =365*Inputs!F32/((Inputs!F10+Inputs!F11+Inputs!F12)) -> 63.701042 | G21: closing payables over COGS
B22: Working capital cycle (days) | C22: =365*Inputs!C36/Inputs!C7+365*Inputs!C35/((Inputs!C10+Inputs!C11+Inputs!C12))-365*Inputs!C32/((Inputs!C10+Inputs!C11+Inputs!C12)) -> 128.98033 | D22: =365*Inputs!D36/Inputs!D7+365*Inputs!D35/((Inputs!D10+Inputs!D11+Inputs!D12))-365*Inputs!D32/((Inputs!D10+Inputs!D11+Inputs!D12)) -> 98.842008 | E22: =365*Inputs!E36/Inputs!E7+365*Inputs!E35/((Inputs!E10+Inputs!E11+Inputs!E12))-365*Inputs!E32/((Inputs!E10+Inputs!E11+Inputs!E12)) -> 126.36429 | F22: =365*Inputs!F36/Inputs!F7+365*Inputs!F35/((Inputs!F10+Inputs!F11+Inputs!F12))-365*Inputs!F32/((Inputs!F10+Inputs!F11+Inputs!F12)) -> 111.36476 | G22: debtor days + inventory days - payable days

Sheet TieOut
B2: Balkrishna Industries Limited - tie-out to company-disclosed figures
B3: Binding gate (CLAUDE.md Step 6): headline computed figures must reconcile to the company's OWN disclosed numbers before the workpaper is issued. PASS/FAIL is itself a formula - it re-evaluates if any input changes.
B5: Check | C5: Computed | D5: Company-disclosed | E5: Result | F5: Note
B6: Balance sheet ties, FY2026 (assets - equity - NC liab, should equal C liab) | C6: =Inputs!F24-Inputs!F25-Inputs!F29 -> 5089 | D6: 5089 | E6: =IF(ABS(C6-D6)<=MAX(1,ABS(D6)*0.005),"PASS","CHECK") -> PASS | F6: AR consolidated balance sheet, total current liabilities - independently stated, not derived from the formula in column C
B7: Gearing, FY2026 | C7: =(Inputs!F26+Inputs!F27+Inputs!F30+Inputs!F31)/Inputs!F25 -> 0.37523607 | D7: 0.37 | E7: =IF(ABS(C7-D7)<=MAX(1,ABS(D7)*0.005),"PASS","CHECK") -> PASS | F7: company's own Reg 52(4) disclosure, Q1 FY2026-27 filing
B8: Operating margin (EBIT basis), FY2026 | C8: =100*((Inputs!F19+Inputs!F14+Inputs!F15-Inputs!F8)-Inputs!F15)/Inputs!F7 -> 14.094602 | D8: 14.09 | E8: =IF(ABS(C8-D8)<=MAX(1,ABS(D8)*0.005),"PASS","CHECK") -> PASS | F8: company's own Reg 52(4) disclosure, Q1 FY2026-27 filing (EBIT basis, differs from OPBDITA margin above)
B9: EPS, FY2026 | C9: =Inputs!F22 -> 64.3 | D9: 64.3 | E9: =IF(ABS(C9-D9)<=MAX(1,ABS(D9)*0.005),"PASS","CHECK") -> PASS | F9: AR consolidated statement of profit and loss
B10: Current ratio, FY2026 | C10: =Inputs!F34/Inputs!F33 -> 1.012865 | D10: 1.01 | E10: =IF(ABS(C10-D10)<=MAX(1,ABS(D10)*0.005),"PASS","CHECK") -> PASS | F10: company's own Reg 52(4) disclosure, Q1 FY2026-27 filing
B12: Tolerance: 0.5% of the disclosed figure, floor Rs 1 - tighter than rounding, loose enough for basis differences.

Sheet RatingScore
B2: Balkrishna Industries Limited - rating scorecard and view
B3: Factor scores 1 (strongest) to 6 (weakest), weighted to a composite. The anchor is a SCREENING cross-check with a +/-2 notch band, NOT the rating - the analyst view and any divergence are stated below and the divergence must be explained, never buried.
B5: Rating factor | C5: Score (1-6) | D5: Weight | E5: Weighted | F5: Justification
B6: Business risk - franchise and diversification | C6: 2 | D6: 0.25 | E6: =C6*D6 -> 0.5 | F6: Largest Indian exporter of off-highway tyres (CareEdge, 05-Mar-2026), operating in over 160 countries, with SKUs grown from ~2,700 (FY2019) to 3,600+ (CRISIL, 27-Feb-2026). Channel mix 70.1% replacement / 28.7% OEM (FY2026 AR) gives revenue stability across cycles. Geographic mix is materially diversified (Europe 40.0%, Americas 13.2%, India 36.3%, RoW 10.5%, FY2026 AR) but this diversification is what transmitted the FY2026 tariff shock - North America revenue fell 28.1% (Rs 1,861.38 cr to Rs 1,338.48 cr, AR segment note) even as India grew 24.0% and 'Others' 46.6% to compensate.
B7: Operating efficiency and cost position | C7: 2 | D7: 0.15 | E7: =C7*D7 -> 0.3 | F7: Backward-integrated carbon black operations (own major raw-material input); logistics cost averaged 5.45% of revenue over 3 years vs an industry benchmark of 7.9%-9%, reduced further to 4.40% in FY2026 (company MD&A); inventory turnover exceeding 24 times with finished-goods held at 12-15 days of production. OPBDITA margin of 21.25% in FY2026, though down from 24.07% (FY2024) and 23.52% (FY2025), remains high in absolute terms for the sector.
B8: Financial risk - leverage and coverage | C8: 1 | D8: 0.3 | E8: =C8*D8 -> 0.3 | F8: Gearing has stayed in a narrow 0.31x-0.44x band across all four years (FY2023-FY2026) DESPITE a Rs 2,984-3,003 crore capex year in FY2026 (cash-flow vs MD&A basis) that was funded predominantly from operating cash flow (Rs 2,249.32 crore, +27.5% y/y) rather than debt. Interest coverage never falls below 17 times in any of the four years, including the FY2026 margin-compression year. TOL/TNW peaks at 0.63x - very low balance-sheet risk for a manufacturer mid-way through a Rs 6,800 crore multi-year capex programme.
B9: Earnings trajectory and margin resilience | C9: 3 | D9: 0.15 | E9: =C9*D9 -> 0.45 | F9: FY2026 PAT fell 24.9% (Rs 1,654.96 cr to Rs 1,243.10 cr) on OPBDITA margin compression to 21.25% from 23.52%, driven by the North America tariff shock the company's own MD&A names explicitly ('US tariffs: the sharp spike in import levies weigh on the finances'). RoCE fell to 9.92% from 12.59% (FY2025), partly because capital employed rose sharply (CWIP alone grew from Rs 985.95 cr to Rs 2,472.46 cr) while earnings fell. The most recent quarter (Q1FY2027, consolidated) shows recovery already under way - operating margin 21.54% (annualised OPBDITA basis) and PAT of Rs 450.77 cr, +56.4% year-on-year against Q1FY2026's Rs 288.30 cr - consistent with CRISIL's own comment (27-Feb-2026) that US tariffs are 'now reducing to ~15%' with an expected FY2027 recovery.
B10: Capex execution and funding risk | C10: 3 | D10: 0.15 | E10: =C10*D10 -> 0.45 | F10: A Rs 6,800 crore cumulative capex programme (announced since Aug-2024, through FY2029) is under way across Carbon Black capacity (2,65,000 to 3,60,000 MTPA), Premium PCR/CVR entry, and OHT debottlenecking to 4,25,000 MTPA total achievable tyre capacity. FY2026 capital commitments (contracts executed but not yet paid) nearly tripled to Rs 2,711.84 crore from Rs 923.98 crore (AR Note 46), confirming the programme's next phase is substantially committed, not merely announced. Execution risk (cost overrun, delay, demand absorption for the new PCR/CVR capacity in an unfamiliar segment) is real, but funding risk is LOW given the demonstrated FY2026 funding mix (74% of capex from operating cash flow).
B11: Weight check (must be 100%) | D11: =SUM(D6:D10) -> 1 | E11: =SUM(E6:E10) -> 2 | F11: =IF(ABS(D11-1)<0.001,"weights sum to 100%","ERROR: weights must sum to 100%") -> weights sum to 100%
B13: Weighted composite score | C13: =E11 -> 2
B14: Indicative anchor grade (screening only, +/-2 band) | C14: AA band (composite reflects strong balance sheet, moderated by a live earnings-trajectory question)
B15: ANALYST RATING VIEW | C15: [ICRA]AA (Stable) / [ICRA]A1+
B16: Divergence from anchor - explanation | C16: This is a NEW ICRA rating (an assignment, not a reaffirmation) - BKT's own FY2025-26 annual report discloses ratings from CRISIL (AA+/Stable) and CareEdge (AA+; Stable on the NCD only) but NO ICRA rating anywhere, confirmed by a recorded zero-hit search for 'ICRA' across the AR and the newest quarterly filing. My independent view is one notch below both peer agencies' AA+ - [ICRA]AA (Stable) - not because the balance sheet disagrees (gearing, coverage and TOL/TNW would all support AA+ on their own) but because the FY2026 earnings trajectory is the live question this exercise cannot resolve with only one quarter of recovery evidence: PAT fell 25% for a full year before Q1FY2027 turned up, and CRISIL's own 27-Feb-2026 rationale (dated inside that same recovery window) explicitly builds its AA+ around a FORECAST of FY2027 recovery ('revenues in FY27 are expected to grow by 7-9%... margins are expected to improve') rather than realised results. A rating built on realised FY2026 results plus one recovering quarter, without that forward-looking credit for a forecast not yet delivered, reasonably sits one notch more cautious. This is a considered, evidenced divergence, not an anchor-matching exercise - and it is within the ±2 notch screening tolerance the scorecard's own back-tested governance allows before requiring committee-level resolution.
