Workbook

Sheet Extraction
A1: Jindal Stainless Limited - consolidated extraction (Rs crore) | B1: FY2023 | C1: FY2024 | D1: FY2025 | E1: FY2026 | F1: Source
A2: PROFIT AND LOSS
A3: Revenue from ops | B3: 35697.03 | C3: 38562.47 | D3: 39312.21 | E3: 42954.66 | F3: AR consolidated statement of profit and loss; non-operating items from the cash-flow reconciliation
A4: Other income | B4: 126.29 | C4: 169.12 | D4: 290.85 | E4: 351.48 | F4: AR consolidated statement of profit and loss; non-operating items from the cash-flow reconciliation
A5: Finance costs | B5: 324.62 | C5: 554.39 | D5: 611.64 | E5: 567.93 | F5: AR consolidated statement of profit and loss; non-operating items from the cash-flow reconciliation
A6: Depreciation | B6: 723.75 | C6: 878.83 | D6: 956.12 | E6: 1060.3 | F6: AR consolidated statement of profit and loss; non-operating items from the cash-flow reconciliation
A7: PBT ex-except ex-assoc | B7: 2664.01 | C7: 3440.19 | D7: 3389.72 | E7: 4283.68 | F7: AR consolidated statement of profit and loss; non-operating items from the cash-flow reconciliation
A8: Associate/JV share | B8: 109.96 | C8: 53.13 | D8: -43.7 | E8: 16.73 | F8: AR consolidated statement of profit and loss; non-operating items from the cash-flow reconciliation
A9: Exceptional items | B9: 0 | C9: 99.15 | D9: -7.06 | E9: -58.34 | F9: AR consolidated statement of profit and loss; non-operating items from the cash-flow reconciliation
A10: PAT | B10: 2083.83 | C10: 2693.48 | D10: 2499.72 | E10: 3184.57 | F10: AR consolidated statement of profit and loss; non-operating items from the cash-flow reconciliation
A11: PAT (owners) | B11: 2114.5 | C11: 2713.21 | D11: 2505.2 | E11: 3193.45 | F11: AR consolidated statement of profit and loss; non-operating items from the cash-flow reconciliation
A12: EPS basic (Rs) | B12: 25.68 | C12: 32.95 | D12: 30.42 | E12: 38.76 | F12: AR consolidated statement of profit and loss; non-operating items from the cash-flow reconciliation
A13: Total income | B13: 35823.32 | C13: 38731.59 | D13: 39603.06 | E13: 43306.14 | F13: AR consolidated statement of profit and loss; non-operating items from the cash-flow reconciliation
A14: PAT (NCI) | B14: -30.67 | C14: -19.73 | D14: -5.48 | E14: -8.88 | F14: AR consolidated statement of profit and loss; non-operating items from the cash-flow reconciliation
A15: Forex gain in Other Expenses | B15: -68.48 | C15: -190.04 | D15: -154.37 | E15: -78.41 | F15: AR consolidated statement of profit and loss; non-operating items from the cash-flow reconciliation
A16: NON-CURRENT ASSETS
A17: Property, plant and equipment | B17: 8545.76 | C17: 11394.53 | D17: 12433.18 | E17: 15544.7 | F17: AR consolidated balance sheet
A18: Capital work-in-progress | B18: 760.9 | C18: 1084.63 | D18: 1770.27 | E18: 1790.21 | F18: AR consolidated balance sheet
A19: Investment property | B19: 0 | C19: 10.05 | D19: 10.13 | E19: 11.05 | F19: AR consolidated balance sheet
A20: Right-of-use assets | B20: 469.55 | C20: 651.88 | D20: 662.88 | E20: 695.66 | F20: AR consolidated balance sheet
A21: Goodwill | B21: 163.39 | C21: 332.38 | D21: 899.24 | E21: 1247.38 | F21: AR consolidated balance sheet
A22: Other intangible assets | B22: 782.38 | C22: 865.59 | D22: 794.79 | E22: 718.02 | F22: AR consolidated balance sheet
A23: Intangible assets under dev | B23: 12.1 | C23: 27.4 | D23: 12.77 | E23: 15.94 | F23: AR consolidated balance sheet
A24: Equity-method investments | B24: 557.09 | C24: 864.66 | D24: 1313.18 | E24: 1179.96 | F24: AR consolidated balance sheet
A25: Investments (non-current) | B25: 112.31 | C25: 37.55 | D25: 328.47 | E25: 366.1 | F25: AR consolidated balance sheet
A26: Loans (non-current) | B26: 67 | C26: 245.2 | D26: 240.39 | E26: 195.16 | F26: AR consolidated balance sheet
A27: Other financial assets (NC) | B27: 288.97 | C27: 152.47 | D27: 209.38 | E27: 468.37 | F27: AR consolidated balance sheet
A28: Deferred tax assets (net) | B28: 0 | C28: 52.4 | D28: 241.03 | E28: 262.77 | F28: AR consolidated balance sheet
... A30: Other non-current assets | B30: 244.3 | C30: 314.42 | D30: 440.29 | E30: 706.28 | F30: AR consolidated balance sheet
A31: Total non-current assets | B31: =B17+B18+B19+B20+B21+B22+B23+B24+B25+B26+B27+B28+B29+B30 | C31: =C17+C18+C19+C20+C21+C22+C23+C24+C25+C26+C27+C28+C29+C30 | D31: =D17+D18+D19+D20+D21+D22+D23+D24+D25+D26+D27+D28+D29+D30 | E31: =E17+E18+E19+E20+E21+E22+E23+E24+E25+E26+E27+E28+E29+E30 | F31: live SUM over the component rows above
A32: CURRENT ASSETS
A33: Inventories | B33: 8393.92 | C33: 7931.5 | D33: 9700.28 | E33: 9507.52 | F33: AR consolidated balance sheet
A34: Investments (current) | B34: 300.7 | C34: 344.25 | D34: 4.5 | E34: 1.12 | F34: AR consolidated balance sheet
A35: Trade receivables | B35: 3657.82 | C35: 2836.85 | D35: 3107.01 | E35: 3085.62 | F35: AR consolidated balance sheet
A36: Cash and cash equivalents | B36: 469.91 | C36: 1229.7 | D36: 632.54 | E36: 415.12 | F36: AR consolidated balance sheet
A37: Other bank balances | B37: 460.9 | C37: 758.41 | D37: 1637.33 | E37: 2518.91 | F37: AR consolidated balance sheet
A38: Loans (current) | B38: 0 | C38: 6.09 | D38: 456.5 | E38: 461.88 | F38: AR consolidated balance sheet
A39: Other financial assets (C) | B39: 487.84 | C39: 306.24 | D39: 270.58 | E39: 451.61 | F39: AR consolidated balance sheet
A40: Income tax assets (C) | B40: 224.8 | C40: 200.11 | D40: 23.66 | E40: 16.12 | F40: AR consolidated balance sheet
A41: Other current assets | B41: 1115.84 | C41: 780.54 | D41: 773.46 | E41: 854.61 | F41: AR consolidated balance sheet
...

Sheet RatioSuite
A1: CareEdge convention ratio suite - every cell a live formula | B1: FY2023 | C1: FY2024 | D1: FY2025 | E1: FY2026 | F1: Source
A2: Total operating income | B2: =Extraction!B3 | C2: =Extraction!C3 | D2: =Extraction!D3 | E2: =Extraction!E3 | F2: Revenue from operations
A3: PBILDT base (= AR's own EBITDA definition) | B3: =(Extraction!B7+Extraction!B5+Extraction!B6-Extraction!B4) | C3: =(Extraction!C7+Extraction!C5+Extraction!C6-Extraction!C4) | D3: =(Extraction!D7+Extraction!D5+Extraction!D6-Extraction!D4) | E3: =(Extraction!E7+Extraction!E5+Extraction!E6-Extraction!E4) | F3: PBT before exceptional/associate + finance cost + depreciation - other income
A4: add back: non-op items per CareEdge | B4: =0 | C4: =0 | D4: =0 | E4: =0 | F4: ZERO on this issuer: the forex result is a net GAIN inside Other Expenses in all four years (note 34 / note 33), so it is already in the base and CareEdge's rule that non-debt forex is operating is satisfied without any adjustment
A5: PBILDT | B5: =((Extraction!B7+Extraction!B5+Extraction!B6-Extraction!B4)+0) | C5: =((Extraction!C7+Extraction!C5+Extraction!C6-Extraction!C4)+0) | D5: =((Extraction!D7+Extraction!D5+Extraction!D6-Extraction!D4)+0) | E5: =((Extraction!E7+Extraction!E5+Extraction!E6-Extraction!E4)+0) | F5: CareEdge convention - see Conventions tab
A6: PBILDT margin (%) | B6: =100*((Extraction!B7+Extraction!B5+Extraction!B6-Extraction!B4)+0)/Extraction!B3 | C6: =100*((Extraction!C7+Extraction!C5+Extraction!C6-Extraction!C4)+0)/Extraction!C3 | D6: =100*((Extraction!D7+Extraction!D5+Extraction!D6-Extraction!D4)+0)/Extraction!D3 | E6: =100*((Extraction!E7+Extraction!E5+Extraction!E6-Extraction!E4)+0)/Extraction!E3 | F6: PBILDT / operating income
A7: PAT | B7: =Extraction!B10 | C7: =Extraction!C10 | D7: =Extraction!D10 | E7: =Extraction!E10 | F7: AR
A8: PAT margin (%) | B8: =100*Extraction!B10/Extraction!B3 | C8: =100*Extraction!C10/Extraction!C3 | D8: =100*Extraction!D10/Extraction!D3 | E8: =100*Extraction!E10/Extraction!E3 | F8: PAT / operating income
A9: Total debt | B9: =(Extraction!B51+Extraction!B59+Extraction!B52+Extraction!B60) | C9: =(Extraction!C51+Extraction!C59+Extraction!C52+Extraction!C60) | D9: =(Extraction!D51+Extraction!D59+Extraction!D52+Extraction!D60) | E9: =(Extraction!E51+Extraction!E59+Extraction!E52+Extraction!E60) | F9: borrowings + lease liabilities (CareEdge Sec.10)
A10: Net debt | B10: =(Extraction!B51+Extraction!B59+Extraction!B52+Extraction!B60)-(Extraction!B36+Extraction!B37+Extraction!B34) | C10: =(Extraction!C51+Extraction!C59+Extraction!C52+Extraction!C60)-(Extraction!C36+Extraction!C37+Extraction!C34) | D10: =(Extraction!D51+Extraction!D59+Extraction!D52+Extraction!D60)-(Extraction!D36+Extraction!D37+Extraction!D34) | E10: =(Extraction!E51+Extraction!E59+Extraction!E52+Extraction!E60)-(Extraction!E36+Extraction!E37+Extraction!E34) | F10: total debt less cash, other bank balances and current investments
A11: Tangible net worth | B11: =(Extraction!B49-Extraction!B21-Extraction!B22-Extraction!B23) | C11: =(Extraction!C49-Extraction!C21-Extraction!C22-Extraction!C23) | D11: =(Extraction!D49-Extraction!D21-Extraction!D22-Extraction!D23) | E11: =(Extraction!E49-Extraction!E21-Extraction!E22-Extraction!E23) | F11: total equity (incl. NCI) less goodwill and intangibles; DTA NOT deducted - that is the financial-sector definition (failure mode 32)
A12: Overall gearing (times) | B12: =(Extraction!B51+Extraction!B59+Extraction!B52+Extraction!B60)/(Extraction!B49-Extraction!B21-Extraction!B22-Extraction!B23) | C12: =(Extraction!C51+Extraction!C59+Extraction!C52+Extraction!C60)/(Extraction!C49-Extraction!C21-Extraction!C22-Extraction!C23) | D12: =(Extraction!D51+Extraction!D59+Extraction!D52+Extraction!D60)/(Extraction!D49-Extraction!D21-Extraction!D22-Extraction!D23) | E12: =(Extraction!E51+Extraction!E59+Extraction!E52+Extraction!E60)/(Extraction!E49-Extraction!E21-Extraction!E22-Extraction!E23) | F12: UNADJUSTED - acceptances and group guarantees not separately disclosed
A13: Total debt/PBILDT (times) | B13: =(Extraction!B51+Extraction!B59+Extraction!B52+Extraction!B60)/((Extraction!B7+Extraction!B5+Extraction!B6-Extraction!B4)+0) | C13: =(Extraction!C51+Extraction!C59+Extraction!C52+Extraction!C60)/((Extraction!C7+Extraction!C5+Extraction!C6-Extraction!C4)+0) | D13: =(Extraction!D51+Extraction!D59+Extraction!D52+Extraction!D60)/((Extraction!D7+Extraction!D5+Extraction!D6-Extraction!D4)+0) | E13: =(Extraction!E51+Extraction!E59+Extraction!E52+Extraction!E60)/((Extraction!E7+Extraction!E5+Extraction!E6-Extraction!E4)+0)
A14: Net debt/PBILDT (times) | B14: =((Extraction!B51+Extraction!B59+Extraction!B52+Extraction!B60)-(Extraction!B36+Extraction!B37+Extraction!B34))/((Extraction!B7+Extraction!B5+Extraction!B6-Extraction!B4)+0) | C14: =((Extraction!C51+Extraction!C59+Extraction!C52+Extraction!C60)-(Extraction!C36+Extraction!C37+Extraction!C34))/((Extraction!C7+Extraction!C5+Extraction!C6-Extraction!C4)+0) | D14: =((Extraction!D51+Extraction!D59+Extraction!D52+Extraction!D60)-(Extraction!D36+Extraction!D37+Extraction!D34))/((Extraction!D7+Extraction!D5+Extraction!D6-Extraction!D4)+0) | E14: =((Extraction!E51+Extraction!E59+Extraction!E52+Extraction!E60)-(Extraction!E36+Extraction!E37+Extraction!E34))/((Extraction!E7+Extraction!E5+Extraction!E6-Extraction!E4)+0)
A15: TOL/TNW (times) | B15: =(Extraction!B57+Extraction!B68)/(Extraction!B49-Extraction!B21-Extraction!B22-Extraction!B23) | C15: =(Extraction!C57+Extraction!C68)/(Extraction!C49-Extraction!C21-Extraction!C22-Extraction!C23) | D15: =(Extraction!D57+Extraction!D68)/(Extraction!D49-Extraction!D21-Extraction!D22-Extraction!D23) | E15: =(Extraction!E57+Extraction!E68)/(Extraction!E49-Extraction!E21-Extraction!E22-Extraction!E23) | F15: total outside liabilities / tangible net worth
A16: Interest coverage (times) | B16: =((Extraction!B7+Extraction!B5+Extraction!B6-Extraction!B4)+0)/Extraction!B5 | C16: =((Extraction!C7+Extraction!C5+Extraction!C6-Extraction!C4)+0)/Extraction!C5 | D16: =((Extraction!D7+Extraction!D5+Extraction!D6-Extraction!D4)+0)/Extraction!D5 | E16: =((Extraction!E7+Extraction!E5+Extraction!E6-Extraction!E4)+0)/Extraction!E5 | F16: PBILDT / finance costs
A17: Current ratio (times) | B17: =Extraction!B43/Extraction!B68 | C17: =Extraction!C43/Extraction!C68 | D17: =Extraction!D43/Extraction!D68 | E17: =Extraction!E43/Extraction!E68
A18: EPS (Rs) | B18: =Extraction!B12 | C18: =Extraction!C12 | D18: =Extraction!D12 | E18: =Extraction!E12 | F18: AR, basic

Sheet TieOut
A1: Check | B1: Computed (live) | C1: Disclosed | D1: Result | E1: Source
A2: Assets = equity + liabilities, FY2023 | B2: =Extraction!B44 | C2: =Extraction!B69 | D2: =IF(ABS(B2-C2)<=0.005,"PASS","FAIL") | E2: consolidated balance sheet
A3: Derived total assets = AR's printed total, FY2023 | B3: =Extraction!B44 | C3: =Extraction!B71 | D3: =IF(ABS(B3-C3)<=0.005,"PASS","FAIL") | E3: AR consolidated balance sheet, Total row
A4: Assets = equity + liabilities, FY2024 | B4: =Extraction!C44 | C4: =Extraction!C69 | D4: =IF(ABS(B4-C4)<=0.005,"PASS","FAIL") | E4: consolidated balance sheet
A5: Derived total assets = AR's printed total, FY2024 | B5: =Extraction!C44 | C5: =Extraction!C71 | D5: =IF(ABS(B5-C5)<=0.005,"PASS","FAIL") | E5: AR consolidated balance sheet, Total row
A6: Assets = equity + liabilities, FY2025 | B6: =Extraction!D44 | C6: =Extraction!D69 | D6: =IF(ABS(B6-C6)<=0.005,"PASS","FAIL") | E6: consolidated balance sheet
A7: Derived total assets = AR's printed total, FY2025 | B7: =Extraction!D44 | C7: =Extraction!D71 | D7: =IF(ABS(B7-C7)<=0.005,"PASS","FAIL") | E7: AR consolidated balance sheet, Total row
A8: Assets = equity + liabilities, FY2026 | B8: =Extraction!E44 | C8: =Extraction!E69 | D8: =IF(ABS(B8-C8)<=0.005,"PASS","FAIL") | E8: consolidated balance sheet
A9: Derived total assets = AR's printed total, FY2026 | B9: =Extraction!E44 | C9: =Extraction!E71 | D9: =IF(ABS(B9-C9)<=0.005,"PASS","FAIL") | E9: AR consolidated balance sheet, Total row
A10: PBILDT base = AR's own EBITDA line, FY2025 | B10: =RatioSuite!D3 | C10: 4666.63 | D10: =IF(ABS(B10-C10)<=0.005,"PASS","FAIL") | E10: FY2025-26 AR consolidated financial highlights, EBITDA row - the company publishes EBITDA on exactly this definition
A11: PBILDT base = AR's own EBITDA line, FY2026 | B11: =RatioSuite!E3 | C11: 5560.43 | D11: =IF(ABS(B11-C11)<=0.005,"PASS","FAIL") | E11: FY2025-26 AR consolidated financial highlights, EBITDA row - the company publishes EBITDA on exactly this definition
A12: Borrowings excl. leases = AR note, FY2023 | B12: =Extraction!B51+Extraction!B59 | C12: 3871.43 | D12: =IF(ABS(B12-C12)<=0.005,"PASS","FAIL") | E12: FY2023-24 AR capital-management note
A13: Borrowings excl. leases = AR note, FY2024 | B13: =Extraction!C51+Extraction!C59 | C13: 5948.19 | D13: =IF(ABS(B13-C13)<=0.005,"PASS","FAIL") | E13: FY2023-24 AR capital-management note
A15: FAILING ROWS (must be zero) | B15: =COUNTIF(D2:D13,"FAIL")

Sheet Conventions
A1: Definition | B1: As applied here, in CareEdge's own terms
A2: PBILDT | B2: PBT before exceptional items and share of equity-method investments, plus finance costs and depreciation, less other income. Non-debt forex stays INSIDE PBILDT in both directions (a gain reported in Other Income is restored); profit/loss on sale of assets and investments comes OUT.
A3: Tangible net worth | B3: Total equity including non-controlling interest, less goodwill and all intangibles. Deferred tax assets are NOT deducted - that belongs to the financial-sector definition.
A4: Total debt | B4: Borrowings plus lease liabilities. UNADJUSTED: CareEdge's adjusted measure also adds acceptances/LC creditors and group guarantees, neither separately disclosed in the consolidated accounts.
A5: Exceptional items | B5: Excluded by construction - the PBILDT base starts below them. The FY2025 Jindal Coke stake loss (7.06) and FY2026 Ind AS 103 gain (17.40) sit INSIDE exceptional items per note 39/40 and must NOT be added back again.
A6: DISCLOSED | B6: PBILDT equals the company's own published EBITDA - no residual to explain - Because neither CareEdge adjustment bites on this issuer, PBILDT here IS the base, and the base reproduces the annual report's own EBITDA line to the paisa in both years the company discloses one (FY2025 4,666.63; FY2026 5,560.43). For FY2023 and FY2024 the older annual report's capital-management note computes EBITDA off FULL profit before tax, so it carries the associate share and the exceptional item; bridging both back reproduces it exactly (FY2023 3,696.05; FY2024 4,856.57). There is no unexplained difference anywhere in the series.
A7: DISCLOSED | B7: Loss on disposal of fixed assets is left unadjusted, and that is a choice - CareEdge's criteria treat profit or loss on sale of assets as non-operating. Profit on sale of current investments (FY2026 3.75, FY2025 4.85) sits in Other Income and is already excluded by the base. Loss on disposal of property, plant and equipment is NOT isolated as a line in the Other Expenses note; the cash-flow reconciliation implies about 11.61 crore in FY2026, or 0.2% of PBILDT. It is left unadjusted and stated here rather than adjusted off the cash-flow reconciliation - which had already been misread once in this case, when its unrealised-forex row was mistaken for the P&L forex line.
A8: DISCLOSED | B8: Adjusted leverage cannot be computed - two CareEdge inputs are not separately disclosed - CareEdge's corporate criteria compute an ADJUSTED gearing that adds acceptances / LC creditors to total debt and adds back corporate guarantees issued to group entities. The trade-payables ageing note (note 55) confirms in a footnote that amounts pertaining to letters of credit ARE included within 'Others' trade payables, but does not quantify them; searches for 'acceptance', "buyer's credit" and 'letter of credit' return no separate figure in the consolidated accounts, and guarantees to subsidiaries are not separately quantified either. Gearing and net debt/PBILDT here are therefore the UNADJUSTED measures. This matters more than a footnote suggests: CareEdge's own published sensitivities for this issuer are framed on net debt INCLUDING acceptances, so the adjusted figures would be higher than those stated here. Both inputs should be obtained from the issuer.
A9: DISCLOSED | B9: Sales volume for FY2025 is derived, not disclosed - The FY2025-26 annual report states finished-goods sales volume of approximately 2.57 MT in FY2026, up 8.1%. The FY2025 figure of 2.377 MT is BACK-SOLVED from that growth rate and is not separately published, so PBILDT per tonne for FY2025 (19,633) inherits that derivation. Both per-tonne figures also rest on a volume the company itself reports as approximate, so they are indicative to roughly the nearest hundred rupees rather than precise to the rupee.
