Workbook

Sheet Inputs
B2: Repco Home Finance Limited - extracted line items (Standalone, Rs crore)
B3: Yellow cells are EXTRACTED INPUTS traced to the source in the final column - nothing here is computed. Every downstream ratio references this sheet, so correcting a value here reflows the entire workbook.
B5: Line item | C5: FY2023 | D5: FY2024 | E5: FY2025 | F5: FY2026 | G5: Q1FY2027 | H5: Source
B6: --- PROFIT AND LOSS ---
B7: Interest income | C7: 1257.01 | D7: 1495.98 | E7: 1648.19 | F7: 1750.13 | G7: 456.9 | H7: FY2023 AR, standalone balance sheet / P&L (audited) / FY2025 AR, standalone balance sheet / P&L (audited; FY2024 comparative column) / Q1FY2027 filing, 11-Aug-2026: audited year-ended-31-Mar-2026 column for FY2026 P&L; Reg 54(3) security-cover certificate for the 30-Jun-2026 balance sheet
B8: Revenue from operations | C8: 1283.74 | D8: 1524.52 | E8: 1685.16 | F8: 1795.79 | G8: 467.7 | H8: FY2023 AR, standalone balance sheet / P&L (audited) / FY2025 AR, standalone balance sheet / P&L (audited; FY2024 comparative column) / Q1FY2027 filing, 11-Aug-2026: audited year-ended-31-Mar-2026 column for FY2026 P&L; Reg 54(3) security-cover certificate for the 30-Jun-2026 balance sheet
B9: Other income | C9: 15.42 | D9: 16.28 | E9: 39.39 | F9: 1.9 | G9: 0.2 | H9: FY2023 AR, standalone balance sheet / P&L (audited) / FY2025 AR, standalone balance sheet / P&L (audited; FY2024 comparative column) / Q1FY2027 filing, 11-Aug-2026: audited year-ended-31-Mar-2026 column for FY2026 P&L; Reg 54(3) security-cover certificate for the 30-Jun-2026 balance sheet
B10: Total income | C10: 1299.16 | D10: 1540.8 | E10: 1724.55 | F10: 1797.69 | G10: 467.9 | H10: FY2023 AR, standalone balance sheet / P&L (audited) / FY2025 AR, standalone balance sheet / P&L (audited; FY2024 comparative column) / Q1FY2027 filing, 11-Aug-2026: audited year-ended-31-Mar-2026 column for FY2026 P&L; Reg 54(3) security-cover certificate for the 30-Jun-2026 balance sheet
B11: Finance costs | C11: 701.07 | D11: 845.57 | E11: 965.86 | F11: 984.18 | G11: 251.29 | H11: FY2023 AR, standalone balance sheet / P&L (audited) / FY2025 AR, standalone balance sheet / P&L (audited; FY2024 comparative column) / Q1FY2027 filing, 11-Aug-2026: audited year-ended-31-Mar-2026 column for FY2026 P&L; Reg 54(3) security-cover certificate for the 30-Jun-2026 balance sheet
B12: Employee cost | C12: 87.89 | D12: 102.18 | E12: 119.92 | F12: 148.5 | G12: 34.22 | H12: FY2023 AR, standalone balance sheet / P&L (audited) / FY2025 AR, standalone balance sheet / P&L (audited; FY2024 comparative column) / Q1FY2027 filing, 11-Aug-2026: audited year-ended-31-Mar-2026 column for FY2026 P&L; Reg 54(3) security-cover certificate for the 30-Jun-2026 balance sheet
B13: Depreciation and amortisation | C13: 14.97 | D13: 18.22 | E13: 28.64 | F13: 36.07 | G13: 10.38 | H13: FY2023 AR, standalone balance sheet / P&L (audited) / FY2025 AR, standalone balance sheet / P&L (audited; FY2024 comparative column) / Q1FY2027 filing, 11-Aug-2026: audited year-ended-31-Mar-2026 column for FY2026 P&L; Reg 54(3) security-cover certificate for the 30-Jun-2026 balance sheet
B14: Other expenses | C14: 42.92 | D14: 50.62 | E14: 60.21 | F14: 73.97 | G14: 14.58 | H14: FY2023 AR, standalone balance sheet / P&L (audited) / FY2025 AR, standalone balance sheet / P&L (audited; FY2024 comparative column) / Q1FY2027 filing, 11-Aug-2026: audited year-ended-31-Mar-2026 column for FY2026 P&L; Reg 54(3) security-cover certificate for the 30-Jun-2026 balance sheet
B15: Impairment on financial instruments (+ charge / - write-back) | C15: 51.55 | D15: -0.51 | E15: -37.57 | F15: -31.07 | G15: 9.69 | H15: FY2023 AR, standalone balance sheet / P&L (audited) / FY2025 AR, standalone balance sheet / P&L (audited; FY2024 comparative column) / Q1FY2027 filing, 11-Aug-2026: audited year-ended-31-Mar-2026 column for FY2026 P&L; Reg 54(3) security-cover certificate for the 30-Jun-2026 balance sheet - sign as reported; negative = write-back
B16: Profit before tax | C16: 400.76 | D16: 524.72 | E16: 587.49 | F16: 586.04 | G16: 147.74 | H16: FY2023 AR, standalone balance sheet / P&L (audited) / FY2025 AR, standalone balance sheet / P&L (audited; FY2024 comparative column) / Q1FY2027 filing, 11-Aug-2026: audited year-ended-31-Mar-2026 column for FY2026 P&L; Reg 54(3) security-cover certificate for the 30-Jun-2026 balance sheet
B17: Tax expense | C17: 104.68 | D17: 130.02 | E17: 148.05 | F17: 133.27 | G17: 33.59 | H17: FY2023 AR, standalone balance sheet / P&L (audited) / FY2025 AR, standalone balance sheet / P&L (audited; FY2024 comparative column) / Q1FY2027 filing, 11-Aug-2026: audited year-ended-31-Mar-2026 column for FY2026 P&L; Reg 54(3) security-cover certificate for the 30-Jun-2026 balance sheet
B18: Profit after tax | C18: 296.08 | D18: 394.7 | E18: 439.44 | F18: 452.77 | G18: 114.15 | H18: FY2023 AR, standalone balance sheet / P&L (audited) / FY2025 AR, standalone balance sheet / P&L (audited; FY2024 comparative column) / Q1FY2027 filing, 11-Aug-2026: audited year-ended-31-Mar-2026 column for FY2026 P&L; Reg 54(3) security-cover certificate for the 30-Jun-2026 balance sheet
B19: --- BALANCE SHEET ---
B20: Cash and cash equivalents | C20: 454.43 | D20: 348.21 | E20: 136.29 | G20: 136.83 | H20: FY2023 AR, standalone balance sheet / P&L (audited) / FY2025 AR, standalone balance sheet / P&L (audited; FY2024 comparative column) / Q1FY2027 filing, 11-Aug-2026: audited year-ended-31-Mar-2026 column for FY2026 P&L; Reg 54(3) security-cover certificate for the 30-Jun-2026 balance sheet
B21: Bank balances other than cash | C21: 0 | D21: 60.19 | E21: 0 | G21: 5.29 | H21: FY2023 AR, standalone balance sheet / P&L (audited) / FY2025 AR, standalone balance sheet / P&L (audited; FY2024 comparative column) / Q1FY2027 filing, 11-Aug-2026: audited year-ended-31-Mar-2026 column for FY2026 P&L; Reg 54(3) security-cover certificate for the 30-Jun-2026 balance sheet
B22: Loans (net of impairment allowance) | C22: 11962.15 | D22: 13042.36 | E22: 14109.18 | G22: 15708.23 | H22: FY2023 AR, standalone balance sheet / P&L (audited) / FY2025 AR, standalone balance sheet / P&L (audited; FY2024 comparative column) / Q1FY2027 filing, 11-Aug-2026: audited year-ended-31-Mar-2026 column for FY2026 P&L; Reg 54(3) security-cover certificate for the 30-Jun-2026 balance sheet
B23: Investments | C23: 31.6 | D23: 131.15 | E23: 211.23 | G23: 138.1 | H23: FY2023 AR, standalone balance sheet / P&L (audited) / FY2025 AR, standalone balance sheet / P&L (audited; FY2024 comparative column) / Q1FY2027 filing, 11-Aug-2026: audited year-ended-31-Mar-2026 column for FY2026 P&L; Reg 54(3) security-cover certificate for the 30-Jun-2026 balance sheet
B24: Other intangible assets | C24: 3.64 | D24: 11.05 | E24: 15.98 | G24: 17.69 | H24: FY2023 AR, standalone balance sheet / P&L (audited) / FY2025 AR, standalone balance sheet / P&L (audited; FY2024 comparative column) / Q1FY2027 filing, 11-Aug-2026: audited year-ended-31-Mar-2026 column for FY2026 P&L; Reg 54(3) security-cover certificate for the 30-Jun-2026 balance sheet
B25: Intangible assets under development | C25: 3.88 | D25: 4.48 | E25: 3.05 | G25: 5.21 | H25: FY2023 AR, standalone balance sheet / P&L (audited) / FY2025 AR, standalone balance sheet / P&L (audited; FY2024 comparative column) / Q1FY2027 filing, 11-Aug-2026: audited year-ended-31-Mar-2026 column for FY2026 P&L; Reg 54(3) security-cover certificate for the 30-Jun-2026 balance sheet
B26: Total assets | C26: 12523.43 | D26: 13707.11 | E26: 14602.24 | G26: 16245.83 | H26: FY2023 AR, standalone balance sheet / P&L (audited) / FY2025 AR, standalone balance sheet / P&L (audited; FY2024 comparative column) / Q1FY2027 filing, 11-Aug-2026: audited year-ended-31-Mar-2026 column for FY2026 P&L; Reg 54(3) security-cover certificate for the 30-Jun-2026 balance sheet
B27: Debt securities | C27: 0 | D27: 0 | E27: 0 | G27: 199.19 | H27: FY2025 AR, standalone balance sheet / P&L (audited; FY2024 comparative column) (nil to FY2025) / Q1FY2027 filing, 11-Aug-2026: audited year-ended-31-Mar-2026 column for FY2026 P&L; Reg 54(3) security-cover certificate for the 30-Jun-2026 balance sheet - listed secured NCD 125.49 + other 73.70
B28: Borrowings other than debt securities | C28: 9924.08 | D28: 10701.04 | E28: 11139.09 | G28: 11887.82 | H28: FY2023 AR, standalone balance sheet / P&L (audited) / FY2025 AR, standalone balance sheet / P&L (audited; FY2024 comparative column) / Q1FY2027 filing, 11-Aug-2026: audited year-ended-31-Mar-2026 column for FY2026 P&L; Reg 54(3) security-cover certificate for the 30-Jun-2026 balance sheet - bank 10,992.79 + others 895.03 at 30-Jun-2026
B29: Total liabilities | C29: 10007.26 | D29: 10813.16 | E29: 11288.69 | G29: 12227.18 | H29: FY2023 AR, standalone balance sheet / P&L (audited) / FY2025 AR, standalone balance sheet / P&L (audited; FY2024 comparative column) / Q1FY2027 filing, 11-Aug-2026: audited year-ended-31-Mar-2026 column for FY2026 P&L; Reg 54(3) security-cover certificate for the 30-Jun-2026 balance sheet
B30: Total equity (net worth) | C30: 2516.17 | D30: 2893.95 | E30: 3313.55 | G30: 4018.65 | H30: FY2023 AR, standalone balance sheet / P&L (audited) / FY2025 AR, standalone balance sheet / P&L (audited; FY2024 comparative column) / Reg 52(4) disclosure in the Q1FY2027 filing, 30-Jun-2026 (4,018.65, independently published)
B31: Impairment allowance on loans | C31: 519.04 | D31: 517.86 | E31: 433.39 | G31: 0 | H31: FY2023 AR, standalone balance sheet / P&L (audited) / FY2025 AR, standalone balance sheet / P&L (audited; FY2024 comparative column) - not disclosed after FY2025
... B33: Opening total equity (prior period) | C33: 2235.6 | D33: 2516.17 | E33: 2893.95 | G33: 3487.28 | H33: prior-period column of the same statement; 30-Sep-2025 for Q1FY2027 averaging
B34: Opening impairment allowance (prior period) | C34: 471.63 | D34: 519.04 | E34: 517.86 | H34: prior-period column of the same statement
B35: --- DISCLOSED / REGULATORY (not computed here) ---
B36: AUM - loan book as reported (Rs cr) | C36: 12449 | D36: 13513 | E36: 14492 | H36: FY2025 AR, management discussion and analysis / regulatory notes
B37: Disbursements (Rs cr) | C37: 2919 | D37: 3135 | E37: 3284 | H37: FY2025 AR, management discussion and analysis / regulatory notes
B38: Gross NPA % - excluding interest accrued and EIR | C38: 5.8 | D38: 4.08 | E38: 3.26 | G38: 2.67 | H38: FY2025 AR, management discussion and analysis / regulatory notes / Reg 52(4) disclosure in the Q1FY2027 filing, 30-Jun-2026
B39: Net NPA % - excluding interest accrued and EIR | D39: 1.46 | E39: 1.32 | G39: 1.23 | H39: FY2025 AR, management discussion and analysis / regulatory notes / Reg 52(4) disclosure in the Q1FY2027 filing, 30-Jun-2026
B40: Gross NPA % - including interest accrued (RBI sectoral format) | G40: 3.33 | H40: Reg 52(4) disclosure in the Q1FY2027 filing, 30-Jun-2026; FY2025 equivalent is 3.99% per the AR
B41: Capital-to-risk-weighted-assets ratio % | C41: 35.79 | D41: 33.97 | E41: 37.09 | H41: FY2025 AR, management discussion and analysis / regulatory notes Note 32.1 - not disclosed in any FY2026/FY2027 quarterly filing
B42: Tier I ratio % | D42: 33.19 | E42: 36.41 | H42: FY2025 AR, management discussion and analysis / regulatory notes Note 32.1
B43: Provision coverage ratio % | G43: 43.48 | H43: Reg 52(4) disclosure in the Q1FY2027 filing, 30-Jun-2026
...

Sheet RatioSuite
B2: Repco Home Finance Limited - ratio suite (Standalone, Rs crore; agency conventions applied)
B3: Every value is a LIVE FORMULA referencing the Inputs sheet - click any cell to see the arithmetic. 'Calculation' states the same formula in words; 'Convention' records the definitional choice (lease treatment, normalisation, netting) so the basis is auditable.
B5: Ratio | C5: FY2023 | D5: FY2024 | E5: FY2025 | F5: FY2026 | G5: Q1FY2027 | H5: Calculation | I5: Convention / note
B6: Net interest income (Rs cr) | C6: =(Inputs!C8-Inputs!C11) -> 582.67 | D6: =(Inputs!D8-Inputs!D11) -> 678.95 | E6: =(Inputs!E8-Inputs!E11) -> 719.3 | F6: =(Inputs!F8-Inputs!F11) -> 811.61 | G6: =(Inputs!G8-Inputs!G11) -> 216.41 | H6: revenue from operations less finance costs
B7: Pre-provision operating profit (Rs cr) | C7: =Inputs!C16+Inputs!C15 -> 452.31 | D7: =Inputs!D16+Inputs!D15 -> 524.21 | E7: =Inputs!E16+Inputs!E15 -> 549.92 | F7: =Inputs!F16+Inputs!F15 -> 554.97 | G7: =Inputs!G16+Inputs!G15 -> 157.43 | H7: PBT add back the impairment line, so the credit-cost swing is visible
B8: Operating expenses (Rs cr) | C8: =(Inputs!C12+Inputs!C13+Inputs!C14) -> 145.78 | D8: =(Inputs!D12+Inputs!D13+Inputs!D14) -> 171.02 | E8: =(Inputs!E12+Inputs!E13+Inputs!E14) -> 208.77 | F8: =(Inputs!F12+Inputs!F13+Inputs!F14) -> 258.54 | G8: =(Inputs!G12+Inputs!G13+Inputs!G14) -> 59.18 | H8: employee + depreciation + other expenses
B9: Total managed assets (Rs cr) | C9: =IF(Inputs!C26="","NA",(Inputs!C26+Inputs!C31)) -> 13042.47 | D9: =IF(Inputs!D26="","NA",(Inputs!D26+Inputs!D31)) -> 14224.97 | E9: =IF(Inputs!E26="","NA",(Inputs!E26+Inputs!E31)) -> 15035.63 | F9: =IF(Inputs!F26="","NA",(Inputs!F26+Inputs!F31)) -> NA | G9: =IF(Inputs!G26="","NA",(Inputs!G26+Inputs!G31)) -> 16245.83 | H9: total assets + impairment allowance (ICRA definition)
B10: Total debt (Rs cr) | C10: =IF(Inputs!C26="","NA",(Inputs!C27+Inputs!C28)) -> 9924.08 | D10: =IF(Inputs!D26="","NA",(Inputs!D27+Inputs!D28)) -> 10701.04 | E10: =IF(Inputs!E26="","NA",(Inputs!E27+Inputs!E28)) -> 11139.09 | F10: =IF(Inputs!F26="","NA",(Inputs!F27+Inputs!F28)) -> NA | G10: =IF(Inputs!G26="","NA",(Inputs!G27+Inputs!G28)) -> 12087.01 | H10: debt securities + borrowings; leases excluded
B11: Tangible net worth (Rs cr) | C11: =IF(Inputs!C26="","NA",(Inputs!C30-Inputs!C24-Inputs!C25)) -> 2508.65 | D11: =IF(Inputs!D26="","NA",(Inputs!D30-Inputs!D24-Inputs!D25)) -> 2878.42 | E11: =IF(Inputs!E26="","NA",(Inputs!E30-Inputs!E24-Inputs!E25)) -> 3294.52 | F11: =IF(Inputs!F26="","NA",(Inputs!F30-Inputs!F24-Inputs!F25)) -> NA | G11: =IF(Inputs!G26="","NA",(Inputs!G30-Inputs!G24-Inputs!G25)) -> 3995.75 | H11: equity less intangibles and intangibles under development
B12: Net interest margin % (on average total assets) | C12: =IF(Inputs!C26="","NA",100*(Inputs!C8-Inputs!C11)*(IF(0=4,4,1))/((Inputs!C26+Inputs!C32)/2)) -> 4.7524512 | D12: =IF(Inputs!D26="","NA",100*(Inputs!D8-Inputs!D11)*(IF(1=4,4,1))/((Inputs!D26+Inputs!D32)/2)) -> 5.1767901 | E12: =IF(Inputs!E26="","NA",100*(Inputs!E8-Inputs!E11)*(IF(2=4,4,1))/((Inputs!E26+Inputs!E32)/2)) -> 5.0817133 | F12: =IF(Inputs!F26="","NA",100*(Inputs!F8-Inputs!F11)*(IF(3=4,4,1))/((Inputs!F26+Inputs!F32)/2)) -> NA | G12: =IF(Inputs!G26="","NA",100*(Inputs!G8-Inputs!G11)*(IF(4=4,4,1))/((Inputs!G26+Inputs!G32)/2)) -> 5.5078543 | H12: annualised NII over average total assets
B13: Operating expenses / average total assets % | C13: =IF(Inputs!C26="","NA",100*(Inputs!C12+Inputs!C13+Inputs!C14)*(IF(0=4,4,1))/((Inputs!C26+Inputs!C32)/2)) -> 1.1890304 | D13: =IF(Inputs!D26="","NA",100*(Inputs!D12+Inputs!D13+Inputs!D14)*(IF(1=4,4,1))/((Inputs!D26+Inputs!D32)/2)) -> 1.3039762 | E13: =IF(Inputs!E26="","NA",100*(Inputs!E12+Inputs!E13+Inputs!E14)*(IF(2=4,4,1))/((Inputs!E26+Inputs!E32)/2)) -> 1.4749191 | F13: =IF(Inputs!F26="","NA",100*(Inputs!F12+Inputs!F13+Inputs!F14)*(IF(3=4,4,1))/((Inputs!F26+Inputs!F32)/2)) -> NA | G13: =IF(Inputs!G26="","NA",100*(Inputs!G12+Inputs!G13+Inputs!G14)*(IF(4=4,4,1))/((Inputs!G26+Inputs!G32)/2)) -> 1.5061911 | H13: ICRA's NBFC efficiency measure, not cost-to-income
B14: Cost-to-income % | C14: =100*(Inputs!C12+Inputs!C13+Inputs!C14)/(Inputs!C10-Inputs!C11) -> 24.374258 | D14: =100*(Inputs!D12+Inputs!D13+Inputs!D14)/(Inputs!D10-Inputs!D11) -> 24.599054 | E14: =100*(Inputs!E12+Inputs!E13+Inputs!E14)/(Inputs!E10-Inputs!E11) -> 27.517168 | F14: =100*(Inputs!F12+Inputs!F13+Inputs!F14)/(Inputs!F10-Inputs!F11) -> 31.780802 | G14: =100*(Inputs!G12+Inputs!G13+Inputs!G14)/(Inputs!G10-Inputs!G11) -> 27.320992 | H14: secondary cross-reference only; bank vocabulary
B15: Credit cost % (on average managed assets) | C15: =IF(Inputs!C26="","NA",100*Inputs!C15*(IF(0=4,4,1))/(((Inputs!C26+Inputs!C31)+(Inputs!C32+Inputs!C34))/2)) -> 0.40413163 | D15: =IF(Inputs!D26="","NA",100*Inputs!D15*(IF(1=4,4,1))/(((Inputs!D26+Inputs!D31)+(Inputs!D32+Inputs!D34))/2)) -> -0.0037407252 | E15: =IF(Inputs!E26="","NA",100*Inputs!E15*(IF(2=4,4,1))/(((Inputs!E26+Inputs!E31)+(Inputs!E32+Inputs!E34))/2)) -> -0.25679583 | F15: =IF(Inputs!F26="","NA",100*Inputs!F15*(IF(3=4,4,1))/(((Inputs!F26+Inputs!F31)+(Inputs!F32+Inputs!F34))/2)) -> NA | G15: =IF(Inputs!G26="","NA",100*Inputs!G15*(IF(4=4,4,1))/(((Inputs!G26+Inputs!G31)+(Inputs!G32+Inputs!G34))/2)) -> 0.24662034 | H15: negative = write-back releasing provisions into profit
B16: Return on average managed assets % | C16: =IF(Inputs!C26="","NA",100*Inputs!C18*(IF(0=4,4,1))/(((Inputs!C26+Inputs!C31)+(Inputs!C32+Inputs!C34))/2)) -> 2.3211502 | D16: =IF(Inputs!D26="","NA",100*Inputs!D18*(IF(1=4,4,1))/(((Inputs!D26+Inputs!D31)+(Inputs!D32+Inputs!D34))/2)) -> 2.8950279 | E16: =IF(Inputs!E26="","NA",100*Inputs!E18*(IF(2=4,4,1))/(((Inputs!E26+Inputs!E31)+(Inputs!E32+Inputs!E34))/2)) -> 3.0036295 | F16: =IF(Inputs!F26="","NA",100*Inputs!F18*(IF(3=4,4,1))/(((Inputs!F26+Inputs!F31)+(Inputs!F32+Inputs!F34))/2)) -> NA | G16: =IF(Inputs!G26="","NA",100*Inputs!G18*(IF(4=4,4,1))/(((Inputs!G26+Inputs!G31)+(Inputs!G32+Inputs!G34))/2)) -> 2.9052335 | H16: ICRA's headline HFC return measure
B17: Return on average total assets % | C17: =IF(Inputs!C26="","NA",100*Inputs!C18*(IF(0=4,4,1))/((Inputs!C26+Inputs!C32)/2)) -> 2.4149274 | D17: =IF(Inputs!D26="","NA",100*Inputs!D18*(IF(1=4,4,1))/((Inputs!D26+Inputs!D32)/2)) -> 3.0094691 | E17: =IF(Inputs!E26="","NA",100*Inputs!E18*(IF(2=4,4,1))/((Inputs!E26+Inputs!E32)/2)) -> 3.1045573 | F17: =IF(Inputs!F26="","NA",100*Inputs!F18*(IF(3=4,4,1))/((Inputs!F26+Inputs!F32)/2)) -> NA | G17: =IF(Inputs!G26="","NA",100*Inputs!G18*(IF(4=4,4,1))/((Inputs!G26+Inputs!G32)/2)) -> 2.9052335 | H17: reproduces the AR's 3.1% and CareEdge's 3.11% for FY2025
B18: Return on average net worth % | C18: =IF(Inputs!C26="","NA",100*Inputs!C18*(IF(0=4,4,1))/((Inputs!C30+Inputs!C33)/2)) -> 12.461883 | D18: =IF(Inputs!D26="","NA",100*Inputs!D18*(IF(1=4,4,1))/((Inputs!D30+Inputs!D33)/2)) -> 14.591174 | E18: =IF(Inputs!E26="","NA",100*Inputs!E18*(IF(2=4,4,1))/((Inputs!E30+Inputs!E33)/2)) -> 14.158357 | F18: =IF(Inputs!F26="","NA",100*Inputs!F18*(IF(3=4,4,1))/((Inputs!F30+Inputs!F33)/2)) -> NA | G18: =IF(Inputs!G26="","NA",100*Inputs!G18*(IF(4=4,4,1))/((Inputs!G30+Inputs!G33)/2)) -> 12.16638 | H18: average denominator; the AR uses opening equity
B19: Gearing (times) | C19: =IF(Inputs!C26="","NA",(Inputs!C27+Inputs!C28)/Inputs!C30) -> 3.9441214 | D19: =IF(Inputs!D26="","NA",(Inputs!D27+Inputs!D28)/Inputs!D30) -> 3.697728 | E19: =IF(Inputs!E26="","NA",(Inputs!E27+Inputs!E28)/Inputs!E30) -> 3.3616786 | F19: =IF(Inputs!F26="","NA",(Inputs!F27+Inputs!F28)/Inputs!F30) -> NA | G19: =IF(Inputs!G26="","NA",(Inputs!G27+Inputs!G28)/Inputs!G30) -> 3.007729 | H19: total debt over net worth
B20: Gearing on tangible net worth (times) | C20: =IF(Inputs!C26="","NA",(Inputs!C27+Inputs!C28)/(Inputs!C30-Inputs!C24-Inputs!C25)) -> 3.9559444 | D20: =IF(Inputs!D26="","NA",(Inputs!D27+Inputs!D28)/(Inputs!D30-Inputs!D24-Inputs!D25)) -> 3.7176784 | E20: =IF(Inputs!E26="","NA",(Inputs!E27+Inputs!E28)/(Inputs!E30-Inputs!E24-Inputs!E25)) -> 3.3810965 | F20: =IF(Inputs!F26="","NA",(Inputs!F27+Inputs!F28)/(Inputs!F30-Inputs!F24-Inputs!F25)) -> NA | G20: =IF(Inputs!G26="","NA",(Inputs!G27+Inputs!G28)/(Inputs!G30-Inputs!G24-Inputs!G25)) -> 3.0249665 | H20: same numerator, intangibles stripped from the denominator
B21: Managed assets / tangible net worth (times) | C21: =IF(Inputs!C26="","NA",(Inputs!C26+Inputs!C31)/(Inputs!C30-Inputs!C24-Inputs!C25)) -> 5.1989995 | D21: =IF(Inputs!D26="","NA",(Inputs!D26+Inputs!D31)/(Inputs!D30-Inputs!D24-Inputs!D25)) -> 4.9419369 | E21: =IF(Inputs!E26="","NA",(Inputs!E26+Inputs!E31)/(Inputs!E30-Inputs!E24-Inputs!E25)) -> 4.5638302 | F21: =IF(Inputs!F26="","NA",(Inputs!F26+Inputs!F31)/(Inputs!F30-Inputs!F24-Inputs!F25)) -> NA | G21: =IF(Inputs!G26="","NA",(Inputs!G26+Inputs!G31)/(Inputs!G30-Inputs!G24-Inputs!G25)) -> 4.0657774 | H21: balance-sheet leverage including the provision cushion
B22: Equity / total assets % | C22: =IF(Inputs!C26="","NA",100*Inputs!C30/Inputs!C26) -> 20.0917 | D22: =IF(Inputs!D26="","NA",100*Inputs!D30/Inputs!D26) -> 21.112766 | E22: =IF(Inputs!E26="","NA",100*Inputs!E30/Inputs!E26) -> 22.692066 | F22: =IF(Inputs!F26="","NA",100*Inputs!F30/Inputs!F26) -> NA | G22: =IF(Inputs!G26="","NA",100*Inputs!G30/Inputs!G26) -> 24.736502 | H22: book capitalisation
B23: Book value per share (Rs) | C23: =IF(Inputs!C26="","NA",Inputs!C30/6.2561362) -> 402.19233 | D23: =IF(Inputs!D26="","NA",Inputs!D30/6.2561362) -> 462.57784 | E23: =IF(Inputs!E26="","NA",Inputs!E30/6.2561362) -> 529.648 | F23: =IF(Inputs!F26="","NA",Inputs!F30/6.2561362) -> NA | G23: =IF(Inputs!G26="","NA",Inputs!G30/6.2561362) -> 642.35334 | H23: 62,561,362 shares, unchanged throughout
B24: Basic EPS (Rs) | C24: =Inputs!C18*(IF(0=4,4,1))/6.2561362 -> 47.326335 | D24: =Inputs!D18*(IF(1=4,4,1))/6.2561362 -> 63.090059 | E24: =Inputs!E18*(IF(2=4,4,1))/6.2561362 -> 70.241438 | F24: =Inputs!F18*(IF(3=4,4,1))/6.2561362 -> 72.372146 | G24: =Inputs!G18*(IF(4=4,4,1))/6.2561362 -> 72.984345 | H24: annualised for the quarter
B25: Liquid assets - cash and bank (Rs cr) | C25: =IF(Inputs!C26="","NA",Inputs!C20+Inputs!C21) -> 454.43 | D25: =IF(Inputs!D26="","NA",Inputs!D20+Inputs!D21) -> 408.4 | E25: =IF(Inputs!E26="","NA",Inputs!E20+Inputs!E21) -> 136.29 | F25: =IF(Inputs!F26="","NA",Inputs!F20+Inputs!F21) -> NA | G25: =IF(Inputs!G26="","NA",Inputs!G20+Inputs!G21) -> 142.12 | H25: on-balance-sheet cash only; excludes undrawn lines, which are not disclosed
B26: Non-housing (home equity) share of book % | C26: =IF(Inputs!C46="","NA",100*Inputs!C46/Inputs!C36) -> 20.684392 | D26: =IF(Inputs!D46="","NA",100*Inputs!D46/Inputs!D36) -> 25.26456 | E26: =IF(Inputs!E46="","NA",100*Inputs!E46/Inputs!E36) -> 26.973503 | F26: =IF(Inputs!F46="","NA",100*Inputs!F46/Inputs!F36) -> NA | G26: =IF(Inputs!G46="","NA",100*Inputs!G46/Inputs!G36) -> NA | H26: the mix shift that carries the higher delinquency

Sheet TieOut
B2: Repco Home Finance Limited - tie-out to company-disclosed figures
B3: Binding gate (CLAUDE.md Step 6): headline computed figures must reconcile to the company's OWN disclosed numbers before the workpaper is issued. PASS/FAIL is itself a formula - it re-evaluates if any input changes.
B5: Check | C5: Computed | D5: Company-disclosed | E5: Result | F5: Note
B6: Balance sheet ties, FY2025 | C6: =Inputs!E26-Inputs!E29-Inputs!E30 -> -9.094947e-13 | D6: 0 | E6: =IF(ABS(C6-D6)<=MAX(1,ABS(D6)*0.005),"PASS","CHECK") -> PASS | F6: assets less (liabilities + equity); FY2025 AR
B7: Balance sheet ties, 30-Jun-2026 | C7: =Inputs!G26-Inputs!G29-Inputs!G30 -> -4.5474735e-13 | D7: 0 | E7: =IF(ABS(C7-D7)<=MAX(1,ABS(D7)*0.005),"PASS","CHECK") -> PASS | F7: Reg 54(3) security-cover certificate, 30-Jun-2026
B8: Total debt / total assets, 30-Jun-2026 | C8: =(Inputs!G27+Inputs!G28)/Inputs!G26 -> 0.74400692 | D8: 0.74 | E8: =IF(ABS(C8-D8)<=MAX(1,ABS(D8)*0.005),"PASS","CHECK") -> PASS | F8: company's own Reg 52(4) disclosure - proves the assembled debt figure
B9: Net worth, 30-Jun-2026 | C9: =Inputs!G30 -> 4018.65 | D9: 4018.65 | E9: =IF(ABS(C9-D9)<=MAX(1,ABS(D9)*0.005),"PASS","CHECK") -> PASS | F9: company's own Reg 52(4) disclosure
B10: Net profit margin, Q1FY2027 | C10: =100*Inputs!G18/Inputs!G10 -> 24.396239 | D10: 24.4 | E10: =IF(ABS(C10-D10)<=MAX(1,ABS(D10)*0.005),"PASS","CHECK") -> PASS | F10: company's own Reg 52(4) disclosure
B11: Net interest income, FY2025 | C11: =Inputs!E8-Inputs!E11 -> 719.3 | D11: 719 | E11: =IF(ABS(C11-D11)<=MAX(1,ABS(D11)*0.005),"PASS","CHECK") -> PASS | F11: FY2025 AR six-year highlights - proves the NII convention
B12: Net interest income, FY2024 | C12: =Inputs!D8-Inputs!D11 -> 678.95 | D12: 679 | E12: =IF(ABS(C12-D12)<=MAX(1,ABS(D12)*0.005),"PASS","CHECK") -> PASS | F12: FY2025 AR six-year highlights
B13: Basic EPS, FY2025 | C13: =Inputs!E18/6.2561362 -> 70.241438 | D13: 70.24 | E13: =IF(ABS(C13-D13)<=MAX(1,ABS(D13)*0.005),"PASS","CHECK") -> PASS | F13: FY2025 AR statement of profit and loss
B14: Gross loan exposure, FY2025 | C14: =Inputs!E22+Inputs!E31 -> 14542.57 | D14: 14542.57 | E14: =IF(ABS(C14-D14)<=MAX(1,ABS(D14)*0.005),"PASS","CHECK") -> PASS | F14: FY2025 AR sector-wise NPA table - proves the impairment allowance
B15: Return on average total assets, FY2025 | C15: =100*Inputs!E18/((Inputs!E26+Inputs!E32)/2) -> 3.1045573 | D15: 3.11 | E15: =IF(ABS(C15-D15)<=MAX(1,ABS(D15)*0.005),"PASS","CHECK") -> PASS | F15: CareEdge press release 30-Sep-2025 (3.11%) and the FY2025 AR chart (3.1%)
B16: FY2026 PAT = PBT less tax | C16: =Inputs!F16-Inputs!F17 -> 452.77 | D16: 452.77 | E16: =IF(ABS(C16-D16)<=MAX(1,ABS(D16)*0.005),"PASS","CHECK") -> PASS | F16: Q1FY2027 filing, audited FY2026 column
B17: CRAR FY2025 = Tier I + Tier II | C17: =Inputs!E42+0.68 -> 37.09 | D17: 37.09 | E17: =IF(ABS(C17-D17)<=MAX(1,ABS(D17)*0.005),"PASS","CHECK") -> PASS | F17: FY2025 AR Note 32.1
B19: Tolerance: 0.5% of the disclosed figure, floor Rs 1 - tighter than rounding, loose enough for basis differences.

Sheet RatingScore
B2: Repco Home Finance Limited - rating scorecard and view
B3: Factor scores 1 (strongest) to 6 (weakest), weighted to a composite. The anchor is a SCREENING cross-check with a +/-2 notch band, NOT the rating - the analyst view and any divergence are stated below and the divergence must be explained, never buried.
B5: Rating factor | C5: Score (1-6) | D5: Weight | E5: Weighted | F5: Justification
B6: Franchise and scale | C6: 4 | D6: 0.15 | E6: =C6*D6 -> 0.6 | F6: A 25-year-old HFC with a defensible niche in tier-2/tier-3 south India, but small: AUM of Rs 14,492 crore (FY2025) against PNB Housing's Rs 98,000 crore and LIC Housing's far larger book. Growth is the weak point - AUM compounded 7.2% a year from Rs 11,759 crore in FY2022, and the network expansion (159 to 189 branches, 192 to 233 touchpoints over FY2023-FY2025) has not yet converted into faster book growth. Disbursements of Rs 3,284 crore in FY2025 grew only 4.8%.
B7: Asset quality | C7: 4 | D7: 0.25 | E7: =C7*D7 -> 1 | F7: The direction is unambiguously favourable and sustained across four years - GNPA 7.0% (FY2022) to 5.8% to 4.08% to 3.26% (FY2025) to 2.67% at 30-Jun-2026, all excluding interest accrued - and net NPA 1.46% to 1.32% to 1.23%. But the LEVEL remains weak for the sector: ICRA's own NBFC methodology puts HFCs at strongest below 1.5% and weakest above 5.5% on 90+ dpd, so 2.67% sits mid-band, against 0.9% for PNB Housing and 1.2% for Aptus. Two live qualifiers: the restructured pool of Rs 253.49 crore (30-Sep-2025) is still slipping - Rs 10.15 crore then Rs 15.89 crore into NPA in successive half-years - and provision coverage of 43.48% is thin, defensible only because the book is fully mortgage-secured. Non-housing loans, at 27% of the book and rising, carry the higher delinquency (4.14% vs 3.93%).
B8: Capitalisation | C8: 2 | D8: 0.25 | E8: =C8*D8 -> 0.5 | F8: The clearest strength. CRAR of 37.09% at FY2025 (Tier I 36.41%) against a 15% regulatory minimum is 22 percentage points of headroom; gearing has fallen from 3.94x (FY2023) to 3.01x at 30-Jun-2026 and equity funds 24.74% of the balance sheet. Net worth of Rs 4,018.65 crore supports the current book more than twice over at the HFC leverage ceiling of 12x net owned funds. Capital is not the constraint on this rating in any foreseeable case.
B9: Earnings | C9: 3 | D9: 0.2 | E9: =C9*D9 -> 0.6 | F9: Headline returns are strong - RoAMA 3.00% and return on average net worth 14.16% in FY2025 - and comfortably above CareEdge's own 2.00% downgrade trigger. The qualification is what produced them. Impairment was a WRITE-BACK in each of FY2024 (Rs 0.51 crore), FY2025 (Rs 37.57 crore) and FY2026 (Rs 31.07 crore); pre-provision operating profit was Rs 524.21, Rs 549.92 and Rs 554.97 crore across those years - growth of 4.9% then 0.9%. FY2026 profit before tax of Rs 586.04 crore was FLAT on FY2025's Rs 587.49 crore and PAT rose only because a Rs 14.40 crore deferred-tax liability on the Section 36(1)(viii) special reserve was reversed. In Q1FY2027 the impairment line turned back to a charge of Rs 9.69 crore. Core earnings power is adequate and stable, not growing.
B10: Resource profile | C10: 5 | D10: 0.15 | E10: =C10*D10 -> 0.75 | F10: The weakest factor and the one that most constrains the rating. At 31-Mar-2025 funding was 100% bank and NHB term borrowing - commercial paper, ECB, secured NCDs, subordinated Tier-II and public deposits all nil (AR Note 34(iv)). Twelve significant counterparties accounted for 96.69% of total liabilities and the top ten borrowings for 93.34% of total borrowings. The first NCD issuance came only in FY2026 and stood at Rs 199.19 crore at 30-Jun-2026, 1.6% of debt. Cash of Rs 142.12 crore covers 1.2% of debt, and Rs 791.11 crore of sanctioned-but-undisbursed commitments is a further near-term call. The offsets are real - LCR of 202.13%, an uninterrupted repayment record, and a book that is entirely amortising retail mortgage - but a lender with one funding channel is exposed to that channel.
B11: Weight check (must be 100%) | D11: =SUM(D6:D10) -> 1 | E11: =SUM(E6:E10) -> 3.45 | F11: =IF(ABS(D11-1)<0.001,"weights sum to 100%","ERROR: weights must sum to 100%") -> weights sum to 100%
B13: Weighted composite score | C13: =E11 -> 3.45
B14: Indicative anchor grade (screening only, +/-2 band) | C14: AA- / A+ band
B15: ANALYST RATING VIEW | C15: [ICRA]AA- (Stable) / [ICRA]A1+
B16: Divergence from anchor - explanation | C16: My independent view, formed at Step 13 before any prior rating was opened for the conclusion, is [ICRA]AA- (Stable) on the long-term facilities and [ICRA]A1+ on commercial paper. The company's own FY2025 annual report (Note 32.17 and the corporate governance report) records that ICRA already rates it AA- (Stable) on long-term fund-based term loans and NCDs and A1+ on commercial paper, and CareEdge independently rates it AA-; Stable / A1+ (press release 30-Sep-2025). There is therefore NO divergence to resolve. The rating balances capitalisation that is genuinely exceptional - 37% CRAR, 3.01x gearing - and an asset-quality trajectory that has improved for four consecutive years, against a resource profile that is effectively single-channel and a franchise whose growth has not accelerated. The case for a higher grade fails on the resource profile and scale, not on capital or asset quality; the case for a lower grade fails because every adverse metric is improving and capital cover is extreme. NOTE ON THE [ICRA]AAA(SO) IN THE LIBRARY: ICRA's file dated 25-Feb-2026 titled 'Repco Home Finance Limited' rates SECURITISATION NOTES issued by the PRATHAM 12 2025 trust, backed by a pool of Repco-originated LAP receivables, on which Repco is the ORIGINATOR and servicer. [ICRA]AAA(SO) on Rs 92.80 crore of Series A1 notes and [ICRA]AA-(SO) on Rs 4.99 crore of equity-tranche notes are structured-obligation ratings on that trust's paper. Neither is Repco's issuer rating and neither has been imported here.
