Workbook

Sheet Assumptions
A1: Ashok Leyland Limited - standalone 5-year model (Rs crore). Base case shown on every statement tab; Scenarios tab carries Bull / Bear (rating stress) / Tail.
A2: Generated by build_model.py from compute_ratios.py (182+ tie-outs). Historical columns FY2023-FY2026 are audited; yellow = projection. Re-run the script to flex a driver.
A4: Driver | B4: FY2027E | C4: FY2028E | D4: FY2029E | E4: FY2030E | F4: FY2031E | G4: Source / basis
A5: Total vehicle volume growth (%) - Base | B5: 5 | C5: 5 | D5: 2 | E5: -4 | F5: 4 | G5: ANALYST JUDGMENT. FY2027 per FY2026 AR MD&A: 'FY27 is expected to mark a year of disciplined, consolidation-led growth'. FY2029-30 moderation reflects the company's own ten-year table (FY2019 peak 1,97,366 -> FY2021 1,00,725 vehicles): a CV upcycle (FY2022-26) is not assumed to run unbroken. Timing is illustrative, not a forecast.
A6: Total vehicle volume growth (%) - Bull | B6: 8 | C6: 8 | D6: 6 | E6: 4 | F6: 5
A7: Total vehicle volume growth (%) - Bear / rating stress | B7: -8 | C7: -25 | D7: -10 | E7: 15 | F7: 10
A8: Total vehicle volume growth (%) - Tail (FY2019-21 repeat) | B8: -37 | C8: -20 | D8: 27 | E8: 40 | F8: 10
A9: CV realisation per vehicle growth (%) - Base | B9: 1.5 | C9: 1.5 | D9: 1.5 | E9: 1.5 | F9: 1.5 | G9: ANALYST JUDGMENT. History (CV revenue / vehicles): Rs 16.46 lakh FY2023 -> 16.71 lakh FY2026, about +0.5% a year; 1.5% allows for premiumisation (chairman's letter) and price increases.
A10: CV realisation per vehicle growth (%) - Bull | B10: 2 | C10: 2 | D10: 2 | E10: 2 | F10: 2
A11: CV realisation per vehicle growth (%) - Bear / rating stress | B11: 0 | C11: -1 | D11: 0 | E11: 1 | F11: 1.5
A12: CV realisation per vehicle growth (%) - Tail (FY2019-21 repeat) | B12: 0 | C12: 0 | D12: 3 | E12: 3 | F12: 2
A13: Engines and gensets growth (%) - Base | B13: 10 | C13: 10 | D13: 8 | E13: 6 | F13: 8 | G13: ANALYST JUDGMENT, well below the FY2023-26 CAGR of 30.7% (633.84 -> 1,414.29, note 3.7.1); Power Solutions crossed Rs 1,000 crore 'for the second year' (chairman).
A14: Engines and gensets growth (%) - Bull | B14: 10 | C14: 10 | D14: 8 | E14: 6 | F14: 8
A15: Engines and gensets growth (%) - Bear / rating stress | B15: 3 | C15: -5 | D15: 0 | E15: 5 | F15: 5
A16: Engines and gensets growth (%) - Tail (FY2019-21 repeat) | B16: -15 | C16: -5 | D16: 15 | E16: 15 | F16: 8
A17: Spare parts and others growth (%) - Base | B17: 8 | C17: 8 | D17: 7 | E17: 5 | F17: 7 | G17: ANALYST JUDGMENT, below the FY2023-26 CAGR of 20.0% (2,577.88 -> 4,450.37, note 3.7.1).
A18: Spare parts and others growth (%) - Bull | B18: 8 | C18: 8 | D18: 7 | E18: 5 | F18: 7
A19: Spare parts and others growth (%) - Bear / rating stress | B19: 3 | C19: -5 | D19: 0 | E19: 5 | F19: 5
A20: Spare parts and others growth (%) - Tail (FY2019-21 repeat) | B20: -15 | C20: -5 | D20: 15 | E20: 15 | F20: 8
A21: Castings / services / scrap / other operating revenue growth (%) - Base | B21: 3 | C21: 3 | D21: 3 | E21: 3 | F21: 3 | G21: ANALYST JUDGMENT - roughly inflation; FY2023-26 services grew 1,106.88 -> 1,257.11.
A22: Castings / services / scrap / other operating revenue growth (%) - Bull | B22: 3 | C22: 3 | D22: 3 | E22: 3 | F22: 3
A23: Castings / services / scrap / other operating revenue growth (%) - Bear / rating stress | B23: 3 | C23: 3 | D23: 3 | E23: 3 | F23: 3
A24: Castings / services / scrap / other operating revenue growth (%) - Tail (FY2019-21 repeat) | B24: 3 | C24: 3 | D24: 3 | E24: 3 | F24: 3
A25: OPBDITA margin (%) - Base | B25: 13 | C25: 13 | D25: 12.5 | E25: 11.5 | F25: 12.5 | G25: ANALYST JUDGMENT anchored on FY2026 actual 13.03% (engine). Management's 'mid-teen EBITDA in the medium term' (Q1 FY2025 press release) is used only in the Bull case.
A26: OPBDITA margin (%) - Bull | B26: 13.5 | C26: 14 | D26: 14.5 | E26: 14.5 | F26: 14.5
A27: OPBDITA margin (%) - Bear / rating stress | B27: 10.5 | C27: 6 | D27: 7.5 | E27: 10 | F27: 11
A28: OPBDITA margin (%) - Tail (FY2019-21 repeat) | B28: 6 | C28: 3 | D28: 8 | E28: 11 | F28: 12.5
A29: Employee cost growth (%) - Base | B29: 7 | C29: 7 | D29: 7 | E29: 7 | F29: 7 | G29: ANALYST JUDGMENT. FY2023-26: 2,113.86 -> 2,606.69 (7.2% CAGR).
A30: Employee cost growth (%) - Bull | B30: 7 | C30: 7 | D30: 7 | E30: 7 | F30: 7
A31: Employee cost growth (%) - Bear / rating stress | B31: 4 | C31: 0 | D31: 0 | E31: 4 | F31: 5
A32: Employee cost growth (%) - Tail (FY2019-21 repeat) | B32: 0 | C32: 0 | D32: 3 | E32: 5 | F32: 5
A33: Capex (Rs crore) - Base | B33: 1200 | C33: 1150 | D33: 1100 | E33: 1000 | F33: 1100 | G33: ANALYST JUDGMENT. FY2026 actual Rs 1,050 crore (Board's report: Lucknow greenfield bus plant, alternate-fuel vehicles, digital, plant infrastructure); capital commitments Rs 460.19 crore (note 3.10).
A34: Capex (Rs crore) - Bull | B34: 1200 | C34: 1150 | D34: 1100 | E34: 1000 | F34: 1100
A35: Capex (Rs crore) - Bear / rating stress | B35: 1000 | C35: 800 | D35: 800 | E35: 900 | F35: 1000
A36: Capex (Rs crore) - Tail (FY2019-21 repeat) | B36: 900 | C36: 700 | D36: 800 | E36: 1000 | F36: 1100
A37: Equity support to subsidiaries (Rs crore) - Base | B37: 500 | C37: 500 | D37: 400 | E37: 400 | F37: 400 | G37: ANALYST JUDGMENT. FY2024-26 actual 1,567.02 / 717.06 / 386.28 (engine; Optare/Switch, OHM, HLF). Bear/Tail add a Hinduja Leyland Finance capital call and continued EV losses (ICRA 1006: 'capital requirements for the captive finance business').
A38: Equity support to subsidiaries (Rs crore) - Bull | B38: 300 | C38: 300 | D38: 300 | E38: 300 | F38: 300
A39: Equity support to subsidiaries (Rs crore) - Bear / rating stress | B39: 1000 | C39: 1000 | D39: 1000 | E39: 500 | F39: 500
A40: Equity support to subsidiaries (Rs crore) - Tail (FY2019-21 repeat) | B40: 1000 | C40: 1000 | D40: 1000 | E40: 500 | F40: 500
A41: Export units - Base | B41: 19500 | C41: 21000 | D41: 22500 | E41: 23500 | F41: 25000 | G41: Chairman's letter: 'a clear ambition to reach 25,000 export units in the near term' (FY2026: 18,082). Base reaches 25,000 by FY2031 - slower than the ambition.
...

Sheet Revenue Model
A1: Rs crore | B1: FY2023 | C1: FY2024 | D1: FY2025 | E1: FY2026 | F1: FY2027E | G1: FY2028E | H1: FY2029E | I1: FY2030E | J1: FY2031E | K1: Source / note
A2: VOLUMES (units)
A3: Total vehicles | B3: 192205 | C3: 194555 | D3: 195097 | E3: 220437 | F3: 231458.85 | G3: 243031.79 | H3: 247892.43 | I3: 237976.73 | J3: 247495.8 | K3: ten-year table (FY2026 AR p6)
A4: of which exports | C4: 11853 | D4: 15255 | E4: 18082 | F4: 19500 | G4: 21000 | H4: 22500 | I4: 23500 | J4: 25000 | K4: chairman's letters; FY2023 not extracted
A5: CV realisation per vehicle (Rs lakh) | B5: 16.4647 | C5: 16.8151 | D5: 16.5988 | E5: 16.7136 | F5: 16.9643 | G5: 17.2187 | H5: 17.477 | I5: 17.7392 | J5: 18.0053 | K5: CV revenue / total vehicles (derived)
A6: REVENUE BY PRODUCT (note 2.1 / 3.7.1)
A7: Commercial vehicles | B7: 31646.05 | C7: 32714.7 | D7: 32383.69 | E7: 36842.91 | F7: 39265.331 | G7: 41847.027 | H7: 43324.227 | I7: 42215.127 | J7: 44562.288 | K7: note 3.7.1 disaggregated revenue
A8: Engines and gensets | B8: 633.84 | C8: 1006.55 | D8: 1190.17 | E8: 1414.29 | F8: 1555.719 | G8: 1711.2909 | H8: 1848.1942 | I8: 1959.0858 | J8: 2115.8127 | K8: note 3.7.1 disaggregated revenue
A9: Ferrous castings and patterns | B9: 609.33 | C9: 508.77 | D9: 572.24 | E9: 602.41 | F9: 620.4823 | G9: 639.0968 | H9: 658.2697 | I9: 678.0178 | J9: 698.3583 | K9: note 3.7.1 disaggregated revenue
A10: Spare parts and others | B10: 2577.88 | C10: 3469.41 | D10: 3977.9 | E10: 4450.37 | F10: 4806.3996 | G10: 5190.9116 | H10: 5554.2754 | I10: 5831.9891 | J10: 6240.2284 | K10: note 3.7.1 disaggregated revenue
A11: Sale of services | B11: 1106.88 | C11: 1209.86 | D11: 1264.42 | E11: 1257.11 | F11: 1294.8233 | G11: 1333.668 | H11: 1373.678 | I11: 1414.8884 | J11: 1457.335 | K11: note 3.7.1 disaggregated revenue
A12: Scrap sales | B12: 108.56 | C12: 114.04 | D12: 96.8 | E12: 110.63 | F12: 113.9489 | G12: 117.3674 | H12: 120.8884 | I12: 124.515 | J12: 128.2505 | K12: note 3.7.1 disaggregated revenue
A13: Other operating revenue - others | B13: 11.11 | C13: 15.68 | D13: 23 | E13: 53.54 | F13: 55.1462 | G13: 56.8006 | H13: 58.5046 | I13: 60.2597 | J13: 62.0675 | K13: note 3.7.1 disaggregated revenue
A14: Less: rebates and discounts | B14: 597.05 | C14: 715.52 | D14: 805.57 | E14: 794.91 | F14: 849.2709 | G14: 905.9517 | H14: 942.2971 | I14: 930.6531 | J14: 983.7053 | K14: note 2.1
A15: Add: export incentives (+ FY2023 grant income) | B15: 47.54 | C15: 43.54 | D15: 50.09 | E15: 70.68 | F15: 74.9801 | G15: 79.9843 | H15: 83.1932 | I15: 82.1652 | J15: 86.849 | K15: note 2.1 other operating revenue
A16: REVENUE FROM OPERATIONS | B16: 36144.14 | C16: 38367.03 | D16: 38752.74 | E16: 44007.03 | F16: 46937.56 | G16: 50070.195 | H16: 52078.933 | I16: 51435.395 | J16: 54367.484 | K16: ties to the P&L (engine tie-outs)
A17: REVENUE BY GEOGRAPHY (contract revenue, note 3.7.1)
A18: India | B18: 34230.04 | C18: 36608.91 | D18: 36571.31 | E18: 40846.22 | F18: 43347.886 | G18: 45990.993 | H18: 47576.102 | I18: 46731.439 | J18: 49123.975 | K18: note 3.7.1
A19: Outside India | B19: 1866.56 | C19: 1714.58 | D19: 2131.34 | E19: 3090.13 | F19: 3514.6935 | G19: 3999.2168 | H19: 4419.6379 | I19: 4621.7907 | J19: 5156.6603 | K19: note 3.7.1
A20: Revenue growth (%) | C20: 6.1501 | D20: 1.0053 | E20: 13.5585 | F20: 6.6592 | G20: 6.674 | H20: 4.0118 | I20: -1.2357 | J20: 5.7005 | K20: derived

Sheet Income Statement
A1: Rs crore | B1: FY2023 | C1: FY2024 | D1: FY2025 | E1: FY2026 | F1: FY2027E | G1: FY2028E | H1: FY2029E | I1: FY2030E | J1: FY2031E | K1: Source / note
A2: Revenue from operations | B2: 36144.14 | C2: 38367.03 | D2: 38752.74 | E2: 44007.03 | F2: 46937.56 | G2: 50070.195 | H2: 52078.933 | I2: 51435.395 | J2: 54367.484 | K2: P&L
A3: Cost of goods sold (materials + purchases + inventory change) | B3: 27849.15 | C3: 27912.01 | D3: 27622.78 | E3: 31417.14 | F3: 33512.351 | G3: 35739.889 | H3: 37344.934 | I3: 37134.826 | J3: 38663.632 | K3: P&L; projected = derived residual of the margin assumption
A4: Employee benefits expense | B4: 2113.86 | C4: 2233.38 | D4: 2406.27 | E4: 2606.69 | F4: 2789.1583 | G4: 2984.3994 | H4: 3193.3073 | I4: 3416.8389 | J4: 3656.0176 | K4: P&L
A5: Other expenses | B5: 3250.43 | C5: 3615.06 | D5: 3793.13 | E5: 4250.95 | F5: 4534.1683 | G5: 4836.7808 | H5: 5030.825 | I5: 4968.6591 | J5: 5251.8989 | K5: P&L
A6: OPBDITA (ICRA: excludes all other income) | B6: 2930.7 | C6: 4606.58 | D6: 4930.56 | E6: 5732.25 | F6: 6101.8828 | G6: 6509.1253 | H6: 6509.8667 | I6: 5915.0704 | J6: 6795.9355 | K6: revenue less operating costs; ties to the company's published EBITDA
A7: Other income (treasury, dividends, gains) | B7: 116.14 | C7: 246.57 | D7: 250.25 | E7: 315.17 | F7: 347.54 | G7: 391.4955 | H7: 459.1391 | I7: 526.7137 | J7: 573.8731 | K7: P&L; projected = yield x opening free liquidity
A8: Depreciation and amortisation | B8: 731.96 | C8: 717.81 | D8: 719.34 | E8: 715.19 | F8: 787.2155 | G8: 841.9304 | H8: 882.7653 | I8: 911.5599 | J8: 923.2827 | K8: P&L; projected = FY2026 rate on opening net block
A9: Finance costs (incl. unwinding of discount) | B9: 289.09 | C9: 249.44 | D9: 216.91 | E9: 169.73 | F9: 156.9968 | G9: 137.6781 | H9: 129.5215 | I9: 121.3649 | J9: 113.2083 | K9: P&L
A10: Profit before exceptional items and tax | B10: 2025.79 | C10: 3885.9 | D10: 4244.56 | E10: 5162.5 | F10: 5505.2105 | G10: 5921.0123 | H10: 5956.7189 | I10: 5408.8593 | J10: 6333.3176 | K10: P&L printed subtotal (tied)
A11: Exceptional items | B11: 84.61 | C11: -93.72 | D11: 103.73 | E11: -348.48 | F11: 0 | G11: 0 | H11: 0 | I11: 0 | J11: 0 | K11: note 2.8; none projected
A12: Profit before tax | B12: 2110.4 | C12: 3792.18 | D12: 4348.29 | E12: 4814.02 | F12: 5505.2105 | G12: 5921.0123 | H12: 5956.7189 | I12: 5408.8593 | J12: 6333.3176 | K12: P&L
A13: Tax expense | B13: 730.29 | C13: 1174.31 | D13: 1045 | E13: 1248.49 | F13: 1403.8287 | G13: 1509.8581 | H13: 1518.9633 | I13: 1379.2591 | J13: 1614.996 | K13: P&L
A14: PROFIT AFTER TAX | B14: 1380.11 | C14: 2617.87 | D14: 3303.29 | E14: 3565.53 | F14: 4101.3818 | G14: 4411.1542 | H14: 4437.7556 | I14: 4029.6001 | J14: 4718.3216 | K14: P&L printed (tied)

Sheet Cash Flow
A1: Rs crore | B1: FY2023 | C1: FY2024 | D1: FY2025 | E1: FY2026 | F1: FY2027E | G1: FY2028E | H1: FY2029E | I1: FY2030E | J1: FY2031E | K1: Source / note
A2: Net cash from operating activities | B2: 2136.01 | C2: 2503.12 | D2: 7819.42 | E2: 4792.1 | F2: 5018.7761 | G2: 5388.1011 | H2: 5407.0975 | I2: 4913.4236 | J2: 5767.9774 | K2: historical: standalone cash-flow statement; projected: PAT + D&A - change in inventory and receivables + change in payables (finance cost treated as paid)
A3: Capex (purchase of PPE and intangibles) | B3: 502.05 | C3: 495.5 | D3: 954.29 | E3: 1049.53 | F3: 1200 | G3: 1150 | H3: 1100 | I3: 1000 | J3: 1100 | K3: cash-flow statement
A4: Equity investment in subsidiaries / JVs | B4: 19.81 | C4: 1567.02 | D4: 717.06 | E4: 386.28 | F4: 500 | G4: 500 | H4: 400 | I4: 400 | J4: 400 | K4: cash-flow statement + Board's report (engine)
A5: Dividends paid | B5: 293.55 | C5: 763.39 | D5: 2040.77 | E5: 1835.42 | F5: 2055.8455 | G5: 2255.76 | H5: 2426.1348 | I5: 2440.7656 | J5: 2216.2801 | K5: cash-flow statement
A6: Repayment of borrowings | B6: 375.94 | C6: 1104.98 | D6: 688.73 | E6: 379.6 | F6: 483.82 | G6: 129.47 | H6: 129.47 | I6: 129.47 | J6: 129.47 | K6: cash-flow statement; projected = schedule
A7: Proceeds from borrowings | B7: 0 | C7: 0 | D7: 247 | E7: 103 | F7: 0 | G7: 0 | H7: 0 | I7: 0 | J7: 0 | K7: cash-flow statement; projected = DERIVED funding-gap draw (zero unless free liquidity < floor)
A8: Other flows, net (interest paid, leases, treasury, investment sales) | C8: 1842.3 | D8: -1628.16 | E8: 127.84 | F8: 100 | G8: 0 | H8: 0 | I8: 0 | J8: 0 | K8: historical = balancing item to the movement in cash + bank + current investments; projected = movement in earmarked balances only
A9: Closing free cash and liquid investments | B9: 3225.53 | C9: 2167.03 | D9: 5678.52 | E9: 6950.8 | F9: 7829.9107 | G9: 9182.7818 | H9: 10534.275 | I9: 11477.463 | J9: 13399.69 | K9: unencumbered: excludes unclaimed-dividend, escrow, DRF and FY2024 dividend accounts

Sheet Balance Sheet
A1: Rs crore | B1: FY2023 | C1: FY2024 | D1: FY2025 | E1: FY2026 | F1: FY2027E | G1: FY2028E | H1: FY2029E | I1: FY2030E | J1: FY2031E | K1: Source / note
A2: Net block (PPE + right-of-use + other intangibles) | B2: 5854.25 | C2: 5501.9 | D2: 5395.59 | E2: 5938.97 | F2: 6351.7545 | G2: 6659.8241 | H2: 6877.0588 | I2: 6965.4989 | J2: 7142.2161
A3: Capital work-in-progress | B3: 48.95 | C3: 95.53 | D3: 276.87 | E3: 209.98 | F3: 209.98 | G3: 209.98 | H3: 209.98 | I3: 209.98 | J3: 209.98
A4: Intangible assets under development | B4: 83.57 | C4: 106 | D4: 147.89 | E4: 269.31 | F4: 269.31 | G4: 269.31 | H4: 269.31 | I4: 269.31 | J4: 269.31
A5: Goodwill | B5: 449.9 | C5: 449.9 | D5: 449.9 | E5: 449.9 | F5: 449.9 | G5: 449.9 | H5: 449.9 | I5: 449.9 | J5: 449.9
A6: Non-current investments (incl. subsidiaries) | B6: 3892.18 | C6: 5310.71 | D6: 5654.26 | E6: 6559.29 | F6: 7059.29 | G6: 7559.29 | H6: 7959.29 | I6: 8359.29 | J6: 8759.29
A7: Other non-current assets | B7: 559.16 | C7: 484.62 | D7: 1269.02 | E7: 504.22 | F7: 504.22 | G7: 504.22 | H7: 504.22 | I7: 504.22 | J7: 504.22
A8: Inventories | B8: 2774.48 | C8: 3190.69 | D8: 2957.32 | E8: 3486.02 | F8: 3717.4547 | G8: 3965.5594 | H8: 4124.6515 | I8: 4073.6833 | J8: 4305.9047
A9: Trade receivables | B9: 4062.08 | C9: 3569.65 | D9: 2887.32 | E9: 2950.41 | F9: 3144.8165 | G9: 3354.703 | H9: 3489.2885 | I9: 3446.1714 | J9: 3642.6214
A10: Free cash and liquid investments | B10: 3225.53 | C10: 2167.03 | D10: 5678.52 | E10: 6950.8 | F10: 7829.9107 | G10: 9182.7818 | H10: 10534.275 | I10: 11477.463 | J10: 13399.69
A11: Earmarked bank balances and non-liquid investments | B11: 47.18 | C11: 1520.21 | D11: 46.13 | E11: 145.96 | F11: 45.96 | G11: 45.96 | H11: 45.96 | I11: 45.96 | J11: 45.96
A12: Other current assets | B12: 1522.43 | C12: 1149.49 | D12: 739.33 | E12: 1128.8 | F12: 1128.8 | G12: 1128.8 | H12: 1128.8 | I12: 1128.8 | J12: 1128.8
A13: Assets held for sale | B13: 71.92 | C13: 66.02 | D13: 23.68 | E13: 0 | F13: 0 | G13: 0 | H13: 0 | I13: 0 | J13: 0
A14: TOTAL ASSETS | B14: 22591.63 | C14: 23611.75 | D14: 25525.83 | E14: 28593.66 | F14: 30711.396 | G14: 33330.328 | H14: 35592.733 | I14: 36930.276 | J14: 39857.892 | K14: standalone balance sheet (grouped; totals tie to the AR)
A15: Equity (= tangible net worth; no revaluation reserve) | B15: 8425.8 | C15: 8810.37 | D15: 11518.79 | E15: 13113.42 | F15: 15158.956 | G15: 17314.351 | H15: 19325.971 | I15: 20914.806 | J15: 23416.847
A16: Non-current borrowings | B16: 1766.23 | C16: 1131.64 | D16: 902.23 | E16: 517.88 | F16: 388.41 | G16: 258.94 | H16: 129.47 | I16: 0 | J16: 0
A17: Non-current lease liabilities | B17: 31.02 | C17: 29.4 | D17: 31.74 | E17: 29.6 | F17: 29.6 | G17: 29.6 | H17: 29.6 | I17: 29.6 | J17: 29.6
A18: Deferred tax liability (net) | B18: 503.51 | C18: 556.31 | D18: 547.89 | E18: 535.71 | F18: 535.71 | G18: 535.71 | H18: 535.71 | I18: 535.71 | J18: 535.71
A19: Other non-current liabilities and provisions | B19: 792.27 | C19: 1028.83 | D19: 1094.4 | E19: 1070.41 | F19: 1070.41 | G19: 1070.41 | H19: 1070.41 | I19: 1070.41 | J19: 1070.41
A20: Current borrowings (incl. current maturities) | B20: 1413.87 | C20: 1122.89 | D20: 533.21 | E20: 633.82 | F20: 279.47 | G20: 279.47 | H20: 279.47 | I20: 279.47 | J20: 150
A21: Current lease liabilities | B21: 13.71 | C21: 15.47 | D21: 14.54 | E21: 13.74 | F21: 13.74 | G21: 13.74 | H21: 13.74 | I21: 13.74 | J21: 13.74
A22: Trade payables | B22: 7175.12 | C22: 6305.19 | D22: 7304.69 | E22: 8329.26 | F22: 8885.2801 | G22: 9478.2879 | H22: 9858.5421 | I22: 9736.7202 | J22: 10291.765
A23: Other current liabilities and provisions | B23: 2459.23 | C23: 4594.82 | D23: 3573.69 | E23: 4349.82 | F23: 4349.82 | G23: 4349.82 | H23: 4349.82 | I23: 4349.82 | J23: 4349.82
A24: Liabilities held for sale | B24: 10.87 | C24: 16.83 | D24: 4.65 | E24: 0 | F24: 0 | G24: 0 | H24: 0 | I24: 0 | J24: 0
A25: TOTAL EQUITY AND LIABILITIES | B25: 22591.63 | C25: 23611.75 | D25: 25525.83 | E25: 28593.66 | F25: 30711.396 | G25: 33330.328 | H25: 35592.733 | I25: 36930.276 | J25: 39857.892 | K25: standalone balance sheet (grouped; totals tie to the AR)
A26: Check: assets - (equity + liabilities) | B26: 0 | C26: 0 | D26: 0 | E26: 0 | F26: 0 | G26: 0 | H26: 0 | I26: 0 | J26: 0 | K26: must be zero in every column

Sheet Credit Ratios
A1: ICRA convention (formulas) | B1: FY2023 | C1: FY2024 | D1: FY2025 | E1: FY2026 | F1: FY2027E | G1: FY2028E | H1: FY2029E | I1: FY2030E | J1: FY2031E | K1: Source / note
A2: OPBDITA margin (%) | B2: =100*'Income Statement'!B6/'Income Statement'!B2 -> 8.1083683 | C2: =100*'Income Statement'!C6/'Income Statement'!C2 -> 12.006611 | D2: =100*'Income Statement'!D6/'Income Statement'!D2 -> 12.723126 | E2: =100*'Income Statement'!E6/'Income Statement'!E2 -> 13.02576 | F2: =100*'Income Statement'!F6/'Income Statement'!F2 -> 13 | G2: =100*'Income Statement'!G6/'Income Statement'!G2 -> 13 | H2: =100*'Income Statement'!H6/'Income Statement'!H2 -> 12.5 | I2: =100*'Income Statement'!I6/'Income Statement'!I2 -> 11.5 | J2: =100*'Income Statement'!J6/'Income Statement'!J2 -> 12.5
A3: PAT margin (%) | B3: =100*'Income Statement'!B14/'Income Statement'!B2 -> 3.8183506 | C3: =100*'Income Statement'!C14/'Income Statement'!C2 -> 6.8232282 | D3: =100*'Income Statement'!D14/'Income Statement'!D2 -> 8.5240166 | E3: =100*'Income Statement'!E14/'Income Statement'!E2 -> 8.1021828 | F3: =100*'Income Statement'!F14/'Income Statement'!F2 -> 8.7379528 | G3: =100*'Income Statement'!G14/'Income Statement'!G2 -> 8.8099402 | H3: =100*'Income Statement'!H14/'Income Statement'!H2 -> 8.5212106 | I3: =100*'Income Statement'!I14/'Income Statement'!I2 -> 7.8342941 | J3: =100*'Income Statement'!J14/'Income Statement'!J2 -> 8.6785727
A4: Total debt (borrowings + leases) | B4: ='Balance Sheet'!B16+'Balance Sheet'!B20+'Balance Sheet'!B17+'Balance Sheet'!B21 -> 3224.83 | C4: ='Balance Sheet'!C16+'Balance Sheet'!C20+'Balance Sheet'!C17+'Balance Sheet'!C21 -> 2299.4 | D4: ='Balance Sheet'!D16+'Balance Sheet'!D20+'Balance Sheet'!D17+'Balance Sheet'!D21 -> 1481.72 | E4: ='Balance Sheet'!E16+'Balance Sheet'!E20+'Balance Sheet'!E17+'Balance Sheet'!E21 -> 1195.04 | F4: ='Balance Sheet'!F16+'Balance Sheet'!F20+'Balance Sheet'!F17+'Balance Sheet'!F21 -> 711.22 | G4: ='Balance Sheet'!G16+'Balance Sheet'!G20+'Balance Sheet'!G17+'Balance Sheet'!G21 -> 581.75 | H4: ='Balance Sheet'!H16+'Balance Sheet'!H20+'Balance Sheet'!H17+'Balance Sheet'!H21 -> 452.28 | I4: ='Balance Sheet'!I16+'Balance Sheet'!I20+'Balance Sheet'!I17+'Balance Sheet'!I21 -> 322.81 | J4: ='Balance Sheet'!J16+'Balance Sheet'!J20+'Balance Sheet'!J17+'Balance Sheet'!J21 -> 193.34
A5: Tangible net worth | B5: ='Balance Sheet'!B15 -> 8425.8 | C5: ='Balance Sheet'!C15 -> 8810.37 | D5: ='Balance Sheet'!D15 -> 11518.79 | E5: ='Balance Sheet'!E15 -> 13113.42 | F5: ='Balance Sheet'!F15 -> 15158.956 | G5: ='Balance Sheet'!G15 -> 17314.351 | H5: ='Balance Sheet'!H15 -> 19325.971 | I5: ='Balance Sheet'!I15 -> 20914.806 | J5: ='Balance Sheet'!J15 -> 23416.847
A6: Gearing - total debt / TNW (x) | B6: =B4/B5 -> 0.3827328 | C6: =C4/C5 -> 0.2609879 | D6: =D4/D5 -> 0.12863504 | E6: =E4/E5 -> 0.09113107 | F6: =F4/F5 -> 0.046917478 | G6: =G4/G5 -> 0.033599297 | H6: =H4/H5 -> 0.023402705 | I6: =I4/I5 -> 0.01543452 | J6: =J4/J5 -> 0.0082564487
A7: TOL / TNW (x) | B7: =('Balance Sheet'!B14-'Balance Sheet'!B15)/'Balance Sheet'!B15 -> 1.6812445 | C7: =('Balance Sheet'!C14-'Balance Sheet'!C15)/'Balance Sheet'!C15 -> 1.6799953 | D7: =('Balance Sheet'!D14-'Balance Sheet'!D15)/'Balance Sheet'!D15 -> 1.2160166 | E7: =('Balance Sheet'!E14-'Balance Sheet'!E15)/'Balance Sheet'!E15 -> 1.1804884 | F7: =('Balance Sheet'!F14-'Balance Sheet'!F15)/'Balance Sheet'!F15 -> 1.0259572 | G7: =('Balance Sheet'!G14-'Balance Sheet'!G15)/'Balance Sheet'!G15 -> 0.92501176 | H7: =('Balance Sheet'!H14-'Balance Sheet'!H15)/'Balance Sheet'!H15 -> 0.84170475 | I7: =('Balance Sheet'!I14-'Balance Sheet'!I15)/'Balance Sheet'!I15 -> 0.76574797 | J7: =('Balance Sheet'!J14-'Balance Sheet'!J15)/'Balance Sheet'!J15 -> 0.70210325
A8: Total debt / OPBDITA (x) | B8: =B4/'Income Statement'!B6 -> 1.1003617 | C8: =C4/'Income Statement'!C6 -> 0.49915556 | D8: =D4/'Income Statement'!D6 -> 0.30051759 | E8: =E4/'Income Statement'!E6 -> 0.2084766 | F8: =F4/'Income Statement'!F6 -> 0.11655747 | G8: =G4/'Income Statement'!G6 -> 0.089374528 | H8: =H4/'Income Statement'!H6 -> 0.069476077 | I8: =I4/'Income Statement'!I6 -> 0.05457416 | J8: =J4/'Income Statement'!J6 -> 0.028449358
A9: Interest coverage - OPBDITA / finance costs (x) | B9: ='Income Statement'!B6/'Income Statement'!B9 -> 10.137673 | C9: ='Income Statement'!C6/'Income Statement'!C9 -> 18.467688 | D9: ='Income Statement'!D6/'Income Statement'!D9 -> 22.730902 | E9: ='Income Statement'!E6/'Income Statement'!E9 -> 33.772757 | F9: ='Income Statement'!F6/'Income Statement'!F9 -> 38.866288 | G9: ='Income Statement'!G6/'Income Statement'!G9 -> 47.277855 | H9: ='Income Statement'!H6/'Income Statement'!H9 -> 50.260896 | I9: ='Income Statement'!I6/'Income Statement'!I9 -> 48.7379 | J9: ='Income Statement'!J6/'Income Statement'!J9 -> 60.030364
A10: DSCR - (PAT + interest + D&A) / (interest + repayments) (x) | B10: =('Income Statement'!B14+'Income Statement'!B9+'Income Statement'!B8)/('Income Statement'!B9+'Cash Flow'!B6) -> 3.610604 | C10: =('Income Statement'!C14+'Income Statement'!C9+'Income Statement'!C8)/('Income Statement'!C9+'Cash Flow'!C6) -> 2.646978 | D10: =('Income Statement'!D14+'Income Statement'!D9+'Income Statement'!D8)/('Income Statement'!D9+'Cash Flow'!D6) -> 4.6812641 | E10: =('Income Statement'!E14+'Income Statement'!E9+'Income Statement'!E8)/('Income Statement'!E9+'Cash Flow'!E6) -> 8.1015965 | F10: =('Income Statement'!F14+'Income Statement'!F9+'Income Statement'!F8)/('Income Statement'!F9+'Cash Flow'!F6) -> 7.873692 | G10: =('Income Statement'!G14+'Income Statement'!G9+'Income Statement'!G8)/('Income Statement'!G9+'Cash Flow'!G6) -> 20.17893 | H10: =('Income Statement'!H14+'Income Statement'!H9+'Income Statement'!H8)/('Income Statement'!H9+'Cash Flow'!H6) -> 21.043325 | I10: =('Income Statement'!I14+'Income Statement'!I9+'Income Statement'!I8)/('Income Statement'!I9+'Cash Flow'!I6) -> 20.182697 | J10: =('Income Statement'!J14+'Income Statement'!J9+'Income Statement'!J8)/('Income Statement'!J9+'Cash Flow'!J6) -> 23.71375
A11: NCA / total debt (x) | B11: =('Income Statement'!B14+'Income Statement'!B8-'Cash Flow'!B5)/B4 -> 0.5639119 | C11: =('Income Statement'!C14+'Income Statement'!C8-'Cash Flow'!C5)/C4 -> 1.1186788 | D11: =('Income Statement'!D14+'Income Statement'!D8-'Cash Flow'!D5)/D4 -> 1.3375402 | E11: =('Income Statement'!E14+'Income Statement'!E8-'Cash Flow'!E5)/E4 -> 2.0462077 | F11: =('Income Statement'!F14+'Income Statement'!F8-'Cash Flow'!F5)/F4 -> 3.9829473 | G11: =('Income Statement'!G14+'Income Statement'!G8-'Cash Flow'!G5)/G4 -> 5.1522554 | H11: =('Income Statement'!H14+'Income Statement'!H8-'Cash Flow'!H5)/H4 -> 6.3995448 | I11: =('Income Statement'!I14+'Income Statement'!I8-'Cash Flow'!I5)/I4 -> 7.7457154 | J11: =('Income Statement'!J14+'Income Statement'!J8-'Cash Flow'!J5)/J4 -> 17.716583
A12: RoCE - PBIT / avg (debt + TNW + DTL - CWIP) (%) | C12: =100*('Income Statement'!C6-'Income Statement'!C8)/((C4+'Balance Sheet'!C15+'Balance Sheet'!C18-'Balance Sheet'!C3+B4+'Balance Sheet'!B15+'Balance Sheet'!B18-'Balance Sheet'!B3)/2) -> 32.850251 | D12: =100*('Income Statement'!D6-'Income Statement'!D8)/((D4+'Balance Sheet'!D15+'Balance Sheet'!D18-'Balance Sheet'!D3+C4+'Balance Sheet'!C15+'Balance Sheet'!C18-'Balance Sheet'!C3)/2) -> 33.903924 | E12: =100*('Income Statement'!E6-'Income Statement'!E8)/((E4+'Balance Sheet'!E15+'Balance Sheet'!E18-'Balance Sheet'!E3+D4+'Balance Sheet'!D15+'Balance Sheet'!D18-'Balance Sheet'!D3)/2) -> 35.957216 | F12: =100*('Income Statement'!F6-'Income Statement'!F8)/((F4+'Balance Sheet'!F15+'Balance Sheet'!F18-'Balance Sheet'!F3+E4+'Balance Sheet'!E15+'Balance Sheet'!E18-'Balance Sheet'!E3)/2) -> 34.477137 | G12: =100*('Income Statement'!G6-'Income Statement'!G8)/((G4+'Balance Sheet'!G15+'Balance Sheet'!G18-'Balance Sheet'!G3+F4+'Balance Sheet'!F15+'Balance Sheet'!F18-'Balance Sheet'!F3)/2) -> 32.931828 | H12: =100*('Income Statement'!H6-'Income Statement'!H8)/((H4+'Balance Sheet'!H15+'Balance Sheet'!H18-'Balance Sheet'!H3+G4+'Balance Sheet'!G15+'Balance Sheet'!G18-'Balance Sheet'!G3)/2) -> 29.364552 | I12: =100*('Income Statement'!I6-'Income Statement'!I8)/((I4+'Balance Sheet'!I15+'Balance Sheet'!I18-'Balance Sheet'!I3+H4+'Balance Sheet'!H15+'Balance Sheet'!H18-'Balance Sheet'!H3)/2) -> 24.01647 | J12: =100*('Income Statement'!J6-'Income Statement'!J8)/((J4+'Balance Sheet'!J15+'Balance Sheet'!J18-'Balance Sheet'!J3+I4+'Balance Sheet'!I15+'Balance Sheet'!I18-'Balance Sheet'!I3)/2) -> 25.814276
A13: Current ratio (x) | B13: =('Balance Sheet'!B8+'Balance Sheet'!B9+'Balance Sheet'!B10+'Balance Sheet'!B11+'Balance Sheet'!B12)/('Balance Sheet'!B20+'Balance Sheet'!B21+'Balance Sheet'!B22+'Balance Sheet'!B23) -> 1.0515073 | C13: =('Balance Sheet'!C8+'Balance Sheet'!C9+'Balance Sheet'!C10+'Balance Sheet'!C11+'Balance Sheet'!C12)/('Balance Sheet'!C20+'Balance Sheet'!C21+'Balance Sheet'!C22+'Balance Sheet'!C23) -> 0.96334221 | D13: =('Balance Sheet'!D8+'Balance Sheet'!D9+'Balance Sheet'!D10+'Balance Sheet'!D11+'Balance Sheet'!D12)/('Balance Sheet'!D20+'Balance Sheet'!D21+'Balance Sheet'!D22+'Balance Sheet'!D23) -> 1.0772344 | E13: =('Balance Sheet'!E8+'Balance Sheet'!E9+'Balance Sheet'!E10+'Balance Sheet'!E11+'Balance Sheet'!E12)/('Balance Sheet'!E20+'Balance Sheet'!E21+'Balance Sheet'!E22+'Balance Sheet'!E23) -> 1.1002016 | F13: =('Balance Sheet'!F8+'Balance Sheet'!F9+'Balance Sheet'!F10+'Balance Sheet'!F11+'Balance Sheet'!F12)/('Balance Sheet'!F20+'Balance Sheet'!F21+'Balance Sheet'!F22+'Balance Sheet'!F23) -> 1.1728695 | G13: =('Balance Sheet'!G8+'Balance Sheet'!G9+'Balance Sheet'!G10+'Balance Sheet'!G11+'Balance Sheet'!G12)/('Balance Sheet'!G20+'Balance Sheet'!G21+'Balance Sheet'!G22+'Balance Sheet'!G23) -> 1.2518523 | H13: =('Balance Sheet'!H8+'Balance Sheet'!H9+'Balance Sheet'!H10+'Balance Sheet'!H11+'Balance Sheet'!H12)/('Balance Sheet'!H20+'Balance Sheet'!H21+'Balance Sheet'!H22+'Balance Sheet'!H23) -> 1.3324745 | I13: =('Balance Sheet'!I8+'Balance Sheet'!I9+'Balance Sheet'!I10+'Balance Sheet'!I11+'Balance Sheet'!I12)/('Balance Sheet'!I20+'Balance Sheet'!I21+'Balance Sheet'!I22+'Balance Sheet'!I23) -> 1.4028114 | J13: =('Balance Sheet'!J8+'Balance Sheet'!J9+'Balance Sheet'!J10+'Balance Sheet'!J11+'Balance Sheet'!J12)/('Balance Sheet'!J20+'Balance Sheet'!J21+'Balance Sheet'!J22+'Balance Sheet'!J23) -> 1.5212754
A14: Net debt (negative = net cash) | B14: =B4-'Balance Sheet'!B10 -> -0.7 | C14: =C4-'Balance Sheet'!C10 -> 132.37 | D14: =D4-'Balance Sheet'!D10 -> -4196.8 | E14: =E4-'Balance Sheet'!E10 -> -5755.76 | F14: =F4-'Balance Sheet'!F10 -> -7118.6907 | G14: =G4-'Balance Sheet'!G10 -> -8601.0318 | H14: =H4-'Balance Sheet'!H10 -> -10081.995 | I14: =I4-'Balance Sheet'!I10 -> -11154.653 | J14: =J4-'Balance Sheet'!J10 -> -13206.35
A16: ICRA indicative bands (960 / 1006): RoCE >=25% strongest, <10% weakest; TOL/TNW <=0.9x / >3.0x; Total debt/OPBDITA <=0.5x / >5.0x; Interest coverage >=18x / <2x; DSCR >=4.0x / <1.1x.

Sheet Scenarios
A1: Scenario / metric | B1: FY2027E | C1: FY2028E | D1: FY2029E | E1: FY2030E | F1: FY2031E | G1: Note
A2: BASE
A3: Total vehicles | B3: 231458.85 | C3: 243031.79 | D3: 247892.43 | E3: 237976.73 | F3: 247495.8
A4: Revenue from operations | B4: 46937.56 | C4: 50070.19 | D4: 52078.93 | E4: 51435.39 | F4: 54367.48
A5: OPBDITA margin (%) | B5: 13 | C5: 13 | D5: 12.5 | E5: 11.5 | F5: 12.5
A6: PAT | B6: 4101.38 | C6: 4411.15 | D6: 4437.76 | E6: 4029.6 | F6: 4718.32
A7: Free cash and liquid investments | B7: 7829.91 | C7: 9182.78 | D7: 10534.27 | E7: 11477.46 | F7: 13399.69
A8: New borrowing drawn (funding gap) | B8: 0 | C8: 0 | D8: 0 | E8: 0 | F8: 0
A9: Total debt | B9: 711.22 | C9: 581.75 | D9: 452.28 | E9: 322.81 | F9: 193.34
A10: Net debt (negative = net cash) | B10: -7118.69 | C10: -8601.03 | D10: -10081.99 | E10: -11154.65 | F10: -13206.35
A11: TOL / TNW (x) | B11: 1.03 | C11: 0.93 | D11: 0.84 | E11: 0.77 | F11: 0.7
A12: Total debt / OPBDITA (x) | B12: 0.12 | C12: 0.09 | D12: 0.07 | E12: 0.05 | F12: 0.03
A13: Interest coverage (x) | B13: 38.87 | C13: 47.28 | D13: 50.26 | E13: 48.74 | F13: 60.03
A14: DSCR (x) | B14: 7.87 | C14: 20.18 | D14: 21.04 | E14: 20.18 | F14: 23.71
A15: RoCE (%) | B15: 34.48 | C15: 32.93 | D15: 29.36 | E15: 24.02 | F15: 25.81
A16: BULL
A17: Total vehicles | B17: 238071.96 | C17: 257117.72 | D17: 272544.78 | E17: 283446.57 | F17: 297618.9
A18: Revenue from operations | B18: 48236.94 | C18: 52886.41 | D18: 57013.44 | E18: 60352.38 | F18: 64557.14
A19: OPBDITA margin (%) | B19: 13.5 | C19: 14 | D19: 14.5 | E19: 14.5 | F19: 14.5
A20: PAT | B20: 4406.91 | C20: 5098.83 | D20: 5796.94 | E20: 6236.26 | F20: 6787.43
A21: Free cash and liquid investments | B21: 8391.44 | C21: 10529.32 | D21: 13053.08 | E21: 15727.02 | F21: 18659.54
A22: New borrowing drawn (funding gap) | B22: 0 | C22: 0 | D22: 0 | E22: 0 | F22: 0
A23: Total debt | B23: 711.22 | C23: 581.75 | D23: 452.28 | E23: 322.81 | F23: 193.34
A24: Net debt (negative = net cash) | B24: -7680.22 | C24: -9947.57 | D24: -12600.8 | E24: -15404.21 | F24: -18466.2
A25: TOL / TNW (x) | B25: 1.02 | C25: 0.91 | D25: 0.81 | E25: 0.73 | F25: 0.67
A26: Total debt / OPBDITA (x) | B26: 0.11 | C26: 0.08 | D26: 0.05 | E26: 0.04 | F26: 0.02
A27: Interest coverage (x) | B27: 41.48 | C27: 53.78 | D27: 63.83 | E27: 72.11 | F27: 82.69
A28: DSCR (x) | B28: 8.35 | C28: 22.75 | D28: 26.29 | E28: 28.98 | F28: 32.24
A29: RoCE (%) | B29: 36.77 | C29: 36.92 | D29: 36.06 | E29: 33.55 | F29: 31.91
A30: BEAR / RATING STRESS
A31: Total vehicles | B31: 202802.04 | C31: 152101.53 | D31: 136891.38 | E31: 157425.08 | F31: 173167.59
A32: Revenue from operations | B32: 41338.55 | C32: 32516.5 | D32: 30103.96 | E32: 34050.21 | F32: 37429.05
A33: OPBDITA margin (%) | B33: 10.5 | C33: 6 | D33: 7.5 | E33: 10 | F33: 11
A34: PAT | B34: 2789.19 | C34: 987.93 | D34: 1174.07 | E34: 2023.4 | F34: 2593.16
A35: Free cash and liquid investments | B35: 6563.78 | C35: 5220.68 | D35: 4878.3 | E35: 6001.69 | F35: 7327.31
A36: New borrowing drawn (funding gap) | B36: 0 | C36: 0 | D36: 0 | E36: 0 | F36: 0
A37: Total debt | B37: 711.22 | C37: 581.75 | D37: 452.28 | E37: 322.81 | F37: 193.34
A38: Net debt (negative = net cash) | B38: -5852.56 | C38: -4638.93 | D38: -4426.02 | E38: -5678.88 | F38: -7133.97
A39: TOL / TNW (x) | B39: 1 | C39: 0.87 | D39: 0.78 | E39: 0.74 | F39: 0.69
A40: Total debt / OPBDITA (x) | B40: 0.16 | C40: 0.3 | D40: 0.2 | E40: 0.09 | F40: 0.05
...

Sheet DCF Inputs
A1: Rs crore | B1: FY2023 | C1: FY2024 | D1: FY2025 | E1: FY2026 | F1: FY2027E | G1: FY2028E | H1: FY2029E | I1: FY2030E | J1: FY2031E | K1: Source / note
A2: OPBDITA | B2: 2930.7 | C2: 4606.58 | D2: 4930.56 | E2: 5732.25 | F2: 6101.8828 | G2: 6509.1253 | H2: 6509.8667 | I2: 5915.0704 | J2: 6795.9355 | K2: Income Statement
A3: Less: tax on operating profit (25.5% x (OPBDITA - D&A)) | F3: 1355.2402 | G3: 1445.1347 | H3: 1434.9108 | I3: 1275.8952 | J3: 1497.5265
A4: Less: capex | B4: 502.05 | C4: 495.5 | D4: 954.29 | E4: 1049.53 | F4: 1200 | G4: 1150 | H4: 1100 | I4: 1000 | J4: 1100
A5: Less: increase in operating working capital (inventory + receivables - payables) | F5: -130.1788 | G5: -135.0166 | H5: -86.5766 | I5: 27.7365 | J5: -126.373
A6: UNLEVERED FREE CASH FLOW (standalone, before support to subsidiaries) | F6: 3676.8214 | G6: 4049.0072 | H6: 4061.5324 | I6: 3611.4387 | J6: 4324.7821

Sheet Valuation
A1: DCF of the standalone CV business (Rs crore) - informs financial flexibility only (Step 12(f)); it does not move the grade.
A2: Cost of equity = risk-free 6.5% + beta 1.1 x ERP 5.5% = 12.55%; AL is net-cash, so WACC ~= cost of equity, rounded to 12.5%. Terminal growth 5.0% (nominal). ALL ANALYST ASSUMPTIONS - not market-sourced.
A3: Enterprise value (WACC 12.5%, g 5.0%) | B3: 47574
A4: Add: free cash and liquid investments, 31-Mar-2026 | B4: 6951
A5: Less: total debt, 31-Mar-2026 | B5: 1195
A6: Add: investments in subsidiaries/associates at book (incl. HLF), 31-Mar-2026 | B6: 6559 | C6: book value; HLF is unlisted - no market value available
A7: Implied equity value (Rs crore) | B7: 59889
A8: Implied value per share (Rs) | B8: 102 | C8: 587.39 crore shares
A10: Market price (Rs, 01-Oct-2026; third-party aggregator, not NSE-verified) | B10: 150.48 | C10: 52-week range Rs 134.21-215.42 (same source)
A11: Market capitalisation (Rs crore) = price x 587.39 crore shares | B11: 88390
A12: Market capitalisation / standalone total debt 31-Mar-2026 (x) | B12: 74 | C12: the financial-flexibility reading: equity cushion over debt
A13: DCF value / market price | B13: 0.68 | C13: below 1: the market prices more growth or a lower discount rate than this conservative DCF
A15: Sensitivity: equity value (Rs crore) | B15: g 4.0% | C15: g 4.5% | D15: g 5.0% | E15: g 5.5% | F15: g 6.0%
A16: WACC 11.00% | B16: 64961 | C16: 68091 | D16: 71744 | E16: 76060 | F16: 81240
A17: WACC 11.75% | B17: 59856 | C17: 62324 | D17: 65157 | E17: 68444 | F17: 72302
A18: WACC 12.50% | B18: 55654 | C18: 57639 | D18: 59889 | E18: 62460 | F18: 65427
A19: WACC 13.25% | B19: 52133 | C19: 53758 | D19: 55579 | E19: 57635 | F19: 59974
A20: WACC 14.00% | B20: 49142 | C20: 50489 | D20: 51987 | E20: 53661 | F20: 55543

Sheet Debt Breakup
A1: (i) STATUTORY BORROWINGS - standalone (Rs crore) | B1: FY2024 | C1: FY2025 | D1: FY2026 | E1: Source
A2: Non-current borrowings | B2: 1131.64 | C2: 902.23 | D2: 517.88 | E2: balance sheet
A3: Current borrowings (incl. current maturities) | B3: 1122.89 | C3: 533.21 | D3: 633.82 | E3: balance sheet
A4: Lease liabilities (non-current + current) | B4: 44.87 | C4: 46.28 | D4: 43.34 | E4: balance sheet
A5: TOTAL DEBT | B5: 2299.4 | C5: 1481.72 | D5: 1195.04 | E5: sum of the three lines; cross-checked to screener.in in the spreads' ExternalTieOut tab
A7: (ii) INSTRUMENT VIEW at 31-Mar-2026 (face value, FY2026 AR repayment schedule) | D7: FY2026
A8: Term loans - non-current | D8: 456.38 | E8: borrowings note repayment schedule
A9: Term loans - current maturities | D9: 279.25 | E9: borrowings note repayment schedule
A10: NCD Series 3 7.30% AL 2027 - current | D10: 200 | E10: ISIN INE208A07406; bullet 17-Mar-2027; call option end of year 3; secured 1.10x on Hosur P&M
A11: Sales-tax loans (interest-free) - non-current | D11: 61.5 | E11: borrowings note repayment schedule
A12: Sales-tax loans (interest-free) - current | D12: 4.91 | E12: borrowings note repayment schedule
A13: Short-term loans from banks (unsecured) | D13: 150 | E13: note 1.21
A14: Commercial paper outstanding | D14: 0 | E14: nil at the standalone level (Rs 2,000 crore rated programme)
A15: Sum of instruments (face) | D15: 1152.04 | E15: vs balance-sheet borrowings 1,151.70: 0.34 effective-interest residual (engine tie-out)
A16: Currency mix | E16: no foreign-currency borrowing disclosed at the standalone level; acceptances: none shown separately
A18: (iii) THE AR'S OWN NET-DEBT BRIDGE (standalone note, Rs crore) | B18: FY2024 | C18: FY2025 | D18: FY2026
A19: Cash | B19: 1941.87 | C19: 2659.82 | D19: 2031.09 | E19: AR net-debt reconciliation
A20: Liquid investments | B20: 225.16 | C20: 3018.7 | D20: 4119.71 | E20: AR net-debt reconciliation
A21: Current borrowings (bridge) | B21: 484.87 | C21: 150.87 | D21: 150.78 | E21: AR net-debt reconciliation
A22: Non-current borrowings (bridge) | B22: 1777.16 | C22: 1289.57 | D22: 1003.93 | E22: AR net-debt reconciliation
A23: Derivative asset/(liability) | B23: 51.99 | C23: 12.19 | D23: -16.1 | E23: AR net-debt reconciliation
A24: Lease liabilities (bridge) | B24: 44.87 | C24: 46.28 | D24: 43.34 | E24: AR net-debt reconciliation
A25: Net surplus (printed) | B25: -87.88 | C25: 4203.99 | D25: 4936.65 | E25: AR net-debt reconciliation
A26: Arithmetic check: cash + liquid inv - borrowings + derivative - leases | B26: -87.88 | C26: 4203.99 | D26: 4936.65 | E26: equals the printed net surplus in every year
A27: Analyst net debt on free liquidity (negative = net cash) | B27: 132.37 | C27: -4196.8 | D27: -5755.76 | E27: basis difference: ours ADDS the free 3-12 month deposits (Rs 800 crore FY2026) and EXCLUDES the derivative; the bridge excludes all bank deposits. Chairman's 'net cash Rs 5,899 crore' adds every bank balance incl. earmarked ones.
A29: (iv) RATED LIMITS vs DRAWN DEBT | D29: Rs crore
A30: ICRA rated programme - CRA-PUBLISHED 02-Jun-2026, NOT issuer-confirmed | D30: 7479.38 | E30: CP 2,000 + NCD 200 + proposed NCD 300 + LT/ST FB 2,000 + LT/ST NFB 1,500 + term loans 729.38 + LT/ST unallocated 750 (line arithmetic verified)
A31: Drawn borrowings + leases, 31-Mar-2026 | D31: 1195.04 | E31: limits and drawn debt are different measures and are not expected to reconcile
A32: Drawn term loans (face) vs rated term loans 729.38 | D32: 735.63 | E32: 6.25 gap = size of an April-May 2026 instalment; to be confirmed by issuer
A33: Undrawn bank facilities, 31-Mar-2026 | D33: 2854.34 | E33: liquidity-risk note (secured 2,000.00 + unsecured 854.34)
